Workbook

Sheet Results_qwen2.5_latest
A1: ID | B1: Turn | C1: Exercise | D1: Student Answer | E1: Tutor Socratic Response | F1: Socratic Quality | G1: Conceptual Precision | H1: Consistency | I1: Hallucination Rate | J1: Total Score | K1: Latency (s) | L1: Tokens | M1: Throughput (resp/min) | N1: Expected ACs | O1: Detected ACs | P1: AC Precision | Q1: AC Recall | R1: AC F1 | T1: Respuestas del gem
A2: 1 | B2: 1 | C2: 1 | D2: R1 y R2 dado que las dos resistencia forman un divisor de tensión | E2: No es exactamente así. Vamos a repasar algo importante. A R1 y R2 como parte del divisor de tensión entre N1 y 0. ¿Crees que R4 también contribuye al valor de la diferencia de potencial entre N2 y tierra, dado que está conectado en paralelo con R2? | F2: 5 | G2: 4 | H2: 3 | I2: 5 | J2: =SUM(F2:I2) -> 17 | K2: 8.65 | L2: 61 | M2: 6.94 | N2: AC9 | O2: AC9 | P2: 1 | Q2: 1 | R2: 1
A3: 2 | B3: 2 | C3: 1 | D3: R1 y R2 dado que se pide la tensión en R2 | E3: Buen comienzo, pero necesitamos ir un poco más allá. R1 y R2 forman parte de la diferencia de potencial entre N2 y tierra. ¿Y qué piensas sobre R4? | F3: 4 | G3: 4 | H3: 3 | I3: 5 | J3: =SUM(F3:I3) -> 16 | K3: 7.826 | L3: 36 | M3: 7.67 | N3: AC9 | O3: AC1, AC9 | P3: 0.5 | Q3: 1 | R3: 0.667
A4: 3 | B4: 3 | C4: 1 | D4: R1 y R2 por identificar un divisor de tensión | E4: Hay algo que no encaja. Vamos a revisarlo juntos. R1 y R2 forman parte del divisor de tensión entre N1 y 0. ¿Puedes pensar en por qué R4 también contribuye al valor de la diferencia de potencial entre N2 y tierra? | F4: 3 | G4: 5 | H4: 3 | I4: 5 | J4: =SUM(F4:I4) -> 16 | K4: 9.646 | L4: 53 | M4: 6.22 | N4: AC9 | O4: AC9 | P4: 1 | Q4: 1 | R4: 1
A5: 4 | B5: 1 | C5: 1 | D5: R1 y R2 hacen un divisor de tensión | E5: No es exactamente así. Vamos a repasar algo importante. Que R1 y R2 forman parte del divisor de tensión entre N2 y tierra. ¿Crees que el interruptor abierto entre N2 y N3 podría afectar la diferencia de potencial entre N2 y tierra? | F5: 4 | G5: 3 | H5: 2 | I5: 3 | J5: =SUM(F5:I5) -> 12 | K5: 10.824 | L5: 54 | M5: 5.54 | N5: AC9 | O5: AC1, AC9 | P5: 0.5 | Q5: 1 | R5: 0.667
A6: 5 | B6: 2 | C6: 1 | D6: R1, R2, R3 y R4 porque R5 está cortocircuitada | E6: Que esos elementos contribuyen al voltaje entre N2 y tierra! Eso es muy buen trabajo. ¿Por qué crees que R3 no contribuye a la diferencia de potencial entre N2 y tierra? | F6: 4 | G6: 5 | H6: 2 | I6: 5 | J6: =SUM(F6:I6) -> 16 | K6: 22.059 | L6: 40 | M6: 2.72 | N6: AC1, AC6 | O6: AC9 | P6: 0 | Q6: 0 | R6: 0
A7: 6 | B7: 3 | C7: 1 | D7: R1, R2, R3 y R4 porque por R5 no circula corriente | E7: Estás cerca. Piensa en qué más podría influir. Ese elemento tiene una propiedad relevante que debes identificar. ¿Qué ocurre con la corriente en una rama interrumpida por un interruptor abierto? | F7: 4 | G7: 5 | H7: 4 | I7: 5 | J7: =SUM(F7:I7) -> 18 | K7: 9.587 | L7: 39 | M7: 6.26 | N7: AC1, AC6 | O7: AC1 | P7: 1 | Q7: 0.5 | R7: 0.667
A8: 7 | B8: 1 | C8: 1 | D8: R1, R2, R3 y R4 porque R5 se quita | E8: Buen comienzo, pero necesitamos ir un poco más allá. Que esos elementos contribuyen al voltaje entre N2 y tierra. Ese elemento tiene una propiedad relevante que debes identificar. ¿Qué ocurre con la corriente en una rama interrumpida? | F8: 4 | G8: 5 | H8: 4 | I8: 5 | J8: =SUM(F8:I8) -> 18 | K8: 9.258 | L8: 48 | M8: 6.48 | N8: AC1, AC6 | O8: AC1, AC9 | P8: 0.5 | Q8: 0.5 | R8: 0.5
A9: 8 | B9: 2 | C9: 1 | D9: R1, R3 y R4 porque R2 está en paralelo con la fuente y R5 corctocircuitada | E9: Buen comienzo, pero necesitamos ir un poco más allá. Que R2 contribuye al voltaje entre N2 y tierra. Hay una característica clave de ese elemento que aún no has nombrado. ¿Por qué crees que R3 también contribuye, dada la topología del circuito? | F9: 3 | G9: 3 | H9: 2 | I9: 3 | J9: =SUM(F9:I9) -> 11 | K9: 9.861 | L9: 54 | M9: 6.08 | N9: AC1, AC6 | O9: AC9 | P9: 0 | Q9: 0 | R9: 0
A10: 9 | B10: 3 | C10: 1 | D10: R1, R4 y R5 porque R2 se elimina y R3 también | E10: Eso no es del todo preciso. Pensemos un momento. Que R1 y R4 contribuyen al voltaje entre N2 y tierra. ¿Por qué crees que R3 también contribuye, dada la topología del circuito? | F10: 3 | G10: 1 | H10: 1 | I10: 1 | J10: =SUM(F10:I10) -> 6 | K10: 13.059 | L10: 41 | M10: 4.59 | N10: AC1, AC6 | O10: AC9 | P10: 0 | Q10: 0 | R10: 0
A11: 10 | B11: 1 | C11: 1 | D11: R1 y R4 dado que R2 está en paralelo con la fuente, R3 en circuito abierto y R5 cortocircuitada | E11: Esas resistencias. ¿Crees que ese conjunto de elementos está realmente en paralelo con la fuente V1? | F11: 5 | G11: 5 | H11: 5 | I11: 5 | J11: =SUM(F11:I11) -> 20 | K11: 8.901 | L11: 20 | M11: 6.74 | N11: AC1, AC6 | O11: AC9 | P11: 0 | Q11: 0 | R11: 0
A12: 11 | B12: 2 | C12: 1 | D12: R1, R2 y R3 dado que R2 y R3 están en paralelo y forman un divisor de tensión con R1 | E12: Parte de tu respuesta es correcta, pero falta algo. A R1 y R2. ¿Crees que R3 contribuye al valor de la diferencia de potencial entre N2 y tierra? | F12: 4 | G12: 4 | H12: 4 | I12: 5 | J12: =SUM(F12:I12) -> 17 | K12: 8.478 | L12: 36 | M12: 7.08 | N12: AC1, AC9 | O12: AC9 | P12: 1 | Q12: 0.5 | R12: 0.667
A13: 12 | B13: 3 | C13: 1 | D13: R1, R2, R4 y R5 dado que R3 está en circuito abierto | E13: Estás cerca. Piensa en qué más podría influir. A ese conjunto de elementos como contribuyentes al valor de la diferencia de potencial entre N2 y tierra. ¿Puedes pensar un poco más sobre por qué R5 no contribuye a esta diferencia de potencial? | F13: 4 | G13: 5 | H13: 2 | I13: 1 | J13: =SUM(F13:I13) -> 12 | K13: 14.977 | L13: 54 | M13: 4.01 | N13: AC1, AC6 | O13: AC1, AC9 | P13: 0.5 | Q13: 0.5 | R13: 0.5
... A15: 14 | B15: 2 | C15: 1 | D15: R1, R2, R4 y R5 dado que R3 no hace nada | E15: A ese conjunto de elementos como contribuyentes al voltaje entre N2 y tierra. ¿Por qué crees que R5 también está incluido en tu respuesta? | F15: 4 | G15: 5 | H15: 5 | I15: 5 | J15: =SUM(F15:I15) -> 19 | K15: 14.979 | L15: 31 | M15: 4.01 | N15: AC1, AC6 | O15: AC9 | P15: 0 | Q15: 0 | R15: 0
A16: 15 | B16: 3 | C16: 1 | D16: R1, R2 y R4 dado que son las resistencias que forman parte del circuito. | E16: Correcto. ¿Crees que R1 contribuye al voltaje entre N2 y tierra? | F16: 2 | G16: 5 | H16: 2 | I16: 5 | J16: =SUM(F16:I16) -> 14 | K16: 7.174 | L16: 14 | M16: 8.36 | O16: AC9 | P16: 0 | Q16: 1 | R16: 0
A17: 16 | B17: 1 | C17: 1 | D17: R1, R2 y R4 dado que R2 y R4 están en paralelo y forma un divisor de tensión con R1. | E17: Pero hay que pulir algunos conceptos. esas resistencias. Estas resistencias contribuyen a la diferencia de potencial entre N2 y tierra. ¿Crees que el hecho de que ese conjunto de elementos estén en paralelo afecta directamente al valor de la diferencia de potencial entre N2 y tierra? | F17: 3 | G17: 5 | H17: 4 | I17: 5 | J17: =SUM(F17:I17) -> 17 | K17: 9.954 | L17: 59 | M17: 6.03 | O17: AC9 | P17: 0 | Q17: 1 | R17: 0
A18: 17 | B18: 2 | C18: 1 | D18: R1, R2 y R4 dado que R3 está en abierto y R5 cortocircuitada | E18: Esas resistencias como contribuyentes a la diferencia de potencial entre N2 y tierra. ¿Crees que el interruptor abierto entre N2 y N3 afecta directamente al valor de la diferencia de potencial entre N2 y tierra? | F18: 3 | G18: 5 | H18: 2 | I18: 5 | J18: =SUM(F18:I18) -> 15 | K18: 13.249 | L18: 45 | M18: 4.53 | N18: AC1, AC6 | O18: AC1, AC9 | P18: 0.5 | Q18: 0.5 | R18: 0.5
A19: 18 | B19: 3 | C19: 1 | D19: R1, R2 y R4 dado que solo por estas resistencias circula una corriente diferente de cero | E19: ¡Excelente trabajo! Has identificado correctamente la respuesta y la has justificado bien. Antes de cerrar: ¿te queda alguna duda sobre este circuito o los conceptos implicados? <FIN_EJERCICIO> | F19: 5 | G19: 5 | H19: 5 | I19: 5 | J19: =SUM(F19:I19) -> 20 | K19: 1.221 | L19: 35 | M19: 49.14 | P19: 1 | Q19: 1 | R19: 1
A20: 19 | B20: 1 | C20: 1 | D20: R1, R2 y R4 dado que por R3 y por R5 no circula corriente | E20: La respuesta incluye los elementos correctos: ese conjunto de elementos. ¿Por qué crees que la corriente no circula a través de R3? | F20: 5 | G20: 5 | H20: 5 | I20: 5 | J20: =SUM(F20:I20) -> 20 | K20: 7.533 | L20: 28 | M20: 7.97 | N20: AC1, AC6 | O20: AC1 | P20: 1 | Q20: 0.5 | R20: 0.667
A21: 20 | B21: 2 | C21: 1 | D21: R1, R2 y R4 dado que R3 y R5 se pueden quitar | E21: A ese conjunto de elementos como contribuyentes al voltaje entre N2 y tierra. ¿Por qué crees que la corriente no circula por R3? Considera lo que ocurre en una rama interrumpida. | F21: 3 | G21: 5 | H21: 4 | I21: 5 | J21: =SUM(F21:I21) -> 17 | K21: 14.775 | L21: 40 | M21: 4.06 | N21: AC1, AC6 | O21: AC1, AC9 | P21: 0.5 | Q21: 0.5 | R21: 0.5
A22: 21 | B22: 3 | C22: 1 | D22: R1, R2 y R4 dado que R3 y R5 no influyen para nada en la diferencia de potencial que se pide | E22: Buen comienzo, pero necesitamos ir un poco más allá. esos elementos contribuyen al voltaje entre N2 y tierra. ¿Por qué crees que R3 no influye en el voltaje entre N2 y tierra? Considera lo que ocurre con la corriente en una rama interrumpida. | F22: 3 | G22: 5 | H22: 4 | I22: 5 | J22: =SUM(F22:I22) -> 17 | K22: 9.547 | L22: 55 | M22: 6.28 | N22: AC1, AC6 | O22: AC1, AC9 | P22: 0.5 | Q22: 0.5 | R22: 0.5
A23: 22 | B23: 1 | C23: 1 | D23: R1, R2 y R4 dado que R3 y R5 sobran | E23: Bien encaminado, aunque falta completar la respuesta. esas resistencias como contribuyentes al voltaje entre N2 y tierra. Ese elemento tiene una propiedad relevante que debes identificar. ¿Qué propiedad de ese elemento podrías analizar para decidirlo? | F23: 4 | G23: 5 | H23: 4 | I23: 5 | J23: =SUM(F23:I23) -> 18 | K23: 8.689 | L23: 45 | M23: 6.9 | N23: AC1, AC6 | O23: AC9 | P23: 0 | Q23: 0 | R23: 0
A24: 23 | B24: 2 | C24: 1 | D24: R1, R2 y R4 dado que R3 sobra | E24: Has identificado bien esas resistencias como contribuyentes al voltaje entre N2 y tierra. ¿Podrías pensarlo desde la perspectiva del interruptor abierto entre N2 y N3? | F24: 4 | G24: 5 | H24: 4 | I24: 5 | J24: =SUM(F24:I24) -> 18 | K24: 9.807 | L24: 32 | M24: 6.12 | N24: AC1 | O24: AC1, AC9 | P24: 0.5 | Q24: 1 | R24: 0.667
A25: 24 | B25: 3 | C25: 1 | D25: R1, R2 y R4 dado que R5 sobra | E25: ¡Excelente trabajo! Has identificado correctamente la respuesta y la has justificado bien. Antes de cerrar: ¿te queda alguna duda sobre este circuito o los conceptos implicados? <FIN_EJERCICIO> | F25: 0 | G25: 3 | H25: 1 | I25: 5 | J25: =SUM(F25:I25) -> 9 | K25: 1.213 | L25: 35 | M25: 49.47 | N25: AC6 | P25: 1 | Q25: 0 | R25: 0
A26: 25 | B26: 1 | C26: 1 | D26: R1, R2 y R4 dado que R3 está en abierto | E26: ¿Crees que el interruptor abierto entre N2 y N3 tiene alguna influencia sobre estas resistencias? | F26: 4 | G26: 3 | H26: 2 | I26: 5 | J26: =SUM(F26:I26) -> 14 | K26: 6.795 | L26: 19 | M26: 8.83 | N26: AC1 | O26: AC1, AC9 | P26: 0.5 | Q26: 1 | R26: 0.667
A27: 26 | B27: 2 | C27: 1 | D27: R1, R2 y R4 dado que R5 cortocircuitada | E27: ¡Excelente trabajo! Has identificado correctamente la respuesta y la has justificado bien. Antes de cerrar: ¿te queda alguna duda sobre este circuito o los conceptos implicados? <FIN_EJERCICIO> | F27: 3 | G27: 3 | H27: 1 | I27: 3 | J27: =SUM(F27:I27) -> 10 | K27: 1.197 | L27: 35 | M27: 50.14 | N27: AC6 | P27: 1 | Q27: 0 | R27: 0
A28: 27 | B28: 3 | C28: 1 | D28: R1, R2 y R4 dado que por R3 no circula corriente | E28: ¡Excelente trabajo! Has identificado correctamente la respuesta y la has justificado bien. Antes de cerrar: ¿te queda alguna duda sobre este circuito o los conceptos implicados? <FIN_EJERCICIO> | F28: 3 | G28: 3 | H28: 1 | I28: 3 | J28: =SUM(F28:I28) -> 10 | K28: 0.026 | L28: 35 | M28: 2286.99 | N28: AC1 | P28: 1 | Q28: 0 | R28: 0
A29: 28 | B29: 1 | C29: 1 | D29: R1, R2 y R4 dado que por R5 no circula corriente | E29: ¿Consideraste cómo afecta un cortocircuito en la corriente que fluye a través de una resistencia? | F29: 3 | G29: 5 | H29: 3 | I29: 5 | J29: =SUM(F29:I29) -> 16 | K29: 8.112 | L29: 19 | M29: 7.4 | N29: AC6 | O29: AC1, AC6 | P29: 0.5 | Q29: 1 | R29: 0.667
A30: 29 | B30: 2 | C30: 1 | D30: R1, R2 y R4 dado que R3 se puede quitar | E30: Parte de tu respuesta es correcta, pero falta algo. A esos elementos como las resistencias que contribuyen al voltaje entre N2 y tierra. ¿Por qué crees que esa resistencia no influye en el voltaje entre N2 y tierra, dado que hay un interruptor abierto entre N2 y N3? | F30: 4 | G30: 4 | H30: 3 | I30: 5 | J30: =SUM(F30:I30) -> 16 | K30: 9.443 | L30: 62 | M30: 6.35 | N30: AC1 | O30: AC1, AC9 | P30: 0.5 | Q30: 1 | R30: 0.667
A31: 30 | B31: 3 | C31: 1 | D31: R1, R2 y R4 dado que R5 se puede quitar | E31: Parte de tu respuesta es correcta, pero falta algo. Sobre ese conjunto de elementos. Esa resistencias contribuyen al voltaje entre N2 y tierra. ¿Por qué crees que el estado de R5 (cortocircuito) no afecta a las otras resistencias en la diferencia de potencial entre N2 y tierra? | F31: 1 | G31: 5 | H31: 3 | I31: 5 | J31: =SUM(F31:I31) -> 14 | K31: 9.484 | L31: 61 | M31: 6.33 | N31: AC6 | O31: AC1, AC6, AC9 | P31: 0.333 | Q31: 1 | R31: 0.5
A32: 31 | B32: 1 | C32: 1 | D32: R1, R2 y R4 dado que R3 no influye para nada en la diferencia de potencial que se pide | E32: Esas resistencias como contribuyentes a la diferencia de potencial entre N2 y tierra. ¿Podrías reflexionar sobre por qué R3 no influye en esta diferencia de potencial? | F32: 5 | G32: 5 | H32: 5 | I32: 5 | J32: =SUM(F32:I32) -> 20 | K32: 8.763 | L32: 33 | M32: 6.85 | N32: AC1 | O32: AC1, AC9 | P32: 0.5 | Q32: 1 | R32: 0.667
A33: 32 | B33: 2 | C33: 1 | D33: R1, R2 y R4 dado que R5 no influye para nada en la diferencia de potencial que se pide | E33: ¡Excelente trabajo! Has identificado correctamente la respuesta y la has justificado bien. Antes de cerrar: ¿te queda alguna duda sobre este circuito o los conceptos implicados? <FIN_EJERCICIO> | F33: 0 | G33: 3 | H33: 1 | I33: 5 | J33: =SUM(F33:I33) -> 9 | K33: 1.172 | L33: 35 | M33: 51.2 | N33: AC6 | P33: 1 | Q33: 0 | R33: 0
A34: 33 | B34: 3 | C34: 1 | D34: No lo sé | E34: La corriente sale del + de V1 y llega al primer nodo (N1). ¿Hacia qué nodo crees que continúa desde N1? | F34: 4 | G34: 5 | H34: 5 | I34: 5 | J34: =SUM(F34:I34) -> 19 | K34: 5.468 | L34: 27 | M34: 10.97 | N34: AC9 | O34: AC1 | P34: 0 | Q34: 0 | R34: 0
A35: 34 | B35: 1 | C35: 1 | D35: Todas las resistencias | E35: Interesante, ¿crees que todas las resistencias contribuyen al valor de la diferencia de potencial entre N2 y 0? | F35: 5 | G35: 5 | H35: 4 | I35: 5 | J35: =SUM(F35:I35) -> 19 | K35: 12.18 | L35: 23 | M35: 4.93 | N35: AC9 | O35: AC9 | P35: 1 | Q35: 1 | R35: 1
A36: 35 | B36: 2 | C36: 1 | D36: R1 y R2 | E36: Parte de tu respuesta es correcta, pero falta algo. A R1 y R2. ¿Consideras que estas resistencias están en serie o en paralelo entre N2 y 0? | F36: 3 | G36: 5 | H36: 4 | I36: 5 | J36: =SUM(F36:I36) -> 17 | K36: 8.903 | L36: 35 | M36: 6.74 | N36: AC9 | O36: AC9 | P36: 1 | Q36: 1 | R36: 1
A37: 36 | B37: 3 | C37: 1 | D37: R1, R2 y R4 | E37: ¿Podrías explicar por qué estas resistencias contribuyen a la diferencia de potencial entre N2 y 0 utilizando la idea del cortocircuito? | F37: 5 | G37: 5 | H37: 2 | I37: 5 | J37: =SUM(F37:I37) -> 17 | K37: 16.062 | L37: 27 | M37: 3.74 | O37: AC6, AC9 | P37: 0 | Q37: 1 | R37: 0
A38: 37 | B38: 1 | C38: 1 | D38: R1, R2, R4 y R5 | E38: La corriente sale del + de V1 y llega al nudo N1. ¿Hacia qué nodo crees que la corriente seguirá desde el nudo N1? | F38: 5 | G38: 5 | H38: 5 | I38: 5 | J38: =SUM(F38:I38) -> 20 | K38: 8.388 | L38: 31 | M38: 7.15 | N38: AC6 | O38: AC1 | P38: 0 | Q38: 0 | R38: 0
A39: 38 | B39: 2 | C39: 1 | D39: R1, R2, R3 y R4 | E39: Bien encaminado, aunque falta completar la respuesta. A esos elementos como elementos que contribuyen al valor de la diferencia de potencial entre N2 y 0. ¿Por qué crees que R3 no influye en el voltaje entre N2 y 0? | F39: 4 | G39: 5 | H39: 5 | I39: 5 | J39: =SUM(F39:I39) -> 19 | K39: 10.063 | L39: 50 | M39: 5.96 | N39: AC1 | P39: 1 | Q39: 0 | R39: 0
A40: 39 | B40: 3 | C40: 1 | D40: R1 y R2 y R4 hacen un divisor de corriente | E40: Los resistores ese conjunto de elementos como contribuyentes al voltaje entre N2 y 0. ¿Cómo piensas que esa resistencia afecta o no afecta a esta diferencia de potencial según el concepto del divisor de corriente? | F40: 3 | G40: 3 | H40: 4 | I40: 5 | J40: =SUM(F40:I40) -> 15 | K40: 14.727 | L40: 45 | M40: 4.07 | O40: AC1 | P40: 0 | Q40: 1 | R40: 0
A41: 40 | B41: 1 | C41: 1 | D41: R1 y R2 y R4 hacen un divisor de tensión, r3 no cuenta por estar en corto | E41: ¿Crees que el interruptor abierto entre N2 y N3 tenga alguna influencia en las resistencias que contribuyen a la diferencia de potencial entre N2 y tierra? | F41: 4 | G41: 5 | H41: 5 | I41: 5 | J41: =SUM(F41:I41) -> 19 | K41: 9.107 | L41: 33 | M41: 6.59 | N41: AC1 | O41: AC1, AC9 | P41: 0.5 | Q41: 1 | R41: 0.667
...

Sheet Metadata
A1: Field | B1: Value
A2: Generation date | B2: 2026-05-22T19:25:48.808041
A3: Method | B3: RAG (via backend API)
A4: Models evaluated | B4: qwen2.5:latest
A5: Exercises covered | B5: 1, 3, 4, 5, 6, 7
A6: Total evaluations | B6: 198
A7: Backend URL | B7: http://localhost:3030

Sheet Ranking
A1: Ranking | B1: Model | C1: samples | D1: avg_latency | E1: p95_latency | F1: throughput | G1: avg_tokens | H1: socratic_format | I1: conceptual_correctness | J1: adaptability | K1: reflection_generation | L1: score_total | M1: pct_socratic | N1: pct_score_15 | O1: faithfulness | P1: relevance | Q1: pct_cot
A2: 1 | B2: qwen2.5:latest | C2: =COUNTA('Results_qwen2.5_latest'!A2:A10000) -> 549 | D2: =IFERROR(AVERAGE('Results_qwen2.5_latest'!K2:K10000),"") -> 5.3617213 | E2: =IFERROR(PERCENTILE('Results_qwen2.5_latest'!K2:K10000,0.95),"") -> 14.519 | F2: =IFERROR(IF(AVERAGE('Results_qwen2.5_latest'!K2:K10000)>0,60/AVERAGE('Results_qwen2.5_latest'!K2:K10000),0),"") -> 11.190436 | G2: =IFERROR(AVERAGE('Results_qwen2.5_latest'!L2:L10000),"") -> 41.116576 | H2: =IFERROR(AVERAGE('Results_qwen2.5_latest'!F2:F10000),"") -> 3.6830601 | I2: =IFERROR(AVERAGE('Results_qwen2.5_latest'!G2:G10000),"") -> 4.2477231 | J2: =IFERROR(AVERAGE('Results_qwen2.5_latest'!H2:H10000),"") -> 3.4225865 | K2: =IFERROR(AVERAGE('Results_qwen2.5_latest'!I2:I10000),"") -> 4.6703097 | L2: =IFERROR(AVERAGE('Results_qwen2.5_latest'!J2:J10000),"") -> 14.570128 | M2: =IFERROR(COUNTIF('Results_qwen2.5_latest'!F2:F10000,">=4")/COUNTA('Results_qwen2.5_latest'!F2:F10000)*100,"") -> 61.818182 | N2: =IFERROR(COUNTIF('Results_qwen2.5_latest'!J2:J10000,">=15")/COUNTA('Results_qwen2.5_latest'!J2:J10000)*100,"") -> 48 | O2: =IFERROR(AVERAGE('Results_qwen2.5_latest'!S2:S10000),"") | P2: =IFERROR(AVERAGE('Results_qwen2.5_latest'!T2:T10000),"") | Q2: =IFERROR(COUNTIF('Results_qwen2.5_latest'!U2:U10000,"<>")/COUNTA('Results_qwen2.5_latest'!A2:A10000)*100,"") -> 0

Sheet Results_Article
A1: Model | B1: Arch. | C1: samples | D1: avg_latency (s) | E1: avg_tokens | F1: socraticity (0-5) | G1: conceptual correctness (0-5) | H1: consistency (0-5) | I1: hallucination rate (0-5) | J1: temperature
A2: qwen2.5:latest | B2: RAG | C2: =COUNTA('Results_qwen2.5_latest'!A2:A10000) -> 549 | D2: =IFERROR(AVERAGE('Results_qwen2.5_latest'!K2:K10000),"") -> 5.3617213 | E2: =IFERROR(AVERAGE('Results_qwen2.5_latest'!L2:L10000),"") -> 41.116576 | F2: =IFERROR(AVERAGE('Results_qwen2.5_latest'!F2:F10000),"") -> 3.6830601 | G2: =IFERROR(AVERAGE('Results_qwen2.5_latest'!G2:G10000),"") -> 4.2477231 | H2: =IFERROR(AVERAGE('Results_qwen2.5_latest'!H2:H10000),"") -> 3.4225865 | I2: =IFERROR(AVERAGE('Results_qwen2.5_latest'!I2:I10000),"") -> 4.6703097 | J2: 0.7

Sheet Efficiency
A1: Model | B1: avg_latency | C1: p95_latency | D1: throughput | E1: avg_tokens
A2: qwen2.5:latest | B2: =IFERROR(AVERAGE('Results_qwen2.5_latest'!K2:K10000),"") -> 5.3617213 | C2: =IFERROR(PERCENTILE('Results_qwen2.5_latest'!K2:K10000,0.95),"") -> 14.519 | D2: =IFERROR(IF(AVERAGE('Results_qwen2.5_latest'!K2:K10000)>0,60/AVERAGE('Results_qwen2.5_latest'!K2:K10000),0),"") -> 11.190436 | E2: =IFERROR(AVERAGE('Results_qwen2.5_latest'!L2:L10000),"") -> 41.116576
