Workbook

Sheet Results_gemma3_27b
A1: ID | B1: Conversation | C1: Turn | D1: Exercise | E1: Student Answer | F1: Tutor Socratic Response | G1: Socratic Quality | H1: Conceptual Precision | I1: Consistency | J1: Hallucination Rate | K1: Total Score | L1: Latency (s) | M1: Tokens | N1: Throughput (resp/min) | O1: Expected ACs | P1: Detected ACs | Q1: AC Precision | R1: AC Recall | S1: AC F1 | T1: Faithfulness | U1: Relevance | V1: Think Content | W1: Constructive Feedback
A2: 199 | B2: 68 | C2: 1 | D2: 1 | E2: R1 y R2 dado que las dos resistencia forman un divisor de tensión | F2: Considerando que el interruptor entre N2 y N3 está abierto, ¿cómo afecta esto al flujo de corriente a través de todas las resistencias conectadas a esos nodos? | G2: 4 | H2: 4 | I2: 3 | J2: 5 | K2: 16 | L2: 1.571 | M2: 36 | N2: 38.2 | O2: AC9 | P2: AC1, AC9 | Q2: 0.5 | R2: 1 | S2: 0.667 | W2: Socratic quality 4/5 (Scaffolding for detection): Scaffolding for detection: identifies the error area and asks a question that confronts the theory. Conceptual precision 4/5 (Good): Good: clearly identifies the alternative conception with precise technical language. Good overall performance; room for improvement in socratic depth.
A3: 200 | B3: 68 | C3: 2 | D3: 1 | E3: R1 y R2 dado que se pide la tensión en R2 | F3: Si conoces la tensión total aplicada al divisor de tensión y la resistencia de R1, ¿qué información adicional necesitarías para calcular la caída de tensión específicamente en R2? | G3: 3 | H3: 3 | I3: 5 | J3: 5 | K3: 16 | L3: 1.137 | M3: 36 | N3: 52.76 | O3: AC9 | Q3: 1 | R3: 0 | S3: 0 | W3: Socratic quality 3/5 (Clarification): Generic question: asks for clarification without attacking the root error. Conceptual precision 3/5 (Sufficient): Sufficient: identifies that there is an error and uses correct concepts, but the diagnosis is somewhat vague. Good overall performance; room for improvement in socratic depth.
A4: 201 | B4: 68 | C4: 3 | D4: 1 | E4: R1 y R2 por identificar un divisor de tensión | F4: Dado que tienes un divisor de tensión compuesto por R1 y R2, ¿cómo se relaciona la resistencia de cada componente con la proporción de la tensión total que cae sobre ella? | G4: 3 | H4: 3 | I4: 5 | J4: 5 | K4: 16 | L4: 1.151 | M4: 37 | N4: 52.13 | O4: AC9 | Q4: 1 | R4: 0 | S4: 0 | W4: Socratic quality 3/5 (Clarification): Generic question: asks for clarification without attacking the root error. Conceptual precision 3/5 (Sufficient): Sufficient: identifies that there is an error and uses correct concepts, but the diagnosis is somewhat vague. Good overall performance; room for improvement in socratic depth.
A5: 202 | B5: 69 | C5: 1 | D5: 1 | E5: R1 y R2 hacen un divisor de tensión | F5: Considerando que el interruptor entre N2 y N3 está abierto, ¿cómo afecta esto al flujo de corriente a través de las diferentes ramas del circuito y qué implicaciones tiene para calcular la diferencia de potencial en N2 con respecto a tierra? | G5: 4 | H5: 3 | I5: 2 | J5: 5 | K5: 14 | L5: 1.544 | M5: 51 | N5: 38.85 | O5: AC9 | P5: AC1, AC9 | Q5: 0.5 | R5: 1 | S5: 0.667 | W5: Socratic quality 4/5 (Scaffolding for detection): Scaffolding for detection: identifies the error area and asks a question that confronts the theory. Conceptual precision 3/5 (Sufficient): Sufficient: identifies that there is an error and uses correct concepts, but the diagnosis is somewhat vague. Good overall performance; room for improvement in socratic depth.
A6: 203 | B6: 69 | C6: 2 | D6: 1 | E6: R1, R2, R3 y R4 porque R5 está cortocircuitada | F6: Si R5 está efectivamente cortocircuitada, ¿cómo impacta esta condición en la corriente que fluye a través de R4 y qué consecuencias tiene esto para determinar qué resistencias contribuyen significativamente a la caída de tensión total? | G6: 3 | H6: 3 | I6: 3 | J6: 5 | K6: 14 | L6: 1.304 | M6: 48 | N6: 46.01 | O6: AC1, AC6 | P6: AC1, AC9 | Q6: 0.5 | R6: 0.5 | S6: 0.5 | W6: Socratic quality 3/5 (Clarification): Generic question: asks for clarification without attacking the root error. Conceptual precision 3/5 (Sufficient): Sufficient: identifies that there is an error and uses correct concepts, but the diagnosis is somewhat vague. Good overall performance; room for improvement in socratic depth.
A7: 204 | B7: 69 | C7: 3 | D7: 1 | E7: R1, R2, R3 y R4 porque por R5 no circula corriente | F7: Si no circula corriente a través de R5 debido al cortocircuito, ¿cómo afecta esto a la configuración general del circuito y a la identificación de las resistencias que realmente determinan la resistencia equivalente total vista por la fuente de tensión? | G7: 4 | H7: 4 | I7: 3 | J7: 5 | K7: 16 | L7: 1.338 | M7: 48 | N7: 44.85 | O7: AC1, AC6 | P7: AC1, AC6, AC9 | Q7: 0.667 | R7: 1 | S7: 0.8 | W7: Socratic quality 4/5 (Scaffolding for detection): Scaffolding for detection: identifies the error area and asks a question that confronts the theory. Conceptual precision 4/5 (Good): Good: clearly identifies the alternative conception with precise technical language. Good overall performance; room for improvement in socratic depth.
A8: 205 | B8: 70 | C8: 1 | D8: 1 | E8: R1, R2, R3 y R4 porque R5 se quita | F8: Si examinas cuidadosamente el netlist, ¿qué relación observas entre los nodos conectados a los terminales de R5? | G8: 3 | H8: 3 | I8: 3 | J8: 5 | K8: 14 | L8: 1.155 | M8: 26 | N8: 51.96 | O8: AC1, AC6 | P8: AC6 | Q8: 1 | R8: 0.5 | S8: 0.667 | W8: Socratic quality 3/5 (Clarification): Generic question: asks for clarification without attacking the root error. Conceptual precision 3/5 (Sufficient): Sufficient: identifies that there is an error and uses correct concepts, but the diagnosis is somewhat vague. Good overall performance; room for improvement in socratic depth.
A9: 206 | B9: 70 | C9: 2 | D9: 1 | E9: R1, R3 y R4 porque R2 está en paralelo con la fuente y R5 corctocircuitada | F9: Si un componente está en cortocircuito, ¿cómo afecta esto a la corriente que fluye a través de él y a la tensión a través de sus terminales? | G9: 4 | H9: 4 | I9: 3 | J9: 5 | K9: 16 | L9: 1.141 | M9: 35 | N9: 52.59 | O9: AC1, AC6 | P9: AC1, AC6 | Q9: 1 | R9: 1 | S9: 1 | W9: Socratic quality 4/5 (Scaffolding for detection): Scaffolding for detection: identifies the error area and asks a question that confronts the theory. Conceptual precision 4/5 (Good): Good: clearly identifies the alternative conception with precise technical language. Good overall performance; room for improvement in socratic depth.
A10: 207 | B10: 70 | C10: 3 | D10: 1 | E10: R1, R4 y R5 porque R2 se elimina y R3 también | F10: Considerando que un cortocircuito implica una resistencia de cero ohmios, ¿cómo afectaría esto a la corriente total que circula por el circuito y a la distribución de la tensión en las demás resistencias? | G10: 3 | H10: 4 | I10: 3 | J10: 5 | K10: 15 | L10: 1.265 | M10: 42 | N10: 47.43 | O10: AC1, AC6 | P10: AC1, AC6, AC9 | Q10: 0.667 | R10: 1 | S10: 0.8 | W10: Socratic quality 3/5 (Clarification): Generic question: asks for clarification without attacking the root error. Conceptual precision 4/5 (Good): Good: clearly identifies the alternative conception with precise technical language. Good overall performance; room for improvement in socratic depth.
A11: 208 | B11: 71 | C11: 1 | D11: 1 | E11: R1 y R4 dado que R2 está en paralelo con la fuente, R3 en circuito abierto y R5 cortocircuitada | F11: Considerando que R2 está en paralelo con la fuente, ¿cómo afecta esta configuración a la corriente que fluye a través de R2 en comparación con la corriente total proveniente de la fuente? | G11: 4 | H11: 3 | I11: 3 | J11: 5 | K11: 15 | L11: 1.412 | M11: 41 | N11: 42.51 | O11: AC1, AC6 | P11: AC1 | Q11: 1 | R11: 0.5 | S11: 0.667 | W11: Socratic quality 4/5 (Scaffolding for detection): Scaffolding for detection: identifies the error area and asks a question that confronts the theory. Conceptual precision 3/5 (Sufficient): Sufficient: identifies that there is an error and uses correct concepts, but the diagnosis is somewhat vague. Good overall performance; room for improvement in socratic depth.
A12: 209 | B12: 71 | C12: 2 | D12: 1 | E12: R1, R2 y R3 dado que R2 y R3 están en paralelo y forman un divisor de tensión con R1 | F12: Si R2 y R3 están en paralelo, ¿cómo se compara el voltaje a través de R2 con el voltaje a través de R3, y cómo esto impacta la corriente que fluye por cada resistencia? | G12: 3 | H12: 3 | I12: 4 | J12: 5 | K12: 15 | L12: 1.278 | M12: 45 | N12: 46.97 | O12: AC1, AC9 | P12: AC1 | Q12: 1 | R12: 0.5 | S12: 0.667 | W12: Socratic quality 3/5 (Clarification): Generic question: asks for clarification without attacking the root error. Conceptual precision 3/5 (Sufficient): Sufficient: identifies that there is an error and uses correct concepts, but the diagnosis is somewhat vague. Good overall performance; room for improvement in socratic depth.
A13: 210 | B13: 71 | C13: 3 | D13: 1 | E13: R1, R2, R4 y R5 dado que R3 está en circuito abierto | F13: Dado que R3 está en circuito abierto, ¿cómo crees que esto afecta el flujo de corriente en el resto del circuito, específicamente en las ramas que contienen a R1, R2, R4 y R5? | G13: 3 | H13: 3 | I13: 5 | J13: 5 | K13: 16 | L13: 1.31 | M13: 46 | N13: 45.8 | O13: AC1, AC6 | P13: AC1 | Q13: 1 | R13: 0.5 | S13: 0.667 | W13: Socratic quality 3/5 (Clarification): Generic question: asks for clarification without attacking the root error. Conceptual precision 3/5 (Sufficient): Sufficient: identifies that there is an error and uses correct concepts, but the diagnosis is somewhat vague. Good overall performance; room for improvement in socratic depth.
A14: 211 | B14: 72 | C14: 1 | D14: 1 | E14: R1, R2, R4 y R5 dado que R3 sobra | F14: Considerando el netlist, ¿qué característica comparten los nodos conectados a los terminales de R5, y cómo podría afectar esto al flujo de corriente a través de esa resistencia? | G14: 3 | H14: 3 | I14: 3 | J14: 5 | K14: 14 | L14: 1.324 | M14: 37 | N14: 45.31 | O14: AC1, AC6 | P14: AC1, AC6 | Q14: 1 | R14: 1 | S14: 1 | W14: Socratic quality 3/5 (Clarification): Generic question: asks for clarification without attacking the root error. Conceptual precision 3/5 (Sufficient): Sufficient: identifies that there is an error and uses correct concepts, but the diagnosis is somewhat vague. Good overall performance; room for improvement in socratic depth.
A15: 212 | B15: 72 | C15: 2 | D15: 1 | E15: R1, R2, R4 y R5 dado que R3 no hace nada | F15: Si R3 no contribuye al circuito, ¿cómo describirías su rol en términos de la corriente eléctrica y la diferencia de potencial entre sus terminales? | G15: 3 | H15: 3 | I15: 3 | J15: 5 | K15: 14 | L15: 1.084 | M15: 32 | N15: 55.35 | O15: AC1, AC6 | P15: AC1, AC6, AC9 | Q15: 0.667 | R15: 1 | S15: 0.8 | W15: Socratic quality 3/5 (Clarification): Generic question: asks for clarification without attacking the root error. Conceptual precision 3/5 (Sufficient): Sufficient: identifies that there is an error and uses correct concepts, but the diagnosis is somewhat vague. Good overall performance; room for improvement in socratic depth.
A16: 213 | B16: 72 | C16: 3 | D16: 1 | E16: R1, R2 y R4 dado que son las resistencias que forman parte del circuito. | F16: Si R5 está efectivamente desconectada del resto del circuito, ¿cómo afectaría esto a la corriente que fluye a través de R4, considerando las leyes de conservación de la corriente en los nodos? | G16: 3 | H16: 3 | I16: 3 | J16: 5 | K16: 14 | L16: 1.266 | M16: 43 | N16: 47.38 | P16: AC1 | Q16: 0 | R16: 1 | S16: 0 | W16: Socratic quality 3/5 (Clarification): Generic question: asks for clarification without attacking the root error. Conceptual precision 3/5 (Sufficient): Sufficient: identifies that there is an error and uses correct concepts, but the diagnosis is somewhat vague. Good overall performance; room for improvement in socratic depth.
A17: 214 | B17: 73 | C17: 1 | D17: 1 | E17: R1, R2 y R4 dado que R2 y R4 están en paralelo y forma un divisor de tensión con R1. | F17: Considerando el interruptor abierto entre N2 y N3, ¿cómo afecta esto al flujo de corriente a través de alguna de las resistencias que mencionaste? | G17: 4 | H17: 4 | I17: 3 | J17: 5 | K17: 16 | L17: 1.311 | M17: 33 | N17: 45.76 | P17: AC1, AC9 | Q17: 0 | R17: 1 | S17: 0 | W17: Socratic quality 4/5 (Scaffolding for detection): Scaffolding for detection: identifies the error area and asks a question that confronts the theory. Conceptual precision 4/5 (Good): Good: clearly identifies the alternative conception with precise technical language. Good overall performance; room for improvement in socratic depth.
A18: 215 | B18: 73 | C18: 2 | D18: 1 | E18: R1, R2 y R4 dado que R3 está en abierto y R5 cortocircuitada | F18: Si R5 está cortocircuitada, ¿cómo crees que esto impacta la diferencia de potencial a través de ella y, por lo tanto, en el resto del circuito? | G18: 3 | H18: 2 | I18: 3 | J18: 5 | K18: 13 | L18: 1.202 | M18: 38 | N18: 49.91 | O18: AC1, AC6 | Q18: 1 | R18: 0 | S18: 0 | W18: Socratic quality 3/5 (Clarification): Generic question: asks for clarification without attacking the root error. Conceptual precision 2/5 (Poor): Poor: responds generically without diagnosing the conceptual error. Good overall performance; room for improvement in socratic depth.
A19: 216 | B19: 73 | C19: 3 | D19: 1 | E19: R1, R2 y R4 dado que solo por estas resistencias circula una corriente diferente de cero | F19: Considerando que R2 y R4 están en paralelo, ¿cómo se compara la corriente que fluye a través de cada una de estas resistencias con la corriente total que proviene de R1? | G19: 3 | H19: 4 | I19: 5 | J19: 5 | K19: 17 | L19: 1.213 | M19: 40 | N19: 49.45 | P19: AC1, AC9 | Q19: 0 | R19: 1 | S19: 0 | W19: Socratic quality 3/5 (Clarification): Generic question: asks for clarification without attacking the root error. Conceptual precision 4/5 (Good): Good: clearly identifies the alternative conception with precise technical language. High-performing tutor: expert socratic guidance with precise diagnosis.
A20: 217 | B20: 74 | C20: 1 | D20: 1 | E20: R1, R2 y R4 dado que por R3 y por R5 no circula corriente | F20: Si observas detenidamente el netlist, ¿qué relación de conexión existe entre los terminales de la resistencia R5 y cómo podría afectar esto al flujo de corriente en ese componente? | G20: 3 | H20: 3 | I20: 3 | J20: 5 | K20: 14 | L20: 1.348 | M20: 38 | N20: 44.5 | O20: AC1, AC6 | P20: AC1, AC6 | Q20: 1 | R20: 1 | S20: 1 | W20: Socratic quality 3/5 (Clarification): Generic question: asks for clarification without attacking the root error. Conceptual precision 3/5 (Sufficient): Sufficient: identifies that there is an error and uses correct concepts, but the diagnosis is somewhat vague. Good overall performance; room for improvement in socratic depth.
A21: 218 | B21: 74 | C21: 2 | D21: 1 | E21: R1, R2 y R4 dado que R3 y R5 se pueden quitar | F21: Si R3 y R5 no tienen corriente circulando, ¿cómo describirías la diferencia de potencial (voltaje) a través de cada uno de estos componentes en relación con los demás elementos del circuito? | G21: 3 | H21: 3 | I21: 3 | J21: 5 | K21: 14 | L21: 1.255 | M21: 42 | N21: 47.8 | O21: AC1, AC6 | P21: AC1 | Q21: 1 | R21: 0.5 | S21: 0.667 | W21: Socratic quality 3/5 (Clarification): Generic question: asks for clarification without attacking the root error. Conceptual precision 3/5 (Sufficient): Sufficient: identifies that there is an error and uses correct concepts, but the diagnosis is somewhat vague. Good overall performance; room for improvement in socratic depth.
A22: 219 | B22: 74 | C22: 3 | D22: 1 | E22: R1, R2 y R4 dado que R3 y R5 no influyen para nada en la diferencia de potencial que se pide | F22: Si R3 y R5 no influyen en la diferencia de potencial, ¿podrías explicar cómo la corriente que fluye a través de R1, R2 y R4 se vería afectada si, hipotéticamente, R3 y R5 estuvieran presentes y con valores distintos de infinito? | G22: 3 | H22: 3 | I22: 5 | J22: 5 | K22: 16 | L22: 1.584 | M22: 63 | N22: 37.88 | O22: AC1, AC6 | P22: AC1 | Q22: 1 | R22: 0.5 | S22: 0.667 | W22: Socratic quality 3/5 (Clarification): Clarification: asks the student to explain their reasoning. Conceptual precision 3/5 (Sufficient): Sufficient: identifies that there is an error and uses correct concepts, but the diagnosis is somewhat vague. Good overall performance; room for improvement in socratic depth.
A23: 220 | B23: 75 | C23: 1 | D23: 1 | E23: R1, R2 y R4 dado que R3 y R5 sobran | F23: Considerando el netlist, ¿qué característica eléctrica comparten los terminales de la resistencia R5 que podría afectar su contribución al cálculo de la diferencia de potencial entre N2 y 0? | G23: 3 | H23: 3 | I23: 3 | J23: 5 | K23: 14 | L23: 1.335 | M23: 40 | N23: 44.94 | O23: AC1, AC6 | P23: AC6, AC9 | Q23: 0.5 | R23: 0.5 | S23: 0.5 | W23: Socratic quality 3/5 (Clarification): Generic question: asks for clarification without attacking the root error. Conceptual precision 3/5 (Sufficient): Sufficient: identifies that there is an error and uses correct concepts, but the diagnosis is somewhat vague. Good overall performance; room for improvement in socratic depth.
A24: 221 | B24: 75 | C24: 2 | D24: 1 | E24: R1, R2 y R4 dado que R3 sobra | F24: Si consideramos la configuración en serie y en paralelo, ¿cómo afectaría la eliminación de R3 al camino que sigue la corriente desde la fuente de voltaje hacia el nodo donde se conectan R1, R2 y R4? | G24: 3 | H24: 3 | I24: 4 | J24: 5 | K24: 15 | L24: 1.309 | M24: 47 | N24: 45.82 | O24: AC1 | P24: AC1, AC9 | Q24: 0.5 | R24: 1 | S24: 0.667 | W24: Socratic quality 3/5 (Clarification): Generic question: asks for clarification without attacking the root error. Conceptual precision 3/5 (Sufficient): Sufficient: identifies that there is an error and uses correct concepts, but the diagnosis is somewhat vague. Good overall performance; room for improvement in socratic depth.
A25: 222 | B25: 75 | C25: 3 | D25: 1 | E25: R1, R2 y R4 dado que R5 sobra | F25: Dado que R5 está en cortocircuito, ¿cómo impacta esto en la corriente que fluye a través de la rama que contiene a R3, y cómo podría esto simplificar el análisis del circuito? | G25: 3 | H25: 3 | I25: 3 | J25: 5 | K25: 14 | L25: 1.475 | M25: 44 | N25: 40.67 | O25: AC6 | P25: AC1, AC6 | Q25: 0.5 | R25: 1 | S25: 0.667 | W25: Socratic quality 3/5 (Clarification): Generic question: asks for clarification without attacking the root error. Conceptual precision 3/5 (Sufficient): Sufficient: identifies that there is an error and uses correct concepts, but the diagnosis is somewhat vague. Good overall performance; room for improvement in socratic depth.
A26: 223 | B26: 76 | C26: 1 | D26: 1 | E26: R1, R2 y R4 dado que R3 está en abierto | F26: Considerando que el interruptor entre N2 y N3 está abierto, ¿qué implicaciones tiene esto para el flujo de corriente a través de cualquier componente conectado directamente a esos nodos? | G26: 3 | H26: 4 | I26: 3 | J26: 5 | K26: 15 | L26: 1.31 | M26: 38 | N26: 45.8 | O26: AC1 | P26: AC1 | Q26: 1 | R26: 1 | S26: 1 | W26: Socratic quality 3/5 (Clarification): Generic question: asks for clarification without attacking the root error. Conceptual precision 4/5 (Good): Good: clearly identifies the alternative conception with precise technical language. Good overall performance; room for improvement in socratic depth.
A27: 224 | B27: 76 | C27: 2 | D27: 1 | E27: R1, R2 y R4 dado que R5 cortocircuitada | F27: Si R5 está en cortocircuito, ¿cómo afecta esto a la diferencia de potencial a través de ella y, por consiguiente, a la corriente que fluye a través de la rama que la contiene? | G27: 4 | H27: 4 | I27: 3 | J27: 5 | K27: 16 | L27: 1.275 | M27: 44 | N27: 47.07 | O27: AC6 | P27: AC1, AC6 | Q27: 0.5 | R27: 1 | S27: 0.667 | W27: Socratic quality 4/5 (Scaffolding for detection): Scaffolding for detection: identifies the error area and asks a question that confronts the theory. Conceptual precision 4/5 (Good): Good: clearly identifies the alternative conception with precise technical language. Good overall performance; room for improvement in socratic depth.
A28: 225 | B28: 76 | C28: 3 | D28: 1 | E28: R1, R2 y R4 dado que por R3 no circula corriente | F28: Si no circula corriente a través de R3, ¿cómo describirías la relación entre los nodos conectados a sus terminales y qué implicaciones tiene esto para el camino que sigue la corriente en el circuito? | G28: 3 | H28: 4 | I28: 3 | J28: 5 | K28: 15 | L28: 1.257 | M28: 42 | N28: 47.72 | O28: AC1 | P28: AC1, AC6, AC9 | Q28: 0.333 | R28: 1 | S28: 0.5 | W28: Socratic quality 3/5 (Clarification): Generic question: asks for clarification without attacking the root error. Conceptual precision 4/5 (Good): Good: clearly identifies the alternative conception with precise technical language. Good overall performance; room for improvement in socratic depth.
A29: 226 | B29: 77 | C29: 1 | D29: 1 | E29: R1, R2 y R4 dado que por R5 no circula corriente | F29: Si observas detenidamente el netlist, ¿qué relación de conexión existe entre los dos terminales de R5 que podría afectar el flujo de corriente a través de ella? | G29: 3 | H29: 3 | I29: 3 | J29: 5 | K29: 14 | L29: 1.304 | M29: 36 | N29: 46.02 | O29: AC6 | P29: AC1, AC6 | Q29: 0.5 | R29: 1 | S29: 0.667 | W29: Socratic quality 3/5 (Clarification): Generic question: asks for clarification without attacking the root error. Conceptual precision 3/5 (Sufficient): Sufficient: identifies that there is an error and uses correct concepts, but the diagnosis is somewhat vague. Good overall performance; room for improvement in socratic depth.
A30: 227 | B30: 77 | C30: 2 | D30: 1 | E30: R1, R2 y R4 dado que R3 se puede quitar | F30: Si R3 se pudiera remover sin afectar la corriente en otros componentes, ¿cómo describirías la configuración del circuito con respecto a R3: en serie, en paralelo, o quizás una combinación de ambas? | G30: 3 | H30: 3 | I30: 3 | J30: 5 | K30: 14 | L30: 1.257 | M30: 42 | N30: 47.73 | O30: AC1 | P30: AC1 | Q30: 1 | R30: 1 | S30: 1 | W30: Socratic quality 3/5 (Clarification): Generic question: asks for clarification without attacking the root error. Conceptual precision 3/5 (Sufficient): Sufficient: identifies that there is an error and uses correct concepts, but the diagnosis is somewhat vague. Good overall performance; room for improvement in socratic depth.
A31: 228 | B31: 77 | C31: 3 | D31: 1 | E31: R1, R2 y R4 dado que R5 se puede quitar | F31: Si R5 puede ser removido sin alterar el funcionamiento del circuito, ¿qué implicación tiene esto sobre el camino que la corriente podría tomar en relación con R5? | G31: 3 | H31: 3 | I31: 3 | J31: 5 | K31: 14 | L31: 1.138 | M31: 35 | N31: 52.71 | O31: AC6 | P31: AC1, AC9 | Q31: 0 | R31: 0 | S31: 0 | W31: Socratic quality 3/5 (Clarification): Generic question: asks for clarification without attacking the root error. Conceptual precision 3/5 (Sufficient): Sufficient: identifies that there is an error and uses correct concepts, but the diagnosis is somewhat vague. Good overall performance; room for improvement in socratic depth.
... A36: 233 | B36: 79 | C36: 2 | D36: 1 | E36: R1 y R2 | F36: Considerando que la corriente siempre busca el camino de menor resistencia, ¿cómo describirías el rol de R3 en relación con el camino que podría tomar la corriente desde la fuente de voltaje? | G36: 3 | H36: 3 | I36: 2 | J36: 5 | K36: 13 | L36: 1.233 | M36: 39 | N36: 48.65 | O36: AC9 | P36: AC1, AC9 | Q36: 0.5 | R36: 1 | S36: 0.667 | W36: Socratic quality 3/5 (Clarification): Generic question: asks for clarification without attacking the root error. Conceptual precision 3/5 (Sufficient): Sufficient: identifies that there is an error and uses correct concepts, but the diagnosis is somewhat vague. Good overall performance; room for improvement in socratic depth.
A37: 234 | B37: 79 | C37: 3 | D37: 1 | E37: R1, R2 y R4 | F37: Si analizamos la configuración de R4, ¿cómo afecta su conexión en serie o en paralelo a la corriente total que fluye desde la fuente de voltaje? | G37: 4 | H37: 4 | I37: 3 | J37: 5 | K37: 16 | L37: 1.121 | M37: 33 | N37: 53.53 | P37: AC1 | Q37: 0 | R37: 1 | S37: 0 | W37: Socratic quality 4/5 (Scaffolding for detection): Scaffolding for detection: identifies the error area and asks a question that confronts the theory. Conceptual precision 4/5 (Good): Good: clearly identifies the alternative conception with precise technical language. Good overall performance; room for improvement in socratic depth.
A38: 235 | B38: 80 | C38: 1 | D38: 1 | E38: R1, R2, R4 y R5 | F38: Si examinas cuidadosamente el netlist, ¿qué característica comparten los dos terminales de la resistencia R5 que podría afectar su contribución al flujo de corriente en el circuito? | G38: 3 | H38: 3 | I38: 3 | J38: 5 | K38: 14 | L38: 1.308 | M38: 36 | N38: 45.88 | O38: AC6 | P38: AC1, AC6, AC9 | Q38: 0.333 | R38: 1 | S38: 0.5 | W38: Socratic quality 3/5 (Clarification): Generic question: asks for clarification without attacking the root error. Conceptual precision 3/5 (Sufficient): Sufficient: identifies that there is an error and uses correct concepts, but the diagnosis is somewhat vague. Good overall performance; room for improvement in socratic depth.
A39: 236 | B39: 80 | C39: 2 | D39: 1 | E39: R1, R2, R3 y R4 | F39: Considerando que has identificado cuatro resistencias, ¿cómo podría la presencia de una quinta resistencia (R5) alterar el cálculo de la resistencia equivalente total del circuito? | G39: 3 | H39: 2 | I39: 2 | J39: 5 | K39: 12 | L39: 1.106 | M39: 33 | N39: 54.23 | O39: AC1 | P39: AC9 | Q39: 0 | R39: 0 | S39: 0 | W39: Socratic quality 3/5 (Clarification): Generic question: asks for clarification without attacking the root error. Conceptual precision 2/5 (Poor): Poor: responds generically without diagnosing the conceptual error. Acceptable performance; needs to improve precision or socratic methodology.
A40: 237 | B40: 80 | C40: 3 | D40: 1 | E40: R1 y R2 y R4 hacen un divisor de corriente | F40: Si R1, R2 y R4 forman un divisor de corriente, ¿cómo afectaría la presencia de R3 y R5 a los nodos donde se conectan estos componentes, y cómo influiría esto en la corriente total del circuito? | G40: 3 | H40: 3 | I40: 4 | J40: 5 | K40: 15 | L40: 1.43 | M40: 51 | N40: 41.97 | P40: AC1 | Q40: 0 | R40: 1 | S40: 0 | W40: Socratic quality 3/5 (Clarification): Generic question: asks for clarification without attacking the root error. Conceptual precision 3/5 (Sufficient): Sufficient: identifies that there is an error and uses correct concepts, but the diagnosis is somewhat vague. Good overall performance; room for improvement in socratic depth.
A41: 238 | B41: 81 | C41: 1 | D41: 1 | E41: R1 y R2 y R4 hacen un divisor de tensión, r3 no cuenta por estar en corto | F41: Si consideramos el estado del interruptor entre N2 y N3, ¿qué implicaciones tiene esto para el flujo de corriente a través de la rama que contiene a R3? | G41: 3 | H41: 5 | I41: 3 | J41: 5 | K41: 16 | L41: 1.382 | M41: 37 | N41: 43.42 | O41: AC1 | P41: AC1 | Q41: 1 | R41: 1 | S41: 1 | W41: Socratic quality 3/5 (Clarification): Generic question: asks for clarification without attacking the root error. Conceptual precision 5/5 (Excellent): Excellent: identifies the specific alternative conception and connects it with the circuit topology. Good overall performance; room for improvement in socratic depth.
A42: 239 | B42: 81 | C42: 2 | D42: 1 | E42: No tengo en cuenta R3 porque el interruptor está cerrado | F42: Si el interruptor está cerrado, ¿cómo afecta esto a la diferencia de potencial a través de R3 y, por lo tanto, a la corriente que podría fluir a través de él? | G42: 4 | H42: 4 | I42: 5 | J42: 5 | K42: 18 | L42: 1.266 | M42: 40 | N42: 47.41 | O42: AC1, AC9 | P42: AC1 | Q42: 1 | R42: 0.5 | S42: 0.667 | W42: Socratic quality 4/5 (Scaffolding for detection): Scaffolding for detection: identifies the error area and asks a question that confronts the theory. Conceptual precision 4/5 (Good): Good: clearly identifies the alternative conception with precise technical language. High-performing tutor: expert socratic guidance with precise diagnosis.
A43: 240 | B43: 81 | C43: 3 | D43: 1 | E43: No tengo en cuenta R5 porque está en circuito abierto | F43: Si R5 está en circuito abierto, ¿cómo afecta esto a la corriente total que fluye desde la fuente de voltaje y a la distribución de voltaje en el resto del circuito? | G43: 4 | H43: 3 | I43: 5 | J43: 5 | K43: 17 | L43: 1.202 | M43: 37 | N43: 49.9 | O43: AC6, AC9 | P43: AC1, AC9 | Q43: 0.5 | R43: 0.5 | S43: 0.5 | W43: Socratic quality 4/5 (Scaffolding for detection): Scaffolding for detection: identifies the error area and asks a question that confronts the theory. Conceptual precision 3/5 (Sufficient): Sufficient: identifies that there is an error and uses correct concepts, but the diagnosis is somewhat vague. High-performing tutor: expert socratic guidance with precise diagnosis.
A44: 241 | B44: 82 | C44: 1 | D44: 3 | E44: R4 y R5 dado que las dos resistencia forman un divisor de tensión | F44: Según el netlist, ¿qué tienen en común los dos terminales de la resistencia R2 y cómo afecta esto a la corriente que podría circular a través de ella? | G44: 3 | H44: 3 | I44: 3 | J44: 5 | K44: 14 | L44: 1.37 | M44: 35 | N44: 43.79 | O44: AC9 | P44: AC6 | Q44: 0 | R44: 0 | S44: 0 | W44: Socratic quality 3/5 (Clarification): Generic question: asks for clarification without attacking the root error. Conceptual precision 3/5 (Sufficient): Sufficient: identifies that there is an error and uses correct concepts, but the diagnosis is somewhat vague. Good overall performance; room for improvement in socratic depth.
...

Sheet Results_gemma3_4b
A1: ID | B1: Conversation | C1: Turn | D1: Exercise | E1: Student Answer | F1: Tutor Socratic Response | G1: Socratic Quality | H1: Conceptual Precision | I1: Consistency | J1: Hallucination Rate | K1: Total Score | L1: Latency (s) | M1: Tokens | N1: Throughput (resp/min) | O1: Expected ACs | P1: Detected ACs | Q1: AC Precision | R1: AC Recall | S1: AC F1 | T1: Faithfulness | U1: Relevance | V1: Think Content | W1: Constructive Feedback
A2: 1 | B2: 1 | C2: 1 | D2: 1 | E2: R1 y R2 dado que las dos resistencia forman un divisor de tensión | F2: Considerando que el interruptor está abierto entre N2 y N3, ¿cómo afecta la presencia de R5 al flujo de corriente y, por lo tanto, a la diferencia de potencial entre N2 y 0? | G2: 4 | H2: 3 | I2: 3 | J2: 5 | K2: 15 | L2: 29.642 | M2: 46 | N2: 2.02 | O2: AC9 | P2: AC1 | Q2: 0 | R2: 0 | S2: 0 | W2: Socratic quality 4/5 (Scaffolding for detection): Scaffolding for detection: identifies the error area and asks a question that confronts the theory. Conceptual precision 3/5 (Sufficient): Sufficient: identifies that there is an error and uses correct concepts, but the diagnosis is somewhat vague. Good overall performance; room for improvement in socratic depth.
A3: 2 | B3: 1 | C3: 2 | D3: 1 | E3: R1 y R2 dado que se pide la tensión en R2 | F3: Si la corriente fluye a través de R1 y R2, ¿qué factores podrían influir en la proporción de corriente que pasa a través de cada resistencia, considerando su resistencia individual? | G3: 3 | H3: 3 | I3: 5 | J3: 5 | K3: 16 | L3: 0.832 | M3: 39 | N3: 72.08 | O3: AC9 | P3: AC1 | Q3: 0 | R3: 0 | S3: 0 | W3: Socratic quality 3/5 (Clarification): Generic question: asks for clarification without attacking the root error. Conceptual precision 3/5 (Sufficient): Sufficient: identifies that there is an error and uses correct concepts, but the diagnosis is somewhat vague. Good overall performance; room for improvement in socratic depth.
A4: 3 | B4: 1 | C4: 3 | D4: 1 | E4: R1 y R2 por identificar un divisor de tensión | F4: Si estás configurando un divisor de tensión con R1 y R2, ¿qué relación específica defines entre los voltajes en los nodos N1 y N2? | G4: 3 | H4: 3 | I4: 5 | J4: 5 | K4: 16 | L4: 0.755 | M4: 34 | N4: 79.43 | O4: AC9 | Q4: 1 | R4: 0 | S4: 0 | W4: Socratic quality 3/5 (Clarification): Generic question: asks for clarification without attacking the root error. Conceptual precision 3/5 (Sufficient): Sufficient: identifies that there is an error and uses correct concepts, but the diagnosis is somewhat vague. Good overall performance; room for improvement in socratic depth.
A5: 4 | B5: 2 | C5: 1 | D5: 1 | E5: R1 y R2 hacen un divisor de tensión | F5: Considerando que el interruptor está abierto, ¿cómo afecta la interrupción del flujo de corriente a través de R3 y R5 al determinar el potencial en el nodo N2 en relación con la tierra? | G5: 4 | H5: 3 | I5: 2 | J5: 5 | K5: 14 | L5: 0.828 | M5: 43 | N5: 72.42 | O5: AC9 | P5: AC1, AC9 | Q5: 0.5 | R5: 1 | S5: 0.667 | W5: Socratic quality 4/5 (Scaffolding for detection): Scaffolding for detection: identifies the error area and asks a question that confronts the theory. Conceptual precision 3/5 (Sufficient): Sufficient: identifies that there is an error and uses correct concepts, but the diagnosis is somewhat vague. Good overall performance; room for improvement in socratic depth.
A6: 5 | B6: 2 | C6: 2 | D6: 1 | E6: R1, R2, R3 y R4 porque R5 está cortocircuitada | F6: Si el interruptor estuviera cerrado, ¿cómo cambiaría la distribución de la corriente a través de R1, R2 y R3, y qué implicaciones tendría eso para el potencial en el nodo N2? | G6: 3 | H6: 4 | I6: 4 | J6: 5 | K6: 16 | L6: 1.042 | M6: 45 | N6: 57.57 | O6: AC1, AC6 | P6: AC1 | Q6: 1 | R6: 0.5 | S6: 0.667 | W6: Socratic quality 3/5 (Clarification): Generic question: asks for clarification without attacking the root error. Conceptual precision 4/5 (Good): Good: clearly identifies the alternative conception with precise technical language. Good overall performance; room for improvement in socratic depth.
A7: 6 | B7: 2 | C7: 3 | D7: 1 | E7: R1, R2, R3 y R4 porque por R5 no circula corriente | F7: Considerando que R5 está efectivamente en cortocircuito, ¿cómo crees que la resistencia total del circuito afectaría el valor de la tensión medida en el nodo N2 con respecto a la tierra? | G7: 3 | H7: 4 | I7: 3 | J7: 5 | K7: 15 | L7: 0.759 | M7: 42 | N7: 79.09 | O7: AC1, AC6 | P7: AC6, AC9 | Q7: 0.5 | R7: 0.5 | S7: 0.5 | W7: Socratic quality 3/5 (Clarification): Generic question: asks for clarification without attacking the root error. Conceptual precision 4/5 (Good): Good: clearly identifies the alternative conception with precise technical language. Good overall performance; room for improvement in socratic depth.
A8: 7 | B8: 3 | C8: 1 | D8: 1 | E8: R1, R2, R3 y R4 porque R5 se quita | F8: Considerando que el interruptor entre N2 y N3 está abierto, ¿qué efecto tiene la ausencia de una ruta continua para la corriente en la rama que incluye R3 sobre el potencial en N2? | G8: 3 | H8: 3 | I8: 3 | J8: 5 | K8: 14 | L8: 0.824 | M8: 43 | N8: 72.83 | O8: AC1, AC6 | P8: AC1 | Q8: 1 | R8: 0.5 | S8: 0.667 | W8: Socratic quality 3/5 (Clarification): Generic question: asks for clarification without attacking the root error. Conceptual precision 3/5 (Sufficient): Sufficient: identifies that there is an error and uses correct concepts, but the diagnosis is somewhat vague. Good overall performance; room for improvement in socratic depth.
A9: 8 | B9: 3 | C9: 2 | D9: 1 | E9: R1, R3 y R4 porque R2 está en paralelo con la fuente y R5 corctocircuitada | F9: Si R5 efectivamente crea un cortocircuito, ¿cómo afectaría esto a la distribución de la corriente y, por lo tanto, a las tensiones medidas en los diferentes nodos del circuito? | G9: 3 | H9: 4 | I9: 3 | J9: 5 | K9: 15 | L9: 0.755 | M9: 40 | N9: 79.49 | O9: AC1, AC6 | P9: AC1, AC6 | Q9: 1 | R9: 1 | S9: 1 | W9: Socratic quality 3/5 (Clarification): Generic question: asks for clarification without attacking the root error. Conceptual precision 4/5 (Good): Good: clearly identifies the alternative conception with precise technical language. Good overall performance; room for improvement in socratic depth.
A10: 9 | B10: 3 | C10: 3 | D10: 1 | E10: R1, R4 y R5 porque R2 se elimina y R3 también | F10: Si R5 crea un cortocircuito, ¿qué implicaría esto para la relación entre la corriente que fluye a través de R1 y R4 y la tensión total que observa el circuito? | G10: 3 | H10: 4 | I10: 4 | J10: 5 | K10: 16 | L10: 0.751 | M10: 41 | N10: 79.92 | O10: AC1, AC6 | P10: AC1, AC6, AC9 | Q10: 0.667 | R10: 1 | S10: 0.8 | W10: Socratic quality 3/5 (Clarification): Generic question: asks for clarification without attacking the root error. Conceptual precision 4/5 (Good): Good: clearly identifies the alternative conception with precise technical language. Good overall performance; room for improvement in socratic depth.
A11: 10 | B11: 4 | C11: 1 | D11: 1 | E11: R1 y R4 dado que R2 está en paralelo con la fuente, R3 en circuito abierto y R5 cortocircuitada | F11: Considerando que R5 está efectivamente cortocircuitada, ¿podría la presencia de R3, aunque aparentemente en circuito abierto, influir en la determinación del potencial en el nodo N2 en relación con tierra? | G11: 3 | H11: 3 | I11: 3 | J11: 5 | K11: 14 | L11: 0.846 | M11: 45 | N11: 70.95 | O11: AC1, AC6 | P11: AC1, AC9 | Q11: 0.5 | R11: 0.5 | S11: 0.5 | W11: Socratic quality 3/5 (Clarification): Generic question: asks for clarification without attacking the root error. Conceptual precision 3/5 (Sufficient): Sufficient: identifies that there is an error and uses correct concepts, but the diagnosis is somewhat vague. Good overall performance; room for improvement in socratic depth.
A12: 11 | B12: 4 | C12: 2 | D12: 1 | E12: R1, R2 y R3 dado que R2 y R3 están en paralelo y forman un divisor de tensión con R1 | F12: Si R3 estuviera realmente en circuito abierto, ¿cómo afectaría su ausencia a la distribución de la corriente entre R1 y R2, considerando que ambos están conectados a la fuente? | G12: 3 | H12: 3 | I12: 5 | J12: 5 | K12: 16 | L12: 0.745 | M12: 39 | N12: 80.52 | O12: AC1, AC9 | P12: AC1, AC9 | Q12: 1 | R12: 1 | S12: 1 | W12: Socratic quality 3/5 (Clarification): Generic question: asks for clarification without attacking the root error. Conceptual precision 3/5 (Sufficient): Sufficient: identifies that there is an error and uses correct concepts, but the diagnosis is somewhat vague. Good overall performance; room for improvement in socratic depth.
A13: 12 | B13: 4 | C13: 3 | D13: 1 | E13: R1, R2, R4 y R5 dado que R3 está en circuito abierto | F13: Dado que R3 está en circuito abierto, ¿cómo crees que la ausencia de esta resistencia afectará la corriente que fluye a través de R4, considerando su conexión en serie con R1 y R2? | G13: 3 | H13: 4 | I13: 5 | J13: 5 | K13: 17 | L13: 0.873 | M13: 45 | N13: 68.69 | O13: AC1, AC6 | P13: AC1 | Q13: 1 | R13: 0.5 | S13: 0.667 | W13: Socratic quality 3/5 (Clarification): Generic question: asks for clarification without attacking the root error. Conceptual precision 4/5 (Good): Good: clearly identifies the alternative conception with precise technical language. High-performing tutor: expert socratic guidance with precise diagnosis.
A14: 13 | B14: 5 | C14: 1 | D14: 1 | E14: R1, R2, R4 y R5 dado que R3 sobra | F14: Considerando que el interruptor entre N2 y N3 está abierto, ¿podrías explicar qué efecto tiene la ausencia de conexión en R5 sobre el flujo de corriente hacia tierra desde el nodo N2, y por qué eso podría influir en el potencial en N2? | G14: 3 | H14: 4 | I14: 3 | J14: 5 | K14: 15 | L14: 0.888 | M14: 58 | N14: 67.56 | O14: AC1, AC6 | P14: AC1, AC9 | Q14: 0.5 | R14: 0.5 | S14: 0.5 | W14: Socratic quality 3/5 (Clarification): Clarification: asks the student to explain their reasoning. Conceptual precision 4/5 (Good): Good: clearly identifies the alternative conception with precise technical language. Good overall performance; room for improvement in socratic depth.
A15: 14 | B15: 5 | C15: 2 | D15: 1 | E15: R1, R2, R4 y R5 dado que R3 no hace nada | F15: Si ignoramos temporalmente la presencia de R3 y nos enfocamos únicamente en la relación entre voltaje y resistencia en los nodos, ¿podrías describir cómo cambiaría la corriente que fluye a través de R1 si el interruptor se cerrara, y por qué? | G15: 3 | H15: 4 | I15: 3 | J15: 5 | K15: 15 | L15: 0.881 | M15: 57 | N15: 68.12 | O15: AC1, AC6 | P15: AC1 | Q15: 1 | R15: 0.5 | S15: 0.667 | W15: Socratic quality 3/5 (Clarification): Generic question: asks for clarification without attacking the root error. Conceptual precision 4/5 (Good): Good: clearly identifies the alternative conception with precise technical language. Good overall performance; room for improvement in socratic depth.
A16: 15 | B16: 5 | C16: 3 | D16: 1 | E16: R1, R2 y R4 dado que son las resistencias que forman parte del circuito. | F16: Si eliminamos R5 y R3, ¿cómo crees que la resistencia total del circuito afectaría la magnitud de la corriente que fluye a través de R2, y por qué es importante esa relación para el comportamiento del circuito? | G16: 3 | H16: 3 | I16: 3 | J16: 5 | K16: 14 | L16: 0.786 | M16: 49 | N16: 76.35 | P16: AC1 | Q16: 0 | R16: 1 | S16: 0 | W16: Socratic quality 3/5 (Clarification): Generic question: asks for clarification without attacking the root error. Conceptual precision 3/5 (Sufficient): Sufficient: identifies that there is an error and uses correct concepts, but the diagnosis is somewhat vague. Good overall performance; room for improvement in socratic depth.
A17: 16 | B17: 6 | C17: 1 | D17: 1 | E17: R1, R2 y R4 dado que R2 y R4 están en paralelo y forma un divisor de tensión con R1. | F17: Considerando que el interruptor está abierto, ¿cómo afecta la interrupción del flujo de corriente a través de la rama que incluye a R3, y qué implicaciones tiene esto para la contribución de esa resistencia al voltaje entre los nodos N2 y 0? | G17: 4 | H17: 4 | I17: 3 | J17: 5 | K17: 16 | L17: 0.89 | M17: 55 | N17: 67.44 | P17: AC1 | Q17: 0 | R17: 1 | S17: 0 | W17: Socratic quality 4/5 (Scaffolding for detection): Scaffolding for detection: identifies the error area and asks a question that confronts the theory. Conceptual precision 4/5 (Good): Good: clearly identifies the alternative conception with precise technical language. Good overall performance; room for improvement in socratic depth.
A18: 17 | B18: 6 | C18: 2 | D18: 1 | E18: R1, R2 y R4 dado que R3 está en abierto y R5 cortocircuitada | F18: Si la resistencia R5 está cortocircuitada, ¿cómo cambiaría la corriente total que fluye a través del circuito y, en consecuencia, ¿cómo afectaría esto al voltaje medido entre los nodos N1 y 0? | G18: 3 | H18: 3 | I18: 3 | J18: 5 | K18: 14 | L18: 0.774 | M18: 49 | N18: 77.49 | O18: AC1, AC6 | P18: AC1, AC9 | Q18: 0.5 | R18: 0.5 | S18: 0.5 | W18: Socratic quality 3/5 (Clarification): Generic question: asks for clarification without attacking the root error. Conceptual precision 3/5 (Sufficient): Sufficient: identifies that there is an error and uses correct concepts, but the diagnosis is somewhat vague. Good overall performance; room for improvement in socratic depth.
A19: 18 | B19: 6 | C19: 3 | D19: 1 | E19: R1, R2 y R4 dado que solo por estas resistencias circula una corriente diferente de cero | F19: Considerando que R2 y R4 están en paralelo, ¿podrías explicar qué efecto tendría la presencia de un cortocircuito en R5 sobre la distribución de la corriente a través de este divisor de tensión? | G19: 3 | H19: 4 | I19: 4 | J19: 5 | K19: 16 | L19: 0.808 | M19: 45 | N19: 74.25 | P19: AC1, AC6 | Q19: 0 | R19: 1 | S19: 0 | W19: Socratic quality 3/5 (Clarification): Clarification: asks the student to explain their reasoning. Conceptual precision 4/5 (Good): Good: clearly identifies the alternative conception with precise technical language. Good overall performance; room for improvement in socratic depth.
A20: 19 | B20: 7 | C20: 1 | D20: 1 | E20: R1, R2 y R4 dado que por R3 y por R5 no circula corriente | F20: Considerando que el interruptor está abierto, ¿cómo afecta la ausencia de conexión entre N2 y N3 a la capacidad de las resistencias R3 y R5 para influir en el potencial en ese nodo, específicamente en relación con la diferencia de potencial entre N2 y 0? | G20: 4 | H20: 4 | I20: 3 | J20: 5 | K20: 16 | L20: 0.904 | M20: 59 | N20: 66.39 | O20: AC1, AC6 | P20: AC1, AC9 | Q20: 0.5 | R20: 0.5 | S20: 0.5 | W20: Socratic quality 4/5 (Scaffolding for detection): Scaffolding for detection: identifies the error area and asks a question that confronts the theory. Conceptual precision 4/5 (Good): Good: clearly identifies the alternative conception with precise technical language. Good overall performance; room for improvement in socratic depth.
A21: 20 | B21: 7 | C21: 2 | D21: 1 | E21: R1, R2 y R4 dado que R3 y R5 se pueden quitar | F21: Si eliminamos R3 y R5, ¿cambiaría la relación entre el voltaje en el nodo N3 y el voltaje en el nodo N2, y por qué crees que eso podría ser así? | G21: 3 | H21: 3 | I21: 3 | J21: 5 | K21: 14 | L21: 0.816 | M21: 44 | N21: 73.51 | O21: AC1, AC6 | Q21: 1 | R21: 0 | S21: 0 | W21: Socratic quality 3/5 (Clarification): Generic question: asks for clarification without attacking the root error. Conceptual precision 3/5 (Sufficient): Sufficient: identifies that there is an error and uses correct concepts, but the diagnosis is somewhat vague. Good overall performance; room for improvement in socratic depth.
A22: 21 | B22: 7 | C22: 3 | D22: 1 | E22: R1, R2 y R4 dado que R3 y R5 no influyen para nada en la diferencia de potencial que se pide | F22: Considerando que R3 y R5 no tienen un camino para la corriente, ¿qué efecto crees que tendría su ausencia en la determinación de la diferencia de potencial entre los nodos N2 y N3? | G22: 3 | H22: 3 | I22: 3 | J22: 5 | K22: 14 | L22: 0.776 | M22: 43 | N22: 77.35 | O22: AC1, AC6 | P22: AC1, AC9 | Q22: 0.5 | R22: 0.5 | S22: 0.5 | W22: Socratic quality 3/5 (Clarification): Generic question: asks for clarification without attacking the root error. Conceptual precision 3/5 (Sufficient): Sufficient: identifies that there is an error and uses correct concepts, but the diagnosis is somewhat vague. Good overall performance; room for improvement in socratic depth.
A23: 22 | B23: 8 | C23: 1 | D23: 1 | E23: R1, R2 y R4 dado que R3 y R5 sobran | F23: Considerando que el interruptor está abierto, ¿podrías explicar cómo la ausencia de un camino continuo afecta la capacidad de las resistencias R3 y R5 para influir en el potencial entre los nodos N2 y 0? | G23: 3 | H23: 4 | I23: 3 | J23: 5 | K23: 15 | L23: 0.797 | M23: 48 | N23: 75.27 | O23: AC1, AC6 | P23: AC1, AC9 | Q23: 0.5 | R23: 0.5 | S23: 0.5 | W23: Socratic quality 3/5 (Clarification): Clarification: asks the student to explain their reasoning. Conceptual precision 4/5 (Good): Good: clearly identifies the alternative conception with precise technical language. Good overall performance; room for improvement in socratic depth.
A24: 23 | B24: 8 | C24: 2 | D24: 1 | E24: R1, R2 y R4 dado que R3 sobra | F24: Si el circuito está configurado de esta manera, ¿cómo crees que la resistencia de R1 afectaría la corriente que fluye a través de R2, considerando que R4 está en paralelo? | G24: 3 | H24: 3 | I24: 4 | J24: 5 | K24: 15 | L24: 0.841 | M24: 42 | N24: 71.34 | O24: AC1 | P24: AC1 | Q24: 1 | R24: 1 | S24: 1 | W24: Socratic quality 3/5 (Clarification): Generic question: asks for clarification without attacking the root error. Conceptual precision 3/5 (Sufficient): Sufficient: identifies that there is an error and uses correct concepts, but the diagnosis is somewhat vague. Good overall performance; room for improvement in socratic depth.
A25: 24 | B25: 8 | C25: 3 | D25: 1 | E25: R1, R2 y R4 dado que R5 sobra | F25: Pensando en el flujo de corriente a través de R2, ¿cómo crees que la presencia de R4, en paralelo, alteraría la distribución de voltaje en comparación con un circuito que solo contuviera R2 y R5? | G25: 3 | H25: 3 | I25: 4 | J25: 5 | K25: 15 | L25: 0.825 | M25: 50 | N25: 72.73 | O25: AC6 | P25: AC1 | Q25: 0 | R25: 0 | S25: 0 | W25: Socratic quality 3/5 (Clarification): Generic question: asks for clarification without attacking the root error. Conceptual precision 3/5 (Sufficient): Sufficient: identifies that there is an error and uses correct concepts, but the diagnosis is somewhat vague. Good overall performance; room for improvement in socratic depth.
A26: 25 | B26: 9 | C26: 1 | D26: 1 | E26: R1, R2 y R4 dado que R3 está en abierto | F26: Considerando que R3 está efectivamente en circuito abierto, ¿podría haber otras resistencias en el camino entre el nodo N2 y el nodo de referencia (0) que aún influyen en la diferencia de potencial, y si es así, ¿cómo se conectan a N2? | G26: 3 | H26: 5 | I26: 3 | J26: 5 | K26: 16 | L26: 0.891 | M26: 58 | N26: 67.33 | O26: AC1 | P26: AC1, AC9 | Q26: 0.5 | R26: 1 | S26: 0.667 | W26: Socratic quality 3/5 (Clarification): Generic question: asks for clarification without attacking the root error. Conceptual precision 5/5 (Excellent): Excellent: identifies the specific alternative conception and connects it with the circuit topology. Good overall performance; room for improvement in socratic depth.
A27: 26 | B27: 9 | C27: 2 | D27: 1 | E27: R1, R2 y R4 dado que R5 cortocircuitada | F27: Si R5 está cortocircuitada, ¿cómo afectaría la corriente que fluye a través de R1 y R2, y qué implicaciones tendría esto para la resistencia equivalente entre esos dos componentes? | G27: 3 | H27: 3 | I27: 4 | J27: 5 | K27: 15 | L27: 0.788 | M27: 43 | N27: 76.11 | O27: AC6 | P27: AC1 | Q27: 0 | R27: 0 | S27: 0 | W27: Socratic quality 3/5 (Clarification): Generic question: asks for clarification without attacking the root error. Conceptual precision 3/5 (Sufficient): Sufficient: identifies that there is an error and uses correct concepts, but the diagnosis is somewhat vague. Good overall performance; room for improvement in socratic depth.
A28: 27 | B28: 9 | C28: 3 | D28: 1 | E28: R1, R2 y R4 dado que por R3 no circula corriente | F28: Si R3 está en circuito abierto, ¿cómo afecta la ausencia de flujo de corriente a través de él a la tensión que podrías medir en cualquier nodo del circuito, y qué papel juega la tensión en el cálculo de la corriente? | G28: 4 | H28: 4 | I28: 3 | J28: 5 | K28: 16 | L28: 0.819 | M28: 48 | N28: 73.28 | O28: AC1 | P28: AC1 | Q28: 1 | R28: 1 | S28: 1 | W28: Socratic quality 4/5 (Scaffolding for detection): Scaffolding for detection: identifies the error area and asks a question that confronts the theory. Conceptual precision 4/5 (Good): Good: clearly identifies the alternative conception with precise technical language. Good overall performance; room for improvement in socratic depth.
A29: 28 | B29: 10 | C29: 1 | D29: 1 | E29: R1, R2 y R4 dado que por R5 no circula corriente | F29: Considerando que R5 está efectivamente cortocircuitada, ¿qué implicaciones tiene esto para la trayectoria que puede tomar la corriente desde V1 hacia el nodo N2, y cómo podría esto afectar la caída de voltaje en las resistencias R1, R2 y R4? | G29: 3 | H29: 3 | I29: 4 | J29: 5 | K29: 15 | L29: 0.874 | M29: 57 | N29: 68.66 | O29: AC6 | P29: AC1, AC9 | Q29: 0 | R29: 0 | S29: 0 | W29: Socratic quality 3/5 (Clarification): Generic question: asks for clarification without attacking the root error. Conceptual precision 3/5 (Sufficient): Sufficient: identifies that there is an error and uses correct concepts, but the diagnosis is somewhat vague. Good overall performance; room for improvement in socratic depth.
A30: 29 | B30: 10 | C30: 2 | D30: 1 | E30: R1, R2 y R4 dado que R3 se puede quitar | F30: Si eliminas R3, ¿cómo cambiaría la relación entre la corriente que fluye a través de R2 y la caída de voltaje en R1, y ¿qué efecto tendría esto en la ley de Ohm? | G30: 3 | H30: 3 | I30: 4 | J30: 5 | K30: 15 | L30: 0.879 | M30: 45 | N30: 68.3 | O30: AC1 | P30: AC1 | Q30: 1 | R30: 1 | S30: 1 | W30: Socratic quality 3/5 (Clarification): Generic question: asks for clarification without attacking the root error. Conceptual precision 3/5 (Sufficient): Sufficient: identifies that there is an error and uses correct concepts, but the diagnosis is somewhat vague. Good overall performance; room for improvement in socratic depth.
A31: 30 | B31: 10 | C31: 3 | D31: 1 | E31: R1, R2 y R4 dado que R5 se puede quitar | F31: Si se elimina R5, ¿cómo afectaría esto a la posibilidad de que la corriente fluya a través de la red y, en consecuencia, ¿cómo se vería la relación entre el voltaje y la resistencia en este circuito modificado? | G31: 3 | H31: 3 | I31: 3 | J31: 5 | K31: 14 | L31: 0.816 | M31: 50 | N31: 73.55 | O31: AC6 | P31: AC1, AC9 | Q31: 0 | R31: 0 | S31: 0 | W31: Socratic quality 3/5 (Clarification): Generic question: asks for clarification without attacking the root error. Conceptual precision 3/5 (Sufficient): Sufficient: identifies that there is an error and uses correct concepts, but the diagnosis is somewhat vague. Good overall performance; room for improvement in socratic depth.
A32: 31 | B32: 11 | C32: 1 | D32: 1 | E32: R1, R2 y R4 dado que R3 no influye para nada en la diferencia de potencial que se pide | F32: Considerando que R3 está físicamente abierto, ¿podría haber una ruta alternativa para la corriente desde el nodo N2 hasta el nodo de referencia (0) que involucre componentes distintos a R1, R2 y R4, o es tu razonamiento completo? | G32: 3 | H32: 3 | I32: 5 | J32: 5 | K32: 16 | L32: 0.904 | M32: 57 | N32: 66.35 | O32: AC1 | P32: AC1, AC9 | Q32: 0.5 | R32: 1 | S32: 0.667 | W32: Socratic quality 3/5 (Clarification): Generic question: asks for clarification without attacking the root error. Conceptual precision 3/5 (Sufficient): Sufficient: identifies that there is an error and uses correct concepts, but the diagnosis is somewhat vague. Good overall performance; room for improvement in socratic depth.
A33: 32 | B33: 11 | C33: 2 | D33: 1 | E33: R1, R2 y R4 dado que R5 no influye para nada en la diferencia de potencial que se pide | F33: Si R5 está desconectado, ¿cambia la forma en que la corriente fluye entre los nodos N1 y N2, y por qué crees que esto podría afectar la diferencia de potencial medida? | G33: 3 | H33: 3 | I33: 3 | J33: 5 | K33: 14 | L33: 0.798 | M33: 44 | N33: 75.23 | O33: AC6 | P33: AC1 | Q33: 0 | R33: 0 | S33: 0 | W33: Socratic quality 3/5 (Clarification): Generic question: asks for clarification without attacking the root error. Conceptual precision 3/5 (Sufficient): Sufficient: identifies that there is an error and uses correct concepts, but the diagnosis is somewhat vague. Good overall performance; room for improvement in socratic depth.
... A36: 35 | B36: 12 | C36: 2 | D36: 1 | E36: R1 y R2 | F36: Si el interruptor entre N2 y N3 impide el flujo de corriente a través de R1 y R2, ¿qué característica fundamental de los circuitos eléctricos define cómo la corriente fluye a través de los componentes conectados en serie? | G36: 3 | H36: 3 | I36: 2 | J36: 5 | K36: 13 | L36: 0.816 | M36: 48 | N36: 73.49 | O36: AC9 | P36: AC1, AC9 | Q36: 0.5 | R36: 1 | S36: 0.667 | W36: Socratic quality 3/5 (Clarification): Generic question: asks for clarification without attacking the root error. Conceptual precision 3/5 (Sufficient): Sufficient: identifies that there is an error and uses correct concepts, but the diagnosis is somewhat vague. Good overall performance; room for improvement in socratic depth.
A37: 36 | B37: 12 | C37: 3 | D37: 1 | E37: R1, R2 y R4 | F37: Si el interruptor entre N2 y N3 ahora está cerrado, ¿qué componente, al estar en el mismo camino que la fuente de tensión, determinará la magnitud de la corriente que fluye hacia N2? | G37: 3 | H37: 4 | I37: 2 | J37: 5 | K37: 14 | L37: 0.774 | M37: 45 | N37: 77.53 | P37: AC1, AC6, AC9 | Q37: 0 | R37: 1 | S37: 0 | W37: Socratic quality 3/5 (Clarification): Generic question: asks for clarification without attacking the root error. Conceptual precision 4/5 (Good): Good: clearly identifies the alternative conception with precise technical language. Good overall performance; room for improvement in socratic depth.
A38: 37 | B38: 13 | C38: 1 | D38: 1 | E38: R1, R2, R4 y R5 | F38: Considerando que el interruptor entre N2 y N3 está abierto, ¿cómo afecta la ausencia de una conexión directa entre esos dos nodos al potencial resultante en N2 en relación con la Tierra? | G38: 4 | H38: 3 | I38: 2 | J38: 5 | K38: 14 | L38: 0.78 | M38: 41 | N38: 76.95 | O38: AC6 | P38: AC1, AC9 | Q38: 0 | R38: 0 | S38: 0 | W38: Socratic quality 4/5 (Scaffolding for detection): Scaffolding for detection: identifies the error area and asks a question that confronts the theory. Conceptual precision 3/5 (Sufficient): Sufficient: identifies that there is an error and uses correct concepts, but the diagnosis is somewhat vague. Good overall performance; room for improvement in socratic depth.
A39: 38 | B39: 13 | C39: 2 | D39: 1 | E39: R1, R2, R3 y R4 | F39: Si el interruptor entre N2 y N3 permanece abierto, ¿podría explicar cómo la resistencia de R3 en particular influye en el flujo de corriente a través del circuito, considerando que está conectado a N1? | G39: 3 | H39: 5 | I39: 3 | J39: 5 | K39: 16 | L39: 0.792 | M39: 46 | N39: 75.73 | O39: AC1 | P39: AC1, AC9 | Q39: 0.5 | R39: 1 | S39: 0.667 | W39: Socratic quality 3/5 (Clarification): Generic question: asks for clarification without attacking the root error. Conceptual precision 5/5 (Excellent): Excellent: identifies the specific alternative conception and connects it with the circuit topology. Good overall performance; room for improvement in socratic depth.
A40: 39 | B40: 13 | C40: 3 | D40: 1 | E40: R1 y R2 y R4 hacen un divisor de corriente | F40: Si R1 y R2 están en serie, ¿cómo afecta la combinación de sus resistencias al flujo total de corriente a través del circuito, considerando que ambos están conectados a un nodo común? | G40: 4 | H40: 4 | I40: 4 | J40: 5 | K40: 17 | L40: 0.8 | M40: 39 | N40: 75.01 | P40: AC1, AC6, AC9 | Q40: 0 | R40: 1 | S40: 0 | W40: Socratic quality 4/5 (Scaffolding for detection): Scaffolding for detection: identifies the error area and asks a question that confronts the theory. Conceptual precision 4/5 (Good): Good: clearly identifies the alternative conception with precise technical language. High-performing tutor: expert socratic guidance with precise diagnosis.
A41: 40 | B41: 14 | C41: 1 | D41: 1 | E41: R1 y R2 y R4 hacen un divisor de tensión, r3 no cuenta por estar en corto | F41: Considerando que R5 está cortocircuitada, ¿cómo afecta esta condición a la corriente que podría circular a través de R3 y, en consecuencia, a su contribución al potencial entre N2 y 0? | G41: 4 | H41: 2 | I41: 3 | J41: 5 | K41: 14 | L41: 0.811 | M41: 46 | N41: 74.01 | O41: AC1 | P41: AC1 | Q41: 1 | R41: 1 | S41: 1 | W41: Socratic quality 4/5 (Scaffolding for detection): Scaffolding for detection: identifies the error area and asks a question that confronts the theory. Conceptual precision 2/5 (Poor): Poor: responds generically without diagnosing the conceptual error. Good overall performance; room for improvement in socratic depth.
A42: 41 | B42: 14 | C42: 2 | D42: 1 | E42: No tengo en cuenta R3 porque el interruptor está cerrado | F42: Si el interruptor está cerrado, ¿cómo crees que la presencia de R3 modifica la relación entre el voltaje aplicado y el voltaje que podrías medir en un nodo específico del circuito? | G42: 3 | H42: 4 | I42: 5 | J42: 5 | K42: 17 | L42: 0.748 | M42: 39 | N42: 80.25 | O42: AC1, AC9 | P42: AC1, AC9 | Q42: 1 | R42: 1 | S42: 1 | W42: Socratic quality 3/5 (Clarification): Generic question: asks for clarification without attacking the root error. Conceptual precision 4/5 (Good): Good: clearly identifies the alternative conception with precise technical language. High-performing tutor: expert socratic guidance with precise diagnosis.
...

Sheet Metadata
A1: Field | B1: Value
A2: Generation date | B2: 2026-05-21T11:40:46.051160
A3: Method | B3: RAG
A4: Models evaluated | B4: gemma3:27b, gemma3:4b
A5: Exercises covered | B5: 1, 3, 4, 5, 6, 7
A6: Total evaluations | B6: 396
A7: UPV Ollama URL | B7: https://ollama.gti-ia.upv.es:443
A8: PoliGPT URL | B8: https://api.poligpt.upv.es

Sheet Ranking
