Workbook

Sheet Results_gemma3_27b
A1: ID | B1: Conversation | C1: Turn | D1: Exercise | E1: Student Answer | F1: Tutor Socratic Response | G1: Socratic Quality | H1: Conceptual Precision | I1: Consistency | J1: Hallucination Rate | K1: Total Score | L1: Latency (s) | M1: Tokens | N1: Throughput (resp/min) | O1: Expected ACs | P1: Detected ACs | Q1: AC Precision | R1: AC Recall | S1: AC F1 | T1: Faithfulness | U1: Relevance | V1: Think Content | W1: Constructive Feedback
A2: 85 | B2: 29 | C2: 1 | D2: 1 | E2: R1 y R2 dado que las dos resistencia forman un divisor de tensión | F2: Considerando que el interruptor entre N2 y N3 está abierto, ¿cómo afecta esto al flujo de corriente a través de todas las resistencias conectadas a esos nodos? | G2: 4 | H2: 4 | I2: 3 | J2: 5 | K2: 16 | L2: 1.772 | M2: 36 | N2: 33.86 | O2: AC9 | P2: AC1, AC9 | Q2: 0.5 | R2: 1 | S2: 0.667 | W2: Socratic quality 4/5 (Scaffolding for detection): Scaffolding for detection: identifies the error area and asks a question that confronts the theory. Conceptual precision 4/5 (Good): Good: clearly identifies the alternative conception with precise technical language. Good overall performance; room for improvement in socratic depth.
A3: 86 | B3: 29 | C3: 2 | D3: 1 | E3: R1 y R2 dado que se pide la tensión en R2 | F3: Si conoces la tensión total aplicada al divisor de tensión y la resistencia de R1, ¿qué información adicional necesitarías para calcular la caída de tensión específicamente en R2? | G3: 3 | H3: 3 | I3: 5 | J3: 5 | K3: 16 | L3: 1.196 | M3: 36 | N3: 50.17 | O3: AC9 | Q3: 1 | R3: 0 | S3: 0 | W3: Socratic quality 3/5 (Clarification): Generic question: asks for clarification without attacking the root error. Conceptual precision 3/5 (Sufficient): Sufficient: identifies that there is an error and uses correct concepts, but the diagnosis is somewhat vague. Good overall performance; room for improvement in socratic depth.
A4: 87 | B4: 29 | C4: 3 | D4: 1 | E4: R1 y R2 por identificar un divisor de tensión | F4: Dado que tienes un divisor de tensión compuesto por R1 y R2, ¿cómo se relaciona la resistencia de cada componente con la proporción de la tensión total que cae sobre ella? | G4: 3 | H4: 3 | I4: 5 | J4: 5 | K4: 16 | L4: 1.224 | M4: 37 | N4: 49.02 | O4: AC9 | Q4: 1 | R4: 0 | S4: 0 | W4: Socratic quality 3/5 (Clarification): Generic question: asks for clarification without attacking the root error. Conceptual precision 3/5 (Sufficient): Sufficient: identifies that there is an error and uses correct concepts, but the diagnosis is somewhat vague. Good overall performance; room for improvement in socratic depth.
A5: 88 | B5: 30 | C5: 1 | D5: 1 | E5: R1 y R2 hacen un divisor de tensión | F5: Considerando que el interruptor entre N2 y N3 está abierto, ¿cómo afecta esta condición al flujo de corriente a través de todas las resistencias conectadas a esos nodos? | G5: 4 | H5: 4 | I5: 3 | J5: 5 | K5: 16 | L5: 1.341 | M5: 37 | N5: 44.73 | O5: AC9 | P5: AC1, AC9 | Q5: 0.5 | R5: 1 | S5: 0.667 | W5: Socratic quality 4/5 (Scaffolding for detection): Scaffolding for detection: identifies the error area and asks a question that confronts the theory. Conceptual precision 4/5 (Good): Good: clearly identifies the alternative conception with precise technical language. Good overall performance; room for improvement in socratic depth.
A6: 89 | B6: 30 | C6: 2 | D6: 1 | E6: R1, R2, R3 y R4 porque R5 está cortocircuitada | F6: Si R5 está efectivamente en cortocircuito, ¿cómo impacta este cortocircuito en la diferencia de potencial a través de ella y, por ende, en el potencial del nodo donde se conecta? | G6: 3 | H6: 4 | I6: 3 | J6: 5 | K6: 15 | L6: 1.329 | M6: 42 | N6: 45.14 | O6: AC1, AC6 | P6: AC6 | Q6: 1 | R6: 0.5 | S6: 0.667 | W6: Socratic quality 3/5 (Clarification): Generic question: asks for clarification without attacking the root error. Conceptual precision 4/5 (Good): Good: clearly identifies the alternative conception with precise technical language. Good overall performance; room for improvement in socratic depth.
A7: 90 | B7: 30 | C7: 3 | D7: 1 | E7: R1, R2, R3 y R4 porque por R5 no circula corriente | F7: Si no circula corriente a través de R5 debido al cortocircuito, ¿cómo afecta esto a la distribución de la corriente total proveniente de la fuente a través de las ramas que contienen R3 y R4? | G7: 4 | H7: 3 | I7: 4 | J7: 5 | K7: 16 | L7: 1.303 | M7: 45 | N7: 46.04 | O7: AC1, AC6 | P7: AC1, AC6 | Q7: 1 | R7: 1 | S7: 1 | W7: Socratic quality 4/5 (Scaffolding for detection): Scaffolding for detection: identifies the error area and asks a question that confronts the theory. Conceptual precision 3/5 (Sufficient): Sufficient: identifies that there is an error and uses correct concepts, but the diagnosis is somewhat vague. Good overall performance; room for improvement in socratic depth.
A8: 91 | B8: 31 | C8: 1 | D8: 1 | E8: R1, R2, R3 y R4 porque R5 se quita | F8: Si observas cuidadosamente el netlist, ¿qué relación de conexión existe entre los terminales de la resistencia R5 y cómo afecta esto al flujo de corriente a través de ella? | G8: 3 | H8: 3 | I8: 3 | J8: 5 | K8: 14 | L8: 1.344 | M8: 37 | N8: 44.64 | O8: AC1, AC6 | P8: AC1, AC6 | Q8: 1 | R8: 1 | S8: 1 | W8: Socratic quality 3/5 (Clarification): Generic question: asks for clarification without attacking the root error. Conceptual precision 3/5 (Sufficient): Sufficient: identifies that there is an error and uses correct concepts, but the diagnosis is somewhat vague. Good overall performance; room for improvement in socratic depth.
A9: 92 | B9: 31 | C9: 2 | D9: 1 | E9: R1, R3 y R4 porque R2 está en paralelo con la fuente y R5 corctocircuitada | F9: Si una resistencia está en paralelo con una fuente de voltaje ideal, ¿cómo describirías la diferencia de potencial a través de esa resistencia y qué implicaciones tiene esto para la corriente que fluye a través del circuito? | G9: 3 | H9: 3 | I9: 3 | J9: 5 | K9: 14 | L9: 1.337 | M9: 44 | N9: 44.87 | O9: AC1, AC6 | P9: AC1 | Q9: 1 | R9: 0.5 | S9: 0.667 | W9: Socratic quality 3/5 (Clarification): Generic question: asks for clarification without attacking the root error. Conceptual precision 3/5 (Sufficient): Sufficient: identifies that there is an error and uses correct concepts, but the diagnosis is somewhat vague. Good overall performance; room for improvement in socratic depth.
A10: 93 | B10: 31 | C10: 3 | D10: 1 | E10: R1, R4 y R5 porque R2 se elimina y R3 también | F10: Considerando que has eliminado R2 y R3 de tu análisis, ¿cómo describirías la configuración resultante del circuito con respecto a R1, R4 y R5: están en serie, en paralelo o una combinación de ambas? | G10: 3 | H10: 3 | I10: 5 | J10: 5 | K10: 16 | L10: 1.391 | M10: 48 | N10: 43.13 | O10: AC1, AC6 | Q10: 1 | R10: 0 | S10: 0 | W10: Socratic quality 3/5 (Clarification): Generic question: asks for clarification without attacking the root error. Conceptual precision 3/5 (Sufficient): Sufficient: identifies that there is an error and uses correct concepts, but the diagnosis is somewhat vague. Good overall performance; room for improvement in socratic depth.
A11: 94 | B11: 32 | C11: 1 | D11: 1 | E11: R1 y R4 dado que R2 está en paralelo con la fuente, R3 en circuito abierto y R5 cortocircuitada | F11: Considerando que R2 está en paralelo con la fuente, ¿cómo afecta esta configuración a la corriente que fluye a través de R2 en comparación con la corriente total proveniente de la fuente? | G11: 4 | H11: 3 | I11: 3 | J11: 5 | K11: 15 | L11: 1.425 | M11: 41 | N11: 42.12 | O11: AC1, AC6 | P11: AC1 | Q11: 1 | R11: 0.5 | S11: 0.667 | W11: Socratic quality 4/5 (Scaffolding for detection): Scaffolding for detection: identifies the error area and asks a question that confronts the theory. Conceptual precision 3/5 (Sufficient): Sufficient: identifies that there is an error and uses correct concepts, but the diagnosis is somewhat vague. Good overall performance; room for improvement in socratic depth.
A12: 95 | B12: 32 | C12: 2 | D12: 1 | E12: R1, R2 y R3 dado que R2 y R3 están en paralelo y forman un divisor de tensión con R1 | F12: Si R2 y R3 están en paralelo, ¿cómo se compara el voltaje a través de R2 con el voltaje a través de R3, y cómo impacta esto en la corriente que circula por cada resistencia? | G12: 3 | H12: 3 | I12: 4 | J12: 5 | K12: 15 | L12: 1.332 | M12: 45 | N12: 45.04 | O12: AC1, AC9 | P12: AC1 | Q12: 1 | R12: 0.5 | S12: 0.667 | W12: Socratic quality 3/5 (Clarification): Generic question: asks for clarification without attacking the root error. Conceptual precision 3/5 (Sufficient): Sufficient: identifies that there is an error and uses correct concepts, but the diagnosis is somewhat vague. Good overall performance; room for improvement in socratic depth.
A13: 96 | B13: 32 | C13: 3 | D13: 1 | E13: R1, R2, R4 y R5 dado que R3 está en circuito abierto | F13: Dado que R3 está en circuito abierto, ¿cómo crees que esto afecta el flujo de corriente en el resto del circuito y, específicamente, en R4 y R5? | G13: 3 | H13: 3 | I13: 4 | J13: 5 | K13: 15 | L13: 1.204 | M13: 37 | N13: 49.83 | O13: AC1, AC6 | P13: AC1 | Q13: 1 | R13: 0.5 | S13: 0.667 | W13: Socratic quality 3/5 (Clarification): Generic question: asks for clarification without attacking the root error. Conceptual precision 3/5 (Sufficient): Sufficient: identifies that there is an error and uses correct concepts, but the diagnosis is somewhat vague. Good overall performance; room for improvement in socratic depth.
A14: 97 | B14: 33 | C14: 1 | D14: 1 | E14: R1, R2, R4 y R5 dado que R3 sobra | F14: Si examinas cuidadosamente el netlist, ¿qué relación observas entre los nodos conectados a los terminales de R5? | G14: 3 | H14: 3 | I14: 3 | J14: 5 | K14: 14 | L14: 1.138 | M14: 26 | N14: 52.75 | O14: AC1, AC6 | P14: AC6 | Q14: 1 | R14: 0.5 | S14: 0.667 | W14: Socratic quality 3/5 (Clarification): Generic question: asks for clarification without attacking the root error. Conceptual precision 3/5 (Sufficient): Sufficient: identifies that there is an error and uses correct concepts, but the diagnosis is somewhat vague. Good overall performance; room for improvement in socratic depth.
A15: 98 | B15: 33 | C15: 2 | D15: 1 | E15: R1, R2, R4 y R5 dado que R3 no hace nada | F15: Si R3 no participa en el circuito, ¿cómo afectaría esto a la corriente que fluye a través de R5 en comparación con si R3 estuviera presente? | G15: 3 | H15: 2 | I15: 3 | J15: 5 | K15: 13 | L15: 1.143 | M15: 36 | N15: 52.51 | O15: AC1, AC6 | P15: AC1 | Q15: 1 | R15: 0.5 | S15: 0.667 | W15: Socratic quality 3/5 (Clarification): Generic question: asks for clarification without attacking the root error. Conceptual precision 2/5 (Poor): Poor: responds generically without diagnosing the conceptual error. Good overall performance; room for improvement in socratic depth.
A16: 99 | B16: 33 | C16: 3 | D16: 1 | E16: R1, R2 y R4 dado que son las resistencias que forman parte del circuito. | F16: Considerando que un circuito completo requiere un camino cerrado para el flujo de corriente, ¿cómo describirías la función de R5 en relación con completar ese camino? | G16: 3 | H16: 3 | I16: 3 | J16: 5 | K16: 14 | L16: 1.108 | M16: 33 | N16: 54.17 | P16: AC1, AC9 | Q16: 0 | R16: 1 | S16: 0 | W16: Socratic quality 3/5 (Clarification): Generic question: asks for clarification without attacking the root error. Conceptual precision 3/5 (Sufficient): Sufficient: identifies that there is an error and uses correct concepts, but the diagnosis is somewhat vague. Good overall performance; room for improvement in socratic depth.
A17: 100 | B17: 34 | C17: 1 | D17: 1 | E17: R1, R2 y R4 dado que R2 y R4 están en paralelo y forma un divisor de tensión con R1. | F17: Considerando el interruptor abierto entre N2 y N3, ¿cómo afecta esto al flujo de corriente a través de cada una de las resistencias que mencionaste y, por lo tanto, a su contribución a la diferencia de potencial entre N2 y 0? | G17: 4 | H17: 4 | I17: 3 | J17: 5 | K17: 16 | L17: 1.704 | M17: 55 | N17: 35.2 | P17: AC1, AC9 | Q17: 0 | R17: 1 | S17: 0 | W17: Socratic quality 4/5 (Scaffolding for detection): Scaffolding for detection: identifies the error area and asks a question that confronts the theory. Conceptual precision 4/5 (Good): Good: clearly identifies the alternative conception with precise technical language. Good overall performance; room for improvement in socratic depth.
A18: 101 | B18: 34 | C18: 2 | D18: 1 | E18: R1, R2 y R4 dado que R3 está en abierto y R5 cortocircuitada | F18: Si R5 está en cortocircuito, ¿cómo impacta esto en la corriente que fluye a través de R4 y, consecuentemente, en la efectividad de R2 y R4 como divisor de tensión con R1? | G18: 3 | H18: 4 | I18: 5 | J18: 5 | K18: 17 | L18: 1.397 | M18: 50 | N18: 42.94 | O18: AC1, AC6 | P18: AC1, AC6 | Q18: 1 | R18: 1 | S18: 1 | W18: Socratic quality 3/5 (Clarification): Generic question: asks for clarification without attacking the root error. Conceptual precision 4/5 (Good): Good: clearly identifies the alternative conception with precise technical language. High-performing tutor: expert socratic guidance with precise diagnosis.
A19: 102 | B19: 34 | C19: 3 | D19: 1 | E19: R1, R2 y R4 dado que solo por estas resistencias circula una corriente diferente de cero | F19: Dado que R3 está abierto y R5 en cortocircuito, ¿cómo describirías la configuración resultante en términos de caminos alternativos para la corriente y cómo esto influye en la resistencia total del circuito? | G19: 3 | H19: 4 | I19: 3 | J19: 5 | K19: 15 | L19: 1.303 | M19: 43 | N19: 46.06 | P19: AC1, AC6, AC9 | Q19: 0 | R19: 1 | S19: 0 | W19: Socratic quality 3/5 (Clarification): Generic question: asks for clarification without attacking the root error. Conceptual precision 4/5 (Good): Good: clearly identifies the alternative conception with precise technical language. Good overall performance; room for improvement in socratic depth.
A20: 103 | B20: 35 | C20: 1 | D20: 1 | E20: R1, R2 y R4 dado que por R3 y por R5 no circula corriente | F20: Considerando el netlist, ¿qué condición eléctrica comparten los terminales de R5 y cómo afecta esto al flujo de corriente a través de ella? | G20: 3 | H20: 3 | I20: 3 | J20: 5 | K20: 14 | L20: 1.254 | M20: 31 | N20: 47.83 | O20: AC1, AC6 | P20: AC1, AC6 | Q20: 1 | R20: 1 | S20: 1 | W20: Socratic quality 3/5 (Clarification): Generic question: asks for clarification without attacking the root error. Conceptual precision 3/5 (Sufficient): Sufficient: identifies that there is an error and uses correct concepts, but the diagnosis is somewhat vague. Good overall performance; room for improvement in socratic depth.
A21: 104 | B21: 35 | C21: 2 | D21: 1 | E21: R1, R2 y R4 dado que R3 y R5 se pueden quitar | F21: Si R3 y R5 no tienen corriente circulando, ¿cómo describirías la diferencia de potencial entre sus terminales y qué implicaciones tiene esto para la configuración del circuito? | G21: 3 | H21: 3 | I21: 3 | J21: 5 | K21: 14 | L21: 1.184 | M21: 37 | N21: 50.68 | O21: AC1, AC6 | P21: AC1, AC6, AC9 | Q21: 0.667 | R21: 1 | S21: 0.8 | W21: Socratic quality 3/5 (Clarification): Generic question: asks for clarification without attacking the root error. Conceptual precision 3/5 (Sufficient): Sufficient: identifies that there is an error and uses correct concepts, but the diagnosis is somewhat vague. Good overall performance; room for improvement in socratic depth.
A22: 105 | B22: 35 | C22: 3 | D22: 1 | E22: R1, R2 y R4 dado que R3 y R5 no influyen para nada en la diferencia de potencial que se pide | F22: Si R3 y R5 no influyen en la diferencia de potencial, ¿cómo describirías la configuración de los componentes en términos de conexiones en serie y en paralelo, y cómo afectaría esto al cálculo de la resistencia equivalente del circuito? | G22: 3 | H22: 3 | I22: 3 | J22: 5 | K22: 14 | L22: 1.396 | M22: 49 | N22: 42.97 | O22: AC1, AC6 | Q22: 1 | R22: 0 | S22: 0 | W22: Socratic quality 3/5 (Clarification): Generic question: asks for clarification without attacking the root error. Conceptual precision 3/5 (Sufficient): Sufficient: identifies that there is an error and uses correct concepts, but the diagnosis is somewhat vague. Good overall performance; room for improvement in socratic depth.
A23: 106 | B23: 36 | C23: 1 | D23: 1 | E23: R1, R2 y R4 dado que R3 y R5 sobran | F23: Si observas cuidadosamente la conexión entre los nodos N2 y N3, ¿qué implicación tiene el estado del interruptor en la posible circulación de corriente a través de R3? | G23: 3 | H23: 4 | I23: 3 | J23: 5 | K23: 15 | L23: 1.349 | M23: 38 | N23: 44.47 | O23: AC1, AC6 | P23: AC1 | Q23: 1 | R23: 0.5 | S23: 0.667 | W23: Socratic quality 3/5 (Clarification): Generic question: asks for clarification without attacking the root error. Conceptual precision 4/5 (Good): Good: clearly identifies the alternative conception with precise technical language. Good overall performance; room for improvement in socratic depth.
A24: 107 | B24: 36 | C24: 2 | D24: 1 | E24: R1, R2 y R4 dado que R3 sobra | F24: Considerando que la corriente busca el camino de menor resistencia, ¿cómo afectaría la presencia de R3 al flujo de corriente entre los nodos N2 y N3, en comparación con el camino a través de R4? | G24: 3 | H24: 3 | I24: 4 | J24: 5 | K24: 15 | L24: 1.342 | M24: 46 | N24: 44.71 | O24: AC1 | P24: AC1, AC9 | Q24: 0.5 | R24: 1 | S24: 0.667 | W24: Socratic quality 3/5 (Clarification): Generic question: asks for clarification without attacking the root error. Conceptual precision 3/5 (Sufficient): Sufficient: identifies that there is an error and uses correct concepts, but the diagnosis is somewhat vague. Good overall performance; room for improvement in socratic depth.
A25: 108 | B25: 36 | C25: 3 | D25: 1 | E25: R1, R2 y R4 dado que R5 sobra | F25: Si R5 estuviera presente y conectado en paralelo con R4, ¿cómo cambiaría la resistencia total del circuito y, por lo tanto, la corriente que fluye desde la fuente? | G25: 3 | H25: 3 | I25: 4 | J25: 5 | K25: 15 | L25: 1.23 | M25: 39 | N25: 48.79 | O25: AC6 | P25: AC1, AC9 | Q25: 0 | R25: 0 | S25: 0 | W25: Socratic quality 3/5 (Clarification): Generic question: asks for clarification without attacking the root error. Conceptual precision 3/5 (Sufficient): Sufficient: identifies that there is an error and uses correct concepts, but the diagnosis is somewhat vague. Good overall performance; room for improvement in socratic depth.
A26: 109 | B26: 37 | C26: 1 | D26: 1 | E26: R1, R2 y R4 dado que R3 está en abierto | F26: Considerando que el interruptor entre N2 y N3 está abierto, ¿qué implicaciones tiene esto para la corriente que podría fluir a través de cualquier componente conectado a esos nodos? | G26: 3 | H26: 4 | I26: 3 | J26: 5 | K26: 15 | L26: 1.34 | M26: 39 | N26: 44.76 | O26: AC1 | P26: AC1 | Q26: 1 | R26: 1 | S26: 1 | W26: Socratic quality 3/5 (Clarification): Generic question: asks for clarification without attacking the root error. Conceptual precision 4/5 (Good): Good: clearly identifies the alternative conception with precise technical language. Good overall performance; room for improvement in socratic depth.
A27: 110 | B27: 37 | C27: 2 | D27: 1 | E27: R1, R2 y R4 dado que R5 cortocircuitada | F27: Si R5 está en cortocircuito, ¿cómo afecta esto a la diferencia de potencial a través de ella y, por lo tanto, a la corriente que fluye a través del circuito en paralelo con R4? | G27: 4 | H27: 4 | I27: 4 | J27: 5 | K27: 17 | L27: 1.308 | M27: 45 | N27: 45.86 | O27: AC6 | P27: AC1, AC6 | Q27: 0.5 | R27: 1 | S27: 0.667 | W27: Socratic quality 4/5 (Scaffolding for detection): Scaffolding for detection: identifies the error area and asks a question that confronts the theory. Conceptual precision 4/5 (Good): Good: clearly identifies the alternative conception with precise technical language. High-performing tutor: expert socratic guidance with precise diagnosis.
A28: 111 | B28: 37 | C28: 3 | D28: 1 | E28: R1, R2 y R4 dado que por R3 no circula corriente | F28: Si no circula corriente a través de R3 debido a que está abierto, ¿cómo describirías el rol de R3 en el circuito y cómo afecta esto a la trayectoria principal de la corriente entre la fuente de voltaje y los demás resistores? | G28: 3 | H28: 3 | I28: 3 | J28: 5 | K28: 14 | L28: 1.425 | M28: 50 | N28: 42.1 | O28: AC1 | P28: AC1, AC9 | Q28: 0.5 | R28: 1 | S28: 0.667 | W28: Socratic quality 3/5 (Clarification): Generic question: asks for clarification without attacking the root error. Conceptual precision 3/5 (Sufficient): Sufficient: identifies that there is an error and uses correct concepts, but the diagnosis is somewhat vague. Good overall performance; room for improvement in socratic depth.
A29: 112 | B29: 38 | C29: 1 | D29: 1 | E29: R1, R2 y R4 dado que por R5 no circula corriente | F29: Observando el netlist, ¿qué relación de voltaje comparten los nodos conectados en los terminales de R5? | G29: 3 | H29: 3 | I29: 3 | J29: 5 | K29: 14 | L29: 1.149 | M29: 24 | N29: 52.24 | O29: AC6 | P29: AC6 | Q29: 1 | R29: 1 | S29: 1 | W29: Socratic quality 3/5 (Clarification): Generic question: asks for clarification without attacking the root error. Conceptual precision 3/5 (Sufficient): Sufficient: identifies that there is an error and uses correct concepts, but the diagnosis is somewhat vague. Good overall performance; room for improvement in socratic depth.
A30: 113 | B30: 38 | C30: 2 | D30: 1 | E30: R1, R2 y R4 dado que R3 se puede quitar | F30: Si R3 se pudiera remover sin afectar el circuito, ¿cómo describirías la configuración resultante de R1, R2 y R4 en términos de conexiones en serie o en paralelo? | G30: 3 | H30: 3 | I30: 5 | J30: 5 | K30: 16 | L30: 1.231 | M30: 38 | N30: 48.75 | O30: AC1 | Q30: 1 | R30: 0 | S30: 0 | W30: Socratic quality 3/5 (Clarification): Generic question: asks for clarification without attacking the root error. Conceptual precision 3/5 (Sufficient): Sufficient: identifies that there is an error and uses correct concepts, but the diagnosis is somewhat vague. Good overall performance; room for improvement in socratic depth.
A31: 114 | B31: 38 | C31: 3 | D31: 1 | E31: R1, R2 y R4 dado que R5 se puede quitar | F31: Considerando que la remoción de R5 no altera la corriente en R1, R2 y R4, ¿qué implicación tiene esto sobre la trayectoria de la corriente en el circuito original? | G31: 3 | H31: 2 | I31: 5 | J31: 5 | K31: 15 | L31: 1.233 | M31: 41 | N31: 48.66 | O31: AC6 | P31: AC1 | Q31: 0 | R31: 0 | S31: 0 | W31: Socratic quality 3/5 (Clarification): Generic question: asks for clarification without attacking the root error. Conceptual precision 2/5 (Poor): Poor: responds generically without diagnosing the conceptual error. Good overall performance; room for improvement in socratic depth.
A32: 115 | B32: 39 | C32: 1 | D32: 1 | E32: R1, R2 y R4 dado que R3 no influye para nada en la diferencia de potencial que se pide | F32: Considerando el netlist, ¿qué condición eléctrica presentan los terminales de la resistencia R5 y cómo afecta esto a la corriente que podría circular a través de ella? | G32: 3 | H32: 3 | I32: 3 | J32: 5 | K32: 14 | L32: 1.347 | M32: 35 | N32: 44.53 | O32: AC1 | P32: AC1, AC6 | Q32: 0.5 | R32: 1 | S32: 0.667 | W32: Socratic quality 3/5 (Clarification): Generic question: asks for clarification without attacking the root error. Conceptual precision 3/5 (Sufficient): Sufficient: identifies that there is an error and uses correct concepts, but the diagnosis is somewhat vague. Good overall performance; room for improvement in socratic depth.
A33: 116 | B33: 39 | C33: 2 | D33: 1 | E33: R1, R2 y R4 dado que R5 no influye para nada en la diferencia de potencial que se pide | F33: Si R5 no influye en la diferencia de potencial medida, ¿cómo describirías su conexión en relación con el resto del circuito y qué implicaciones tiene esto para el flujo de corriente a través de ella? | G33: 3 | H33: 3 | I33: 3 | J33: 5 | K33: 14 | L33: 1.268 | M33: 43 | N33: 47.31 | O33: AC6 | P33: AC1 | Q33: 0 | R33: 0 | S33: 0 | W33: Socratic quality 3/5 (Clarification): Generic question: asks for clarification without attacking the root error. Conceptual precision 3/5 (Sufficient): Sufficient: identifies that there is an error and uses correct concepts, but the diagnosis is somewhat vague. Good overall performance; room for improvement in socratic depth.
A34: 117 | B34: 39 | C34: 3 | D34: 1 | E34: No lo sé | F34: Considerando que la diferencia de potencial se mide a través de R4, ¿podrías describir cómo están conectados en serie o en paralelo R1, R2 y R4, y cómo esto podría afectar la corriente total del circuito? | G34: 3 | H34: 3 | I34: 2 | J34: 5 | K34: 13 | L34: 1.375 | M34: 49 | N34: 43.63 | O34: AC9 | P34: AC1 | Q34: 0 | R34: 0 | S34: 0 | W34: Socratic quality 3/5 (Clarification): Generic question: asks for clarification without attacking the root error. Conceptual precision 3/5 (Sufficient): Sufficient: identifies that there is an error and uses correct concepts, but the diagnosis is somewhat vague. Good overall performance; room for improvement in socratic depth.
A35: 118 | B35: 40 | C35: 1 | D35: 1 | E35: Todas las resistencias | F35: Si el interruptor entre N2 y N3 está abierto, ¿qué implicaciones tiene esto para el flujo de corriente en la rama que contiene a R3? | G35: 3 | H35: 3 | I35: 2 | J35: 5 | K35: 13 | L35: 1.297 | M35: 34 | N35: 46.27 | O35: AC9 | P35: AC1 | Q35: 0 | R35: 0 | S35: 0 | W35: Socratic quality 3/5 (Clarification): Generic question: asks for clarification without attacking the root error. Conceptual precision 3/5 (Sufficient): Sufficient: identifies that there is an error and uses correct concepts, but the diagnosis is somewhat vague. Good overall performance; room for improvement in socratic depth.
A36: 119 | B36: 40 | C36: 2 | D36: 1 | E36: R1 y R2 | F36: Considerando que la corriente total que sale del nodo 1 debe ser igual a la corriente que entra, ¿cómo se relacionan las corrientes que fluyen a través de R1 y R2 con la corriente total suministrada por la fuente de voltaje? | G36: 3 | H36: 3 | I36: 2 | J36: 5 | K36: 13 | L36: 1.447 | M36: 52 | N36: 41.48 | O36: AC9 | P36: AC1 | Q36: 0 | R36: 0 | S36: 0 | W36: Socratic quality 3/5 (Clarification): Generic question: asks for clarification without attacking the root error. Conceptual precision 3/5 (Sufficient): Sufficient: identifies that there is an error and uses correct concepts, but the diagnosis is somewhat vague. Good overall performance; room for improvement in socratic depth.
A37: 120 | B37: 40 | C37: 3 | D37: 1 | E37: R1, R2 y R4 | F37: Si consideras la caída de voltaje a través de cada resistencia en el circuito, ¿cómo afectaría una resistencia infinita (circuito abierto) en R4 a la distribución del voltaje en las demás resistencias? | G37: 3 | H37: 4 | I37: 2 | J37: 5 | K37: 14 | L37: 1.28 | M37: 43 | N37: 46.87 | P37: AC1, AC9 | Q37: 0 | R37: 1 | S37: 0 | W37: Socratic quality 3/5 (Clarification): Generic question: asks for clarification without attacking the root error. Conceptual precision 4/5 (Good): Good: clearly identifies the alternative conception with precise technical language. Good overall performance; room for improvement in socratic depth.
A38: 121 | B38: 41 | C38: 1 | D38: 1 | E38: R1, R2, R4 y R5 | F38: Observando el netlist, ¿qué puedes decir sobre la conexión entre los terminales de la resistencia R5 y cómo afecta esto al flujo de corriente a través de ella? | G38: 3 | H38: 3 | I38: 3 | J38: 5 | K38: 14 | L38: 1.303 | M38: 36 | N38: 46.05 | O38: AC6 | P38: AC1, AC6 | Q38: 0.5 | R38: 1 | S38: 0.667 | W38: Socratic quality 3/5 (Clarification): Generic question: asks for clarification without attacking the root error. Conceptual precision 3/5 (Sufficient): Sufficient: identifies that there is an error and uses correct concepts, but the diagnosis is somewhat vague. Good overall performance; room for improvement in socratic depth.
A39: 122 | B39: 41 | C39: 2 | D39: 1 | E39: R1, R2, R3 y R4 | F39: Si revisas cuidadosamente el esquema original, ¿podrías identificar si omitiste algún componente en tu lista y cómo su ausencia podría afectar el análisis del circuito? | G39: 5 | H39: 2 | I39: 2 | J39: 5 | K39: 14 | L39: 1.17 | M39: 33 | N39: 51.29 | O39: AC1 | Q39: 1 | R39: 0 | S39: 0 | W39: Socratic quality 5/5 (Induction to contradiction): Induction to contradiction: uses counterexample or reduction to absurdity. Conceptual precision 2/5 (Poor): Generic response: no technical vocabulary or error diagnosis. Good overall performance; room for improvement in socratic depth.
A40: 123 | B40: 41 | C40: 3 | D40: 1 | E40: R1 y R2 y R4 hacen un divisor de corriente | F40: Considerando que un divisor de corriente implica una corriente total que se divide en caminos paralelos, ¿cómo se relaciona la resistencia R4 con estos caminos y su efecto en la distribución de la corriente? | G40: 3 | H40: 4 | I40: 3 | J40: 5 | K40: 15 | L40: 1.255 | M40: 41 | N40: 47.81 | P40: AC1, AC9 | Q40: 0 | R40: 1 | S40: 0 | W40: Socratic quality 3/5 (Clarification): Generic question: asks for clarification without attacking the root error. Conceptual precision 4/5 (Good): Good: clearly identifies the alternative conception with precise technical language. Good overall performance; room for improvement in socratic depth.
...

Sheet Results_gemma3_4b
A1: ID | B1: Conversation | C1: Turn | D1: Exercise | E1: Student Answer | F1: Tutor Socratic Response | G1: Socratic Quality | H1: Conceptual Precision | I1: Consistency | J1: Hallucination Rate | K1: Total Score | L1: Latency (s) | M1: Tokens | N1: Throughput (resp/min) | O1: Expected ACs | P1: Detected ACs | Q1: AC Precision | R1: AC Recall | S1: AC F1 | T1: Faithfulness | U1: Relevance | V1: Think Content | W1: Constructive Feedback
A2: 43 | B2: 15 | C2: 1 | D2: 1 | E2: R1 y R2 dado que las dos resistencia forman un divisor de tensión | F2: Considerando que el interruptor está abierto entre N2 y N3, ¿podría la diferencia de potencial entre N2 y 0 estar influenciada por componentes además de R1 y R2, y cómo afectaría la eliminación de R2 al resultado? | G2: 3 | H2: 3 | I2: 5 | J2: 5 | K2: 16 | L2: 2.026 | M2: 55 | N2: 29.61 | O2: AC9 | P2: AC1 | Q2: 0 | R2: 0 | S2: 0 | W2: Socratic quality 3/5 (Clarification): Generic question: asks for clarification without attacking the root error. Conceptual precision 3/5 (Sufficient): Sufficient: identifies that there is an error and uses correct concepts, but the diagnosis is somewhat vague. Good overall performance; room for improvement in socratic depth.
A3: 44 | B3: 15 | C3: 2 | D3: 1 | E3: R1 y R2 dado que se pide la tensión en R2 | F3: Si la corriente que fluye a través de R2 está determinada únicamente por la fuente y R1, ¿cómo cambiaría el valor de R2 y su efecto en la tensión medida, considerando un cortocircuito en lugar de un divisor? | G3: 3 | H3: 3 | I3: 5 | J3: 5 | K3: 16 | L3: 0.915 | M3: 50 | N3: 65.55 | O3: AC9 | P3: AC1, AC6 | Q3: 0 | R3: 0 | S3: 0 | W3: Socratic quality 3/5 (Clarification): Generic question: asks for clarification without attacking the root error. Conceptual precision 3/5 (Sufficient): Sufficient: identifies that there is an error and uses correct concepts, but the diagnosis is somewhat vague. Good overall performance; room for improvement in socratic depth.
A4: 45 | B4: 15 | C4: 3 | D4: 1 | E4: R1 y R2 por identificar un divisor de tensión | F4: Si la tensión en el nodo entre R1 y R2 es la que realmente determina la tensión en R2, ¿cómo se relaciona la ley de Ohm con la distribución de la corriente a través de estas resistencias? | G4: 3 | H4: 3 | I4: 4 | J4: 5 | K4: 15 | L4: 0.851 | M4: 44 | N4: 70.49 | O4: AC9 | P4: AC1, AC9 | Q4: 0.5 | R4: 1 | S4: 0.667 | W4: Socratic quality 3/5 (Clarification): Generic question: asks for clarification without attacking the root error. Conceptual precision 3/5 (Sufficient): Sufficient: identifies that there is an error and uses correct concepts, but the diagnosis is somewhat vague. Good overall performance; room for improvement in socratic depth.
A5: 46 | B5: 16 | C5: 1 | D5: 1 | E5: R1 y R2 hacen un divisor de tensión | F5: Considerando que el interruptor está abierto, ¿cómo afecta la presencia de R4 al flujo de corriente desde V1 hacia N2, y qué papel juega en ese flujo? | G5: 4 | H5: 3 | I5: 3 | J5: 5 | K5: 15 | L5: 0.763 | M5: 37 | N5: 78.66 | O5: AC9 | P5: AC1 | Q5: 0 | R5: 0 | S5: 0 | W5: Socratic quality 4/5 (Scaffolding for detection): Scaffolding for detection: identifies the error area and asks a question that confronts the theory. Conceptual precision 3/5 (Sufficient): Sufficient: identifies that there is an error and uses correct concepts, but the diagnosis is somewhat vague. Good overall performance; room for improvement in socratic depth.
A6: 47 | B6: 16 | C6: 2 | D6: 1 | E6: R1, R2, R3 y R4 porque R5 está cortocircuitada | F6: Si la corriente fluye a través de R1 y R2, ¿cómo se relaciona la resistencia de cada componente con la tensión total que observas en el nodo entre ellos? | G6: 3 | H6: 3 | I6: 3 | J6: 5 | K6: 14 | L6: 0.993 | M6: 37 | N6: 60.42 | O6: AC1, AC6 | P6: AC1 | Q6: 1 | R6: 0.5 | S6: 0.667 | W6: Socratic quality 3/5 (Clarification): Generic question: asks for clarification without attacking the root error. Conceptual precision 3/5 (Sufficient): Sufficient: identifies that there is an error and uses correct concepts, but the diagnosis is somewhat vague. Good overall performance; room for improvement in socratic depth.
A7: 48 | B7: 16 | C7: 3 | D7: 1 | E7: R1, R2, R3 y R4 porque por R5 no circula corriente | F7: Si R5 está cortocircuitada, ¿cómo crees que esto modifica la distribución de la carga entre R1 y R2, y qué implicaciones tiene para la tensión medida en el nodo entre ellos? | G7: 3 | H7: 3 | I7: 4 | J7: 5 | K7: 15 | L7: 1.02 | M7: 44 | N7: 58.83 | O7: AC1, AC6 | Q7: 1 | R7: 0 | S7: 0 | W7: Socratic quality 3/5 (Clarification): Generic question: asks for clarification without attacking the root error. Conceptual precision 3/5 (Sufficient): Sufficient: identifies that there is an error and uses correct concepts, but the diagnosis is somewhat vague. Good overall performance; room for improvement in socratic depth.
A8: 49 | B8: 17 | C8: 1 | D8: 1 | E8: R1, R2, R3 y R4 porque R5 se quita | F8: Considerando que el interruptor entre N2 y N3 está abierto, ¿podría la eliminación de R3 afectar la trayectoria que permite el flujo de corriente desde la fuente hacia N2, y si es así, ¿cómo influye esto en la caída de potencial en esa rama del circuito? | G8: 4 | H8: 3 | I8: 3 | J8: 5 | K8: 15 | L8: 0.913 | M8: 61 | N8: 65.73 | O8: AC1, AC6 | P8: AC1, AC9 | Q8: 0.5 | R8: 0.5 | S8: 0.5 | W8: Socratic quality 4/5 (Scaffolding for detection): Scaffolding for detection: identifies the error area and asks a question that confronts the theory. Conceptual precision 3/5 (Sufficient): Sufficient: identifies that there is an error and uses correct concepts, but the diagnosis is somewhat vague. Good overall performance; room for improvement in socratic depth.
A9: 50 | B9: 17 | C9: 2 | D9: 1 | E9: R1, R3 y R4 porque R2 está en paralelo con la fuente y R5 corctocircuitada | F9: Si eliminamos R3, ¿qué efecto tendría esto en la relación entre la corriente que fluye a través de R1 y R4, y cómo podría esto afectar la tensión total medida en esos componentes? | G9: 3 | H9: 3 | I9: 4 | J9: 5 | K9: 15 | L9: 0.796 | M9: 43 | N9: 75.37 | O9: AC1, AC6 | P9: AC1 | Q9: 1 | R9: 0.5 | S9: 0.667 | W9: Socratic quality 3/5 (Clarification): Generic question: asks for clarification without attacking the root error. Conceptual precision 3/5 (Sufficient): Sufficient: identifies that there is an error and uses correct concepts, but the diagnosis is somewhat vague. Good overall performance; room for improvement in socratic depth.
A10: 51 | B10: 17 | C10: 3 | D10: 1 | E10: R1, R4 y R5 porque R2 se elimina y R3 también | F10: Considerando que R2 ahora está efectivamente en circuito abierto, ¿cómo crees que esto alteraría la distribución de la corriente a través de los componentes conectados directamente a la fuente? | G10: 3 | H10: 3 | I10: 3 | J10: 5 | K10: 14 | L10: 0.748 | M10: 37 | N10: 80.17 | O10: AC1, AC6 | P10: AC1 | Q10: 1 | R10: 0.5 | S10: 0.667 | W10: Socratic quality 3/5 (Clarification): Generic question: asks for clarification without attacking the root error. Conceptual precision 3/5 (Sufficient): Sufficient: identifies that there is an error and uses correct concepts, but the diagnosis is somewhat vague. Good overall performance; room for improvement in socratic depth.
A11: 52 | B11: 18 | C11: 1 | D11: 1 | E11: R1 y R4 dado que R2 está en paralelo con la fuente, R3 en circuito abierto y R5 cortocircuitada | F11: Considerando que R5 está efectivamente cortocircuitada, ¿podría haber una conexión directa entre los nodos N2 y el nodo de referencia (0) que no involucra a R5? | G11: 3 | H11: 2 | I11: 3 | J11: 5 | K11: 13 | L11: 0.811 | M11: 41 | N11: 74.01 | O11: AC1, AC6 | Q11: 1 | R11: 0 | S11: 0 | W11: Socratic quality 3/5 (Clarification): Generic question: asks for clarification without attacking the root error. Conceptual precision 2/5 (Poor): Poor: responds generically without diagnosing the conceptual error. Good overall performance; room for improvement in socratic depth.
A12: 53 | B12: 18 | C12: 2 | D12: 1 | E12: R1, R2 y R3 dado que R2 y R3 están en paralelo y forman un divisor de tensión con R1 | F12: Si R3 está en circuito abierto, ¿cómo afectaría esto a la capacidad de R2 y R3 para influir en el flujo de corriente a través de R1? | G12: 3 | H12: 3 | I12: 5 | J12: 5 | K12: 16 | L12: 0.714 | M12: 37 | N12: 84.09 | O12: AC1, AC9 | P12: AC1 | Q12: 1 | R12: 0.5 | S12: 0.667 | W12: Socratic quality 3/5 (Clarification): Generic question: asks for clarification without attacking the root error. Conceptual precision 3/5 (Sufficient): Sufficient: identifies that there is an error and uses correct concepts, but the diagnosis is somewhat vague. Good overall performance; room for improvement in socratic depth.
A13: 54 | B13: 18 | C13: 3 | D13: 1 | E13: R1, R2, R4 y R5 dado que R3 está en circuito abierto | F13: Dado que R3 está en circuito abierto, ¿cómo crees que esto modifica la relación entre la tensión aplicada y la corriente que fluye a través de R4? | G13: 3 | H13: 4 | I13: 3 | J13: 5 | K13: 15 | L13: 0.71 | M13: 35 | N13: 84.51 | O13: AC1, AC6 | P13: AC1, AC9 | Q13: 0.5 | R13: 0.5 | S13: 0.5 | W13: Socratic quality 3/5 (Clarification): Generic question: asks for clarification without attacking the root error. Conceptual precision 4/5 (Good): Good: clearly identifies the alternative conception with precise technical language. Good overall performance; room for improvement in socratic depth.
A14: 55 | B14: 19 | C14: 1 | D14: 1 | E14: R1, R2, R4 y R5 dado que R3 sobra | F14: Considerando que el interruptor entre N2 y N3 está abierto, ¿podrías explicar cómo la corriente, si existiera, fluiría a través de R5 y qué efecto tendría eso en el potencial en N2 en comparación con el nodo 0? | G14: 5 | H14: 4 | I14: 3 | J14: 5 | K14: 17 | L14: 0.888 | M14: 56 | N14: 67.53 | O14: AC1, AC6 | P14: AC1 | Q14: 1 | R14: 0.5 | S14: 0.667 | W14: Socratic quality 5/5 (Induction to contradiction): Induction to contradiction: uses counterexample or reduction to absurdity. Conceptual precision 4/5 (Good): Good: clearly identifies the alternative conception with precise technical language. High-performing tutor: expert socratic guidance with precise diagnosis.
A15: 56 | B15: 19 | C15: 2 | D15: 1 | E15: R1, R2, R4 y R5 dado que R3 no hace nada | F15: Si el interruptor entre N2 y N3 permanece abierto, ¿cómo crees que la resistencia total del circuito afectaría la distribución de la corriente entre R1 y R2? | G15: 3 | H15: 4 | I15: 3 | J15: 5 | K15: 15 | L15: 0.777 | M15: 38 | N15: 77.22 | O15: AC1, AC6 | P15: AC1, AC9 | Q15: 0.5 | R15: 0.5 | S15: 0.5 | W15: Socratic quality 3/5 (Clarification): Generic question: asks for clarification without attacking the root error. Conceptual precision 4/5 (Good): Good: clearly identifies the alternative conception with precise technical language. Good overall performance; room for improvement in socratic depth.
A16: 57 | B16: 19 | C16: 3 | D16: 1 | E16: R1, R2 y R4 dado que son las resistencias que forman parte del circuito. | F16: Considerando que el interruptor entre N2 y N3 aún está abierto, ¿podrías describir cómo la presencia de R4 influiría en el flujo de corriente hacia el nodo N2? | G16: 3 | H16: 5 | I16: 3 | J16: 5 | K16: 16 | L16: 0.735 | M16: 42 | N16: 81.66 | P16: AC1 | Q16: 0 | R16: 1 | S16: 0 | W16: Socratic quality 3/5 (Clarification): Generic question: asks for clarification without attacking the root error. Conceptual precision 5/5 (Excellent): Excellent: identifies the specific alternative conception and connects it with the circuit topology. Good overall performance; room for improvement in socratic depth.
A17: 58 | B17: 20 | C17: 1 | D17: 1 | E17: R1, R2 y R4 dado que R2 y R4 están en paralelo y forma un divisor de tensión con R1. | F17: Considerando que el interruptor entre N2 y N3 está abierto, ¿cómo afecta la presencia de R5, que está directamente cortocircuitada a N3, al camino que permite la caída de potencial entre N2 y tierra? | G17: 4 | H17: 5 | I17: 3 | J17: 5 | K17: 17 | L17: 0.845 | M17: 50 | N17: 71.04 | P17: AC1, AC9 | Q17: 0 | R17: 1 | S17: 0 | W17: Socratic quality 4/5 (Scaffolding for detection): Scaffolding for detection: identifies the error area and asks a question that confronts the theory. Conceptual precision 5/5 (Excellent): Excellent: identifies the specific alternative conception and connects it with the circuit topology. High-performing tutor: expert socratic guidance with precise diagnosis.
A18: 59 | B18: 20 | C18: 2 | D18: 1 | E18: R1, R2 y R4 dado que R3 está en abierto y R5 cortocircuitada | F18: Si el objetivo es medir la corriente que fluye a través de R1, ¿qué consideraciones serían cruciales al tener en cuenta la conexión directa de R5 a tierra a través del interruptor? | G18: 3 | H18: 3 | I18: 3 | J18: 5 | K18: 14 | L18: 0.845 | M18: 42 | N18: 71.03 | O18: AC1, AC6 | P18: AC1, AC9 | Q18: 0.5 | R18: 0.5 | S18: 0.5 | W18: Socratic quality 3/5 (Clarification): Generic question: asks for clarification without attacking the root error. Conceptual precision 3/5 (Sufficient): Sufficient: identifies that there is an error and uses correct concepts, but the diagnosis is somewhat vague. Good overall performance; room for improvement in socratic depth.
A19: 60 | B19: 20 | C19: 3 | D19: 1 | E19: R1, R2 y R4 dado que solo por estas resistencias circula una corriente diferente de cero | F19: Considerando que R5 está cortocircuitada, ¿cómo influye esta conexión en la distribución de la corriente a través de R1, R2 y R4 en comparación con un circuito abierto de R5? | G19: 4 | H19: 3 | I19: 5 | J19: 5 | K19: 17 | L19: 0.777 | M19: 45 | N19: 77.24 | P19: AC1 | Q19: 0 | R19: 1 | S19: 0 | W19: Socratic quality 4/5 (Scaffolding for detection): Scaffolding for detection: identifies the error area and asks a question that confronts the theory. Conceptual precision 3/5 (Sufficient): Sufficient: identifies that there is an error and uses correct concepts, but the diagnosis is somewhat vague. High-performing tutor: expert socratic guidance with precise diagnosis.
A20: 61 | B20: 21 | C20: 1 | D20: 1 | E20: R1, R2 y R4 dado que por R3 y por R5 no circula corriente | F20: Considerando que el interruptor entre N2 y N3 está abierto, ¿qué efecto tiene la ausencia de un camino directo entre esos nodos en la distribución del potencial eléctrico a través de las resistencias conectadas? | G20: 3 | H20: 4 | I20: 3 | J20: 5 | K20: 15 | L20: 0.795 | M20: 43 | N20: 75.45 | O20: AC1, AC6 | P20: AC1, AC9 | Q20: 0.5 | R20: 0.5 | S20: 0.5 | W20: Socratic quality 3/5 (Clarification): Generic question: asks for clarification without attacking the root error. Conceptual precision 4/5 (Good): Good: clearly identifies the alternative conception with precise technical language. Good overall performance; room for improvement in socratic depth.
A21: 62 | B21: 21 | C21: 2 | D21: 1 | E21: R1, R2 y R4 dado que R3 y R5 se pueden quitar | F21: Si la corriente no puede fluir a través de R3 y R5, ¿cómo afectaría esto a la relación entre el voltaje aplicado, la resistencia y la corriente en el resto del circuito? | G21: 3 | H21: 3 | I21: 3 | J21: 5 | K21: 14 | L21: 0.747 | M21: 41 | N21: 80.28 | O21: AC1, AC6 | P21: AC1, AC9 | Q21: 0.5 | R21: 0.5 | S21: 0.5 | W21: Socratic quality 3/5 (Clarification): Generic question: asks for clarification without attacking the root error. Conceptual precision 3/5 (Sufficient): Sufficient: identifies that there is an error and uses correct concepts, but the diagnosis is somewhat vague. Good overall performance; room for improvement in socratic depth.
A22: 63 | B22: 21 | C22: 3 | D22: 1 | E22: R1, R2 y R4 dado que R3 y R5 no influyen para nada en la diferencia de potencial que se pide | F22: Considerando que R3 y R5 no están en el circuito, ¿cómo cambiaría tu comprensión de cómo el potencial eléctrico se establece a través de las resistencias R1, R2 y R4? | G22: 3 | H22: 2 | I22: 5 | J22: 5 | K22: 15 | L22: 0.772 | M22: 42 | N22: 77.73 | O22: AC1, AC6 | P22: AC9 | Q22: 0 | R22: 0 | S22: 0 | W22: Socratic quality 3/5 (Clarification): Generic question: asks for clarification without attacking the root error. Conceptual precision 2/5 (Poor): Poor: responds generically without diagnosing the conceptual error. Good overall performance; room for improvement in socratic depth.
A23: 64 | B23: 22 | C23: 1 | D23: 1 | E23: R1, R2 y R4 dado que R3 y R5 sobran | F23: Considerando que R3 y R5 están efectivamente desconectados del circuito, ¿podrías explicar qué factores, además de las resistencias que permanecen en el camino entre el nodo N2 y el nodo de referencia 0, determinan la magnitud del potencial en N2? | G23: 3 | H23: 3 | I23: 3 | J23: 5 | K23: 14 | L23: 0.86 | M23: 58 | N23: 69.8 | O23: AC1, AC6 | P23: AC1, AC9 | Q23: 0.5 | R23: 0.5 | S23: 0.5 | W23: Socratic quality 3/5 (Clarification): Clarification: asks the student to explain their reasoning. Conceptual precision 3/5 (Sufficient): Sufficient: identifies that there is an error and uses correct concepts, but the diagnosis is somewhat vague. Good overall performance; room for improvement in socratic depth.
A24: 65 | B24: 22 | C24: 2 | D24: 1 | E24: R1, R2 y R4 dado que R3 sobra | F24: Si ignoramos R3, ¿qué papel juega la relación entre la corriente que fluye a través de R1 y el voltaje a través de R2 en la determinación del potencial en N2? | G24: 3 | H24: 3 | I24: 4 | J24: 5 | K24: 15 | L24: 0.767 | M24: 41 | N24: 78.23 | O24: AC1 | P24: AC1 | Q24: 1 | R24: 1 | S24: 1 | W24: Socratic quality 3/5 (Clarification): Generic question: asks for clarification without attacking the root error. Conceptual precision 3/5 (Sufficient): Sufficient: identifies that there is an error and uses correct concepts, but the diagnosis is somewhat vague. Good overall performance; room for improvement in socratic depth.
A25: 66 | B25: 22 | C25: 3 | D25: 1 | E25: R1, R2 y R4 dado que R5 sobra | F25: Considerando que R5 está desconectado del circuito, ¿cómo crees que la distribución de la carga eléctrica se vería afectada en comparación con un circuito con una ruta completa? | G25: 3 | H25: 2 | I25: 3 | J25: 5 | K25: 13 | L25: 0.746 | M25: 38 | N25: 80.4 | O25: AC6 | Q25: 1 | R25: 0 | S25: 0 | W25: Socratic quality 3/5 (Clarification): Generic question: asks for clarification without attacking the root error. Conceptual precision 2/5 (Poor): Generic response: no technical vocabulary or error diagnosis. Good overall performance; room for improvement in socratic depth.
A26: 67 | B26: 23 | C26: 1 | D26: 1 | E26: R1, R2 y R4 dado que R3 está en abierto | F26: Considerando que R3 está físicamente en abierto, ¿cómo afecta esta condición a la capacidad de la corriente para fluir desde el nodo N2 hacia tierra, y qué papel juegan las resistencias R1, R2 y R4 en ese flujo particular? | G26: 4 | H26: 3 | I26: 4 | J26: 5 | K26: 16 | L26: 0.92 | M26: 53 | N26: 65.22 | O26: AC1 | P26: AC1, AC9 | Q26: 0.5 | R26: 1 | S26: 0.667 | W26: Socratic quality 4/5 (Scaffolding for detection): Scaffolding for detection: identifies the error area and asks a question that confronts the theory. Conceptual precision 3/5 (Sufficient): Sufficient: identifies that there is an error and uses correct concepts, but the diagnosis is somewhat vague. Good overall performance; room for improvement in socratic depth.
A27: 68 | B27: 23 | C27: 2 | D27: 1 | E27: R1, R2 y R4 dado que R5 cortocircuitada | F27: Si R5 estuviera cortocircuitado, ¿cómo cambiaría la relación entre el voltaje aplicado y la corriente que fluye a través de la red, y qué implicaciones tendría esto para la resistencia equivalente de ese circuito? | G27: 3 | H27: 3 | I27: 3 | J27: 5 | K27: 14 | L27: 0.802 | M27: 47 | N27: 74.84 | O27: AC6 | P27: AC1, AC9 | Q27: 0 | R27: 0 | S27: 0 | W27: Socratic quality 3/5 (Clarification): Generic question: asks for clarification without attacking the root error. Conceptual precision 3/5 (Sufficient): Sufficient: identifies that there is an error and uses correct concepts, but the diagnosis is somewhat vague. Good overall performance; room for improvement in socratic depth.
A28: 69 | B28: 23 | C28: 3 | D28: 1 | E28: R1, R2 y R4 dado que por R3 no circula corriente | F28: Si R3 está en abierto, ¿cómo influye la ausencia de este componente en la distribución de la corriente a través de R1, R2 y R4, y qué consideraciones debemos tener sobre el concepto de resistencia en este escenario particular? | G28: 4 | H28: 3 | I28: 4 | J28: 5 | K28: 16 | L28: 0.887 | M28: 51 | N28: 67.66 | O28: AC1 | P28: AC1 | Q28: 1 | R28: 1 | S28: 1 | W28: Socratic quality 4/5 (Scaffolding for detection): Scaffolding for detection: identifies the error area and asks a question that confronts the theory. Conceptual precision 3/5 (Sufficient): Sufficient: identifies that there is an error and uses correct concepts, but the diagnosis is somewhat vague. Good overall performance; room for improvement in socratic depth.
A29: 70 | B29: 24 | C29: 1 | D29: 1 | E29: R1, R2 y R4 dado que por R5 no circula corriente | F29: Considerando que el interruptor entre N2 y N3 está abierto, ¿podrías describir cómo la ausencia de flujo de corriente a través de R5 afecta tu comprensión del camino que la corriente debe tomar para establecer la diferencia de potencial entre N2 y 0? | G29: 3 | H29: 3 | I29: 3 | J29: 5 | K29: 14 | L29: 0.887 | M29: 56 | N29: 67.65 | O29: AC6 | P29: AC1, AC9 | Q29: 0 | R29: 0 | S29: 0 | W29: Socratic quality 3/5 (Clarification): Generic question: asks for clarification without attacking the root error. Conceptual precision 3/5 (Sufficient): Sufficient: identifies that there is an error and uses correct concepts, but the diagnosis is somewhat vague. Good overall performance; room for improvement in socratic depth.
A30: 71 | B30: 24 | C30: 2 | D30: 1 | E30: R1, R2 y R4 dado que R3 se puede quitar | F30: Si la corriente fluye desde la fuente a través de R1 y R2, ¿cómo crees que la presencia o ausencia de una resistencia específica, como R3, impactaría en el cálculo del voltaje a través de R2? | G30: 3 | H30: 3 | I30: 4 | J30: 5 | K30: 15 | L30: 0.786 | M30: 49 | N30: 76.3 | O30: AC1 | P30: AC1 | Q30: 1 | R30: 1 | S30: 1 | W30: Socratic quality 3/5 (Clarification): Generic question: asks for clarification without attacking the root error. Conceptual precision 3/5 (Sufficient): Sufficient: identifies that there is an error and uses correct concepts, but the diagnosis is somewhat vague. Good overall performance; room for improvement in socratic depth.
A31: 72 | B31: 24 | C31: 3 | D31: 1 | E31: R1, R2 y R4 dado que R5 se puede quitar | F31: Si se elimina R5, ¿cómo cambiaría tu enfoque para determinar la relación entre la corriente y el voltaje en el resto del circuito, considerando que aún necesitas encontrar la caída de tensión a través de R2? | G31: 3 | H31: 3 | I31: 4 | J31: 5 | K31: 15 | L31: 0.784 | M31: 44 | N31: 76.53 | O31: AC6 | P31: AC1, AC9 | Q31: 0 | R31: 0 | S31: 0 | W31: Socratic quality 3/5 (Clarification): Generic question: asks for clarification without attacking the root error. Conceptual precision 3/5 (Sufficient): Sufficient: identifies that there is an error and uses correct concepts, but the diagnosis is somewhat vague. Good overall performance; room for improvement in socratic depth.
A32: 73 | B32: 25 | C32: 1 | D32: 1 | E32: R1, R2 y R4 dado que R3 no influye para nada en la diferencia de potencial que se pide | F32: Considerando que el interruptor está abierto, ¿cómo afecta la interrupción del flujo de corriente a través de R3, y qué papel juega esta interrupción en la determinación del potencial en el nodo N2 en relación con la tierra? | G32: 4 | H32: 5 | I32: 3 | J32: 5 | K32: 17 | L32: 0.902 | M32: 49 | N32: 66.54 | O32: AC1 | P32: AC1, AC9 | Q32: 0.5 | R32: 1 | S32: 0.667 | W32: Socratic quality 4/5 (Scaffolding for detection): Scaffolding for detection: identifies the error area and asks a question that confronts the theory. Conceptual precision 5/5 (Excellent): Excellent: identifies the specific alternative conception and connects it with the circuit topology. High-performing tutor: expert socratic guidance with precise diagnosis.
A33: 74 | B33: 25 | C33: 2 | D33: 1 | E33: R1, R2 y R4 dado que R5 no influye para nada en la diferencia de potencial que se pide | F33: Si el potencial en el nodo N2 está determinado únicamente por R1, R2 y R4, ¿cómo se relaciona la carga que fluye a través de R2 con el voltaje aplicado a R1 en este circuito específico? | G33: 3 | H33: 3 | I33: 4 | J33: 5 | K33: 15 | L33: 0.818 | M33: 48 | N33: 73.32 | O33: AC6 | Q33: 1 | R33: 0 | S33: 0 | W33: Socratic quality 3/5 (Clarification): Generic question: asks for clarification without attacking the root error. Conceptual precision 3/5 (Sufficient): Sufficient: identifies that there is an error and uses correct concepts, but the diagnosis is somewhat vague. Good overall performance; room for improvement in socratic depth.
A34: 75 | B34: 25 | C34: 3 | D34: 1 | E34: No lo sé | F34: Considerando que el circuito solo consta de R1, R2 y R4, ¿podrías describir cómo la resistencia de cada componente afecta la distribución de la corriente cuando se aplica un voltaje? | G34: 3 | H34: 3 | I34: 2 | J34: 5 | K34: 13 | L34: 0.757 | M34: 41 | N34: 79.22 | O34: AC9 | P34: AC1 | Q34: 0 | R34: 0 | S34: 0 | W34: Socratic quality 3/5 (Clarification): Generic question: asks for clarification without attacking the root error. Conceptual precision 3/5 (Sufficient): Sufficient: identifies that there is an error and uses correct concepts, but the diagnosis is somewhat vague. Good overall performance; room for improvement in socratic depth.
A35: 76 | B35: 26 | C35: 1 | D35: 1 | E35: Todas las resistencias | F35: Considerando que el interruptor entre N2 y N3 está abierto, ¿qué resistencias, al estar en un estado de circuito abierto o cortocircuito, no influyen en la diferencia de potencial entre esos dos nodos? | G35: 3 | H35: 3 | I35: 2 | J35: 5 | K35: 13 | L35: 0.843 | M35: 46 | N35: 71.15 | O35: AC9 | P35: AC1, AC6, AC9 | Q35: 0.333 | R35: 1 | S35: 0.5 | W35: Socratic quality 3/5 (Clarification): Generic question: asks for clarification without attacking the root error. Conceptual precision 3/5 (Sufficient): Sufficient: identifies that there is an error and uses correct concepts, but the diagnosis is somewhat vague. Good overall performance; room for improvement in socratic depth.
A36: 77 | B36: 26 | C36: 2 | D36: 1 | E36: R1 y R2 | F36: Si el interruptor entre N2 y N3 mantiene el circuito abierto, ¿qué característica de las resistencias, específicamente en relación con la corriente, determina si una resistencia contribuye o no a la caída de tensión en un circuito dado? | G36: 3 | H36: 3 | I36: 2 | J36: 5 | K36: 13 | L36: 0.778 | M36: 48 | N36: 77.09 | O36: AC9 | P36: AC1, AC9 | Q36: 0.5 | R36: 1 | S36: 0.667 | W36: Socratic quality 3/5 (Clarification): Generic question: asks for clarification without attacking the root error. Conceptual precision 3/5 (Sufficient): Sufficient: identifies that there is an error and uses correct concepts, but the diagnosis is somewhat vague. Good overall performance; room for improvement in socratic depth.
A37: 78 | B37: 26 | C37: 3 | D37: 1 | E37: R1, R2 y R4 | F37: Si el interruptor entre N2 y N3 permanece abierto, ¿qué aspecto de las resistencias, como su valor o disposición, determina directamente la magnitud de la caída de tensión en cada rama del circuito? | G37: 3 | H37: 4 | I37: 2 | J37: 5 | K37: 14 | L37: 0.759 | M37: 42 | N37: 79.04 | P37: AC1, AC9 | Q37: 0 | R37: 1 | S37: 0 | W37: Socratic quality 3/5 (Clarification): Generic question: asks for clarification without attacking the root error. Conceptual precision 4/5 (Good): Good: clearly identifies the alternative conception with precise technical language. Good overall performance; room for improvement in socratic depth.
A38: 79 | B38: 27 | C38: 1 | D38: 1 | E38: R1, R2, R4 y R5 | F38: Considerando que el interruptor entre N2 y N3 está abierto, ¿podría la corriente fluir a través de R5 y, si es así, qué efecto tendría eso en la diferencia de potencial entre N2 y 0? | G38: 5 | H38: 3 | I38: 3 | J38: 5 | K38: 16 | L38: 0.929 | M38: 50 | N38: 64.56 | O38: AC6 | P38: AC1 | Q38: 0 | R38: 0 | S38: 0 | W38: Socratic quality 5/5 (Induction to contradiction): Induction to contradiction: uses counterexample or reduction to absurdity. Conceptual precision 3/5 (Sufficient): Sufficient: identifies that there is an error and uses correct concepts, but the diagnosis is somewhat vague. Good overall performance; room for improvement in socratic depth.
A39: 80 | B39: 27 | C39: 2 | D39: 1 | E39: R1, R2, R3 y R4 | F39: Si el interruptor entre N2 y N3 estuviera cerrado, ¿cómo cambiaría el flujo de corriente a través de los componentes y qué implicaría eso para la medición del voltaje en N3? | G39: 3 | H39: 4 | I39: 2 | J39: 5 | K39: 14 | L39: 0.803 | M39: 42 | N39: 74.71 | O39: AC1 | P39: AC1 | Q39: 1 | R39: 1 | S39: 1 | W39: Socratic quality 3/5 (Clarification): Generic question: asks for clarification without attacking the root error. Conceptual precision 4/5 (Good): Good: clearly identifies the alternative conception with precise technical language. Good overall performance; room for improvement in socratic depth.
A40: 81 | B40: 27 | C40: 3 | D40: 1 | E40: R1 y R2 y R4 hacen un divisor de corriente | F40: Si el objetivo es obtener una caída de voltaje específica a través de R4, ¿cómo influye la combinación de R1, R2 y R4 en la distribución general de la corriente en el circuito? | G40: 4 | H40: 3 | I40: 5 | J40: 5 | K40: 17 | L40: 0.783 | M40: 43 | N40: 76.66 | P40: AC1 | Q40: 0 | R40: 1 | S40: 0 | W40: Socratic quality 4/5 (Scaffolding for detection): Scaffolding for detection: identifies the error area and asks a question that confronts the theory. Conceptual precision 3/5 (Sufficient): Sufficient: identifies that there is an error and uses correct concepts, but the diagnosis is somewhat vague. High-performing tutor: expert socratic guidance with precise diagnosis.
...

Sheet Results_qwen2.5_latest
A1: ID | B1: Conversation | C1: Turn | D1: Exercise | E1: Student Answer | F1: Tutor Socratic Response | G1: Socratic Quality | H1: Conceptual Precision | I1: Consistency | J1: Hallucination Rate | K1: Total Score | L1: Latency (s) | M1: Tokens | N1: Throughput (resp/min) | O1: Expected ACs | P1: Detected ACs | Q1: AC Precision | R1: AC Recall | S1: AC F1 | T1: Faithfulness | U1: Relevance | V1: Think Content | W1: Constructive Feedback
