Workbook

Sheet Resultados_llama
A1: ID | B1: Conversación | C1: Turno | D1: Ejercicio | E1: Respuesta Estudiante | F1: Respuesta Tutor Socrático | G1: Socraticidad | H1: Precisión Conceptual | I1: Consistencia | J1: Tasa Alucinación | K1: Score Total | L1: Latencia (s) | M1: Tokens | N1: Throughput (resp/min) | O1: ACs Esperadas | P1: ACs Detectadas | Q1: AC Precision | R1: AC Recall | S1: AC F1 | T1: Faithfulness | U1: Relevance | V1: Think Content | W1: Feedback Constructivo
A2: 1 | B2: 1 | C2: 1 | D2: 1 | E2: R1 y R2 dado que las dos resistencia forman un divisor de tensión | F2: ¿Estás considerando solo el camino directo entre N2 y el divisor de tensión formado por R1 y R2, o has analizado también las posibles corrientes que puedan fluir a través de otros componentes hacia tierra? | G2: 3 | H2: 3 | I2: 5 | J2: 5 | K2: 16 | L2: 8.26 | M2: 55 | N2: 7.26 | O2: AC9 | P2: AC1, AC9 | Q2: 0.5 | R2: 1 | S2: 0.667 | W2: Socraticidad 3/5 (Clarificación): Pregunta genérica: pide clarificación sin atacar la raíz del error. Precisión Conceptual 3/5 (Suficiente): Suficiente: identifica que hay un error y usa conceptos correctos, pero el diagnóstico es algo vago. Buen desempeño general; hay margen de mejora en profundidad socrática.
A3: 2 | B3: 1 | C3: 2 | D3: 1 | E3: R1 y R2 dado que se pide la tensión en R2 | F3: ¿Estás asumiendo que la tensión en R2 es independiente de la corriente que fluye a través de ella y de la relación de división de tensión que establecen R1 y R2 en el circuito? | G3: 3 | H3: 3 | I3: 5 | J3: 5 | K3: 16 | L3: 3.666 | M3: 52 | N3: 16.37 | O3: AC9 | P3: AC1 | Q3: 0 | R3: 0 | S3: 0 | W3: Socraticidad 3/5 (Clarificación): Pregunta genérica: pide clarificación sin atacar la raíz del error. Precisión Conceptual 3/5 (Suficiente): Suficiente: identifica que hay un error y usa conceptos correctos, pero el diagnóstico es algo vago. Buen desempeño general; hay margen de mejora en profundidad socrática.
A4: 3 | B4: 1 | C4: 3 | D4: 1 | E4: R1 y R2 por identificar un divisor de tensión | F4: ¿Estás considerando la fórmula específica para calcular la tensión en R2 en un divisor de tensión, que involucra la relación entre las resistencias R1 y R2? | G4: 3 | H4: 3 | I4: 5 | J4: 5 | K4: 16 | L4: 3.281 | M4: 44 | N4: 18.29 | O4: AC9 | P4: AC9 | Q4: 1 | R4: 1 | S4: 1 | W4: Socraticidad 3/5 (Clarificación): Pregunta genérica: pide clarificación sin atacar la raíz del error. Precisión Conceptual 3/5 (Suficiente): Suficiente: identifica que hay un error y usa conceptos correctos, pero el diagnóstico es algo vago. Buen desempeño general; hay margen de mejora en profundidad socrática.
A5: 4 | B5: 2 | C5: 1 | D5: 1 | E5: R1 y R2 hacen un divisor de tensión | F5: ¿Qué sucede con la corriente en una rama del circuito cuando hay un interruptor abierto, y cómo afecta esto a la diferencia de potencial entre N2 y 0? | G5: 4 | H5: 3 | I5: 3 | J5: 5 | K5: 15 | L5: 2.651 | M5: 43 | N5: 22.63 | O5: AC9 | P5: AC1, AC9 | Q5: 0.5 | R5: 1 | S5: 0.667 | W5: Socraticidad 4/5 (Andamiaje para detección): Andamiaje para detección: identifica el área del error y plantea pregunta que confronta con la teoría. Precisión Conceptual 3/5 (Suficiente): Suficiente: identifica que hay un error y usa conceptos correctos, pero el diagnóstico es algo vago. Buen desempeño general; hay margen de mejora en profundidad socrática.
A6: 5 | B6: 2 | C6: 2 | D6: 1 | E6: R1, R2, R3 y R4 porque R5 está cortocircuitada | F6: ¿Estás considerando el efecto del cortocircuito en el nodo donde se encuentra R5, y cómo esto podría influir en la corriente que fluye a través de los demás resistores? | G6: 3 | H6: 4 | I6: 3 | J6: 5 | K6: 15 | L6: 3.262 | M6: 46 | N6: 18.39 | O6: AC1, AC6 | P6: AC1, AC6 | Q6: 1 | R6: 1 | S6: 1 | W6: Socraticidad 3/5 (Clarificación): Pregunta genérica: pide clarificación sin atacar la raíz del error. Precisión Conceptual 4/5 (Bueno): Bueno: identifica claramente la concepción alternativa con lenguaje técnico preciso. Buen desempeño general; hay margen de mejora en profundidad socrática.
A7: 6 | B7: 2 | C7: 3 | D7: 1 | E7: R1, R2, R3 y R4 porque por R5 no circula corriente | F7: ¿Qué sucede con el potencial en los extremos de R5 cuando está cortocircuitada, y cómo afecta esto a la distribución de corriente en el circuito? | G7: 4 | H7: 2 | I7: 3 | J7: 5 | K7: 14 | L7: 3.202 | M7: 41 | N7: 18.74 | O7: AC1, AC6 | P7: AC1 | Q7: 1 | R7: 0.5 | S7: 0.667 | W7: Socraticidad 4/5 (Andamiaje para detección): Andamiaje para detección: identifica el área del error y plantea pregunta que confronta con la teoría. Precisión Conceptual 2/5 (Pobre): Pobre: responde de forma genérica sin diagnosticar el error conceptual. Buen desempeño general; hay margen de mejora en profundidad socrática.
A8: 7 | B8: 3 | C8: 1 | D8: 1 | E8: R1, R2, R3 y R4 porque R5 se quita | F8: ¿Qué sucede con la corriente en una rama del circuito cuando hay un interruptor abierto en ella, y cómo afecta esto a la contribución de las resistencias a la diferencia de potencial entre dos nudos? | G8: 4 | H8: 4 | I8: 3 | J8: 5 | K8: 16 | L8: 3.089 | M8: 51 | N8: 19.42 | O8: AC1, AC6 | P8: AC1, AC9 | Q8: 0.5 | R8: 0.5 | S8: 0.5 | W8: Socraticidad 4/5 (Andamiaje para detección): Andamiaje para detección: identifica el área del error y plantea pregunta que confronta con la teoría. Precisión Conceptual 4/5 (Bueno): Bueno: identifica claramente la concepción alternativa con lenguaje técnico preciso. Buen desempeño general; hay margen de mejora en profundidad socrática.
A9: 8 | B9: 3 | C9: 2 | D9: 1 | E9: R1, R3 y R4 porque R2 está en paralelo con la fuente y R5 corctocircuitada | F9: ¿Cómo afecta la conexión en paralelo de R2 con la fuente a su contribución a la resistencia total del circuito, y qué sucede con la corriente a través de R5 cuando se encuentra en cortocircuito? | G9: 4 | H9: 4 | I9: 3 | J9: 5 | K9: 16 | L9: 3.912 | M9: 54 | N9: 15.34 | O9: AC1, AC6 | P9: AC1, AC6 | Q9: 1 | R9: 1 | S9: 1 | W9: Socraticidad 4/5 (Andamiaje para detección): Andamiaje para detección: identifica el área del error y plantea pregunta que confronta con la teoría. Precisión Conceptual 4/5 (Bueno): Bueno: identifica claramente la concepción alternativa con lenguaje técnico preciso. Buen desempeño general; hay margen de mejora en profundidad socrática.
A10: 9 | B10: 3 | C10: 3 | D10: 1 | E10: R1, R4 y R5 porque R2 se elimina y R3 también | F10: ¿Por qué crees que R3 se elimina si no hay un interruptor abierto o un cortocircuito que lo afecte directamente, y cómo puede influir su posición en el circuito en la corriente que fluye a través de él? | G10: 4 | H10: 4 | I10: 3 | J10: 5 | K10: 16 | L10: 4.147 | M10: 57 | N10: 14.47 | O10: AC1, AC6 | P10: AC1, AC6 | Q10: 1 | R10: 1 | S10: 1 | W10: Socraticidad 4/5 (Andamiaje para detección): Andamiaje para detección: identifica el área del error y plantea pregunta que confronta con la teoría. Precisión Conceptual 4/5 (Bueno): Bueno: identifica claramente la concepción alternativa con lenguaje técnico preciso. Buen desempeño general; hay margen de mejora en profundidad socrática.
A11: 10 | B11: 4 | C11: 1 | D11: 1 | E11: R1 y R4 dado que R2 está en paralelo con la fuente, R3 en circuito abierto y R5 cortocircuitada | F11: ¿Qué relación hay entre la resistencia R2 y el camino que sigue la corriente desde el nodo N2 hasta tierra, considerando que R2 está conectada en serie con otras resistencias en el camino hacia la fuente? | G11: 3 | H11: 3 | I11: 3 | J11: 5 | K11: 14 | L11: 3.223 | M11: 51 | N11: 18.61 | O11: AC1, AC6 | P11: AC1, AC9 | Q11: 0.5 | R11: 0.5 | S11: 0.5 | W11: Socraticidad 3/5 (Clarificación): Pregunta genérica: pide clarificación sin atacar la raíz del error. Precisión Conceptual 3/5 (Suficiente): Suficiente: identifica que hay un error y usa conceptos correctos, pero el diagnóstico es algo vago. Buen desempeño general; hay margen de mejora en profundidad socrática.
A12: 11 | B12: 4 | C12: 2 | D12: 1 | E12: R1, R2 y R3 dado que R2 y R3 están en paralelo y forman un divisor de tensión con R1 | F12: ¿No se ha considerado el estado de R5 como cortocircuitada, lo que podría afectar el comportamiento del circuito y la relación entre R1, R2 y R3 en este contexto? | G12: 3 | H12: 2 | I12: 5 | J12: 5 | K12: 15 | L12: 3.507 | M12: 45 | N12: 17.11 | O12: AC1, AC9 | P12: AC9 | Q12: 1 | R12: 0.5 | S12: 0.667 | W12: Socraticidad 3/5 (Clarificación): Pregunta genérica: pide clarificación sin atacar la raíz del error. Precisión Conceptual 2/5 (Pobre): Respuesta genérica: sin vocabulario técnico ni diagnóstico del error. Buen desempeño general; hay margen de mejora en profundidad socrática.
A13: 12 | B13: 4 | C13: 3 | D13: 1 | E13: R1, R2, R4 y R5 dado que R3 está en circuito abierto | F13: ¿Cómo afecta el estado de R3 en circuito abierto a la corriente que fluye a través de R4 y R5, considerando el camino que sigue la corriente en el circuito? | G13: 4 | H13: 4 | I13: 4 | J13: 5 | K13: 17 | L13: 3.661 | M13: 47 | N13: 16.39 | O13: AC1, AC6 | P13: AC1, AC9 | Q13: 0.5 | R13: 0.5 | S13: 0.5 | W13: Socraticidad 4/5 (Andamiaje para detección): Andamiaje para detección: identifica el área del error y plantea pregunta que confronta con la teoría. Precisión Conceptual 4/5 (Bueno): Bueno: identifica claramente la concepción alternativa con lenguaje técnico preciso. Tutor de alto rendimiento: guía socrática experta con diagnóstico preciso.
... A15: 14 | B15: 5 | C15: 2 | D15: 1 | E15: R1, R2, R4 y R5 dado que R3 no hace nada | F15: ¿No podría R3 influir en la corriente que fluye a través de otras resistencias si estuviera conectada en serie o en paralelo con ellas, cambiando así la distribución de corrientes en el circuito? | G15: 3 | H15: 3 | I15: 3 | J15: 5 | K15: 14 | L15: 3.8 | M15: 53 | N15: 15.79 | O15: AC1, AC6 | P15: AC1, AC9 | Q15: 0.5 | R15: 0.5 | S15: 0.5 | W15: Socraticidad 3/5 (Clarificación): Pregunta genérica: pide clarificación sin atacar la raíz del error. Precisión Conceptual 3/5 (Suficiente): Suficiente: identifica que hay un error y usa conceptos correctos, pero el diagnóstico es algo vago. Buen desempeño general; hay margen de mejora en profundidad socrática.
A16: 15 | B16: 5 | C16: 3 | D16: 1 | E16: R1, R2 y R4 dado que son las resistencias que forman parte del circuito. | F16: ¿Qué papel juega R5 en el circuito si está conectada en paralelo con R4, y cómo afecta esto a la contribución de R5 a la resistencia total del circuito? | G16: 3 | H16: 3 | I16: 3 | J16: 5 | K16: 14 | L16: 3.449 | M16: 45 | N16: 17.4 | Q16: 1 | R16: 1 | S16: 1 | W16: Socraticidad 3/5 (Clarificación): Pregunta genérica: pide clarificación sin atacar la raíz del error. Precisión Conceptual 3/5 (Suficiente): Suficiente: identifica que hay un error y usa conceptos correctos, pero el diagnóstico es algo vago. Buen desempeño general; hay margen de mejora en profundidad socrática.
A17: 16 | B17: 6 | C17: 1 | D17: 1 | E17: R1, R2 y R4 dado que R2 y R4 están en paralelo y forma un divisor de tensión con R1. | F17: ¿Qué sucede con la corriente en una rama del circuito cuando hay un interruptor abierto, como el que está entre los nudos N2 y N3, y cómo afecta esto a la contribución de las resistencias a la diferencia de potencial entre N2 y 0? | G17: 4 | H17: 4 | I17: 3 | J17: 5 | K17: 16 | L17: 4.025 | M17: 65 | N17: 14.91 | P17: AC1, AC9 | Q17: 0 | R17: 1 | S17: 0 | W17: Socraticidad 4/5 (Andamiaje para detección): Andamiaje para detección: identifica el área del error y plantea pregunta que confronta con la teoría. Precisión Conceptual 4/5 (Bueno): Bueno: identifica claramente la concepción alternativa con lenguaje técnico preciso. Buen desempeño general; hay margen de mejora en profundidad socrática.
A18: 17 | B18: 6 | C18: 2 | D18: 1 | E18: R1, R2 y R4 dado que R3 está en abierto y R5 cortocircuitada | F18: ¿Cómo se comportan las resistencias R2 y R4 cuando están en paralelo y se conectan en serie con R1, considerando que R3 está abierto y no permite el flujo de corriente a través de él? | G18: 3 | H18: 3 | I18: 5 | J18: 5 | K18: 16 | L18: 4.281 | M18: 53 | N18: 14.02 | O18: AC1, AC6 | P18: AC1, AC9 | Q18: 0.5 | R18: 0.5 | S18: 0.5 | W18: Socraticidad 3/5 (Clarificación): Pregunta genérica: pide clarificación sin atacar la raíz del error. Precisión Conceptual 3/5 (Suficiente): Suficiente: identifica que hay un error y usa conceptos correctos, pero el diagnóstico es algo vago. Buen desempeño general; hay margen de mejora en profundidad socrática.
A19: 18 | B19: 6 | C19: 3 | D19: 1 | E19: R1, R2 y R4 dado que solo por estas resistencias circula una corriente diferente de cero | F19: ¿Qué efecto tiene el cortocircuito de R5 en la distribución de la corriente a través de R2 y R4, considerando que R3 está abierto? | G19: 3 | H19: 3 | I19: 4 | J19: 5 | K19: 15 | L19: 3.286 | M19: 41 | N19: 18.26 | P19: AC1, AC6 | Q19: 0 | R19: 1 | S19: 0 | W19: Socraticidad 3/5 (Clarificación): Pregunta genérica: pide clarificación sin atacar la raíz del error. Precisión Conceptual 3/5 (Suficiente): Suficiente: identifica que hay un error y usa conceptos correctos, pero el diagnóstico es algo vago. Buen desempeño general; hay margen de mejora en profundidad socrática.
A20: 19 | B20: 7 | C20: 1 | D20: 1 | E20: R1, R2 y R4 dado que por R3 y por R5 no circula corriente | F20: ¿Estás seguro de que has considerado todos los posibles caminos que la corriente puede tomar desde el nodo N2 hasta tierra, incluyendo todos los componentes que se encuentran en ese camino? ¿Has analizado cada una de las resistencias en relación con su conexión a N2 y a tierra? | G20: 3 | H20: 3 | I20: 3 | J20: 5 | K20: 14 | L20: 3.984 | M20: 70 | N20: 15.06 | O20: AC1, AC6 | P20: AC1, AC9 | Q20: 0.5 | R20: 0.5 | S20: 0.5 | W20: Socraticidad 3/5 (Clarificación): Pregunta genérica: pide clarificación sin atacar la raíz del error. Precisión Conceptual 3/5 (Suficiente): Suficiente: identifica que hay un error y usa conceptos correctos, pero el diagnóstico es algo vago. Buen desempeño general; hay margen de mejora en profundidad socrática.
A21: 20 | B21: 7 | C21: 2 | D21: 1 | E21: R1, R2 y R4 dado que R3 y R5 se pueden quitar | F21: ¿Qué sucedería con el flujo de corriente si R3 y R5 se conectaran en paralelo con otras resistencias en lugar de estar en serie, afectando así su contribución a la red eléctrica? ¿Cómo影响aría esto tu análisis inicial sobre las resistencias que no contribuyen a la circulación de corriente? | G21: 3 | H21: 3 | I21: 3 | J21: 5 | K21: 14 | L21: 5.256 | M21: 79 | N21: 11.42 | O21: AC1, AC6 | P21: AC1, AC9 | Q21: 0.5 | R21: 0.5 | S21: 0.5 | W21: Socraticidad 3/5 (Clarificación): Pregunta genérica: pide clarificación sin atacar la raíz del error. Precisión Conceptual 3/5 (Suficiente): Suficiente: identifica que hay un error y usa conceptos correctos, pero el diagnóstico es algo vago. Buen desempeño general; hay margen de mejora en profundidad socrática.
A22: 21 | B22: 7 | C22: 3 | D22: 1 | E22: R1, R2 y R4 dado que R3 y R5 no influyen para nada en la diferencia de potencial que se pide | F22: ¿Estás considerando que la presencia de R3 y R5 podría afectar la distribución de corriente en el circuito, incluso si no están directamente en el camino del nodo de interés? ¿Cómo justificarías que su eliminación no tenga efecto en la diferencia de potencial que se busca calcular? | G22: 3 | H22: 3 | I22: 3 | J22: 5 | K22: 14 | L22: 5.012 | M22: 70 | N22: 11.97 | O22: AC1, AC6 | P22: AC1, AC9 | Q22: 0.5 | R22: 0.5 | S22: 0.5 | W22: Socraticidad 3/5 (Clarificación): Pregunta genérica: pide clarificación sin atacar la raíz del error. Precisión Conceptual 3/5 (Suficiente): Suficiente: identifica que hay un error y usa conceptos correctos, pero el diagnóstico es algo vago. Buen desempeño general; hay margen de mejora en profundidad socrática.
A23: 22 | B23: 8 | C23: 1 | D23: 1 | E23: R1, R2 y R4 dado que R3 y R5 sobran | F23: ¿Qué sucede con la corriente en una rama del circuito cuando se encuentra interrumpida por un interruptor abierto, y cómo afecta esto a las resistencias involucradas en esa rama? | G23: 4 | H23: 4 | I23: 3 | J23: 5 | K23: 16 | L23: 3.051 | M23: 49 | N23: 19.67 | O23: AC1, AC6 | P23: AC1, AC9 | Q23: 0.5 | R23: 0.5 | S23: 0.5 | W23: Socraticidad 4/5 (Andamiaje para detección): Andamiaje para detección: identifica el área del error y plantea pregunta que confronta con la teoría. Precisión Conceptual 4/5 (Bueno): Bueno: identifica claramente la concepción alternativa con lenguaje técnico preciso. Buen desempeño general; hay margen de mejora en profundidad socrática.
A24: 23 | B24: 8 | C24: 2 | D24: 1 | E24: R1, R2 y R4 dado que R3 sobra | F24: ¿Consideraste la posibilidad de que R5 pueda estar en serie o en paralelo con alguna de las resistencias que mencionaste, y cómo podría afectar su inclusión o exclusión en el circuito? | G24: 3 | H24: 3 | I24: 3 | J24: 5 | K24: 14 | L24: 3.586 | M24: 47 | N24: 16.73 | O24: AC1 | P24: AC9 | Q24: 0 | R24: 0 | S24: 0 | W24: Socraticidad 3/5 (Clarificación): Pregunta genérica: pide clarificación sin atacar la raíz del error. Precisión Conceptual 3/5 (Suficiente): Suficiente: identifica que hay un error y usa conceptos correctos, pero el diagnóstico es algo vago. Buen desempeño general; hay margen de mejora en profundidad socrática.
A25: 24 | B25: 8 | C25: 3 | D25: 1 | E25: R1, R2 y R4 dado que R5 sobra | F25: ¿Qué pasaría si R3 y R5 estuvieran conectadas en paralelo, y cómo afectaría esto a la configuración del circuito y a las resistencias involucradas? | G25: 3 | H25: 3 | I25: 3 | J25: 5 | K25: 14 | L25: 3.463 | M25: 43 | N25: 17.33 | O25: AC6 | P25: AC9 | Q25: 0 | R25: 0 | S25: 0 | W25: Socraticidad 3/5 (Clarificación): Pregunta genérica: pide clarificación sin atacar la raíz del error. Precisión Conceptual 3/5 (Suficiente): Suficiente: identifica que hay un error y usa conceptos correctos, pero el diagnóstico es algo vago. Buen desempeño general; hay margen de mejora en profundidad socrática.
A26: 25 | B26: 9 | C26: 1 | D26: 1 | E26: R1, R2 y R4 dado que R3 está en abierto | F26: ¿Qué sucede con la corriente en una rama cuando hay un interruptor abierto en el camino, y cómo afecta esto a la contribución de las resistencias en la diferencia de potencial entre dos nudos? | G26: 4 | H26: 4 | I26: 3 | J26: 5 | K26: 16 | L26: 2.889 | M26: 49 | N26: 20.77 | O26: AC1 | P26: AC1, AC9 | Q26: 0.5 | R26: 1 | S26: 0.667 | W26: Socraticidad 4/5 (Andamiaje para detección): Andamiaje para detección: identifica el área del error y plantea pregunta que confronta con la teoría. Precisión Conceptual 4/5 (Bueno): Bueno: identifica claramente la concepción alternativa con lenguaje técnico preciso. Buen desempeño general; hay margen de mejora en profundidad socrática.
A27: 26 | B27: 9 | C27: 2 | D27: 1 | E27: R1, R2 y R4 dado que R5 cortocircuitada | F27: ¿Cómo cambia el flujo de corriente y la relación entre las resistencias cuando una de ellas, como R5, se encuentra cortocircuitada, y qué efecto tiene esto en la equivalencia de resistencias en el circuito? | G27: 4 | H27: 3 | I27: 3 | J27: 5 | K27: 15 | L27: 3.871 | M27: 53 | N27: 15.5 | O27: AC6 | P27: AC1, AC9 | Q27: 0 | R27: 0 | S27: 0 | W27: Socraticidad 4/5 (Andamiaje para detección): Andamiaje para detección: identifica el área del error y plantea pregunta que confronta con la teoría. Precisión Conceptual 3/5 (Suficiente): Suficiente: identifica que hay un error y usa conceptos correctos, pero el diagnóstico es algo vago. Buen desempeño general; hay margen de mejora en profundidad socrática.
A28: 27 | B28: 9 | C28: 3 | D28: 1 | E28: R1, R2 y R4 dado que por R3 no circula corriente | F28: ¿La ausencia de corriente en R3 implica que no hay voltaje a través de ella, y cómo afecta esto a la configuración equivalente del circuito con R1, R2 y R4? | G28: 3 | H28: 3 | I28: 5 | J28: 5 | K28: 16 | L28: 3.693 | M28: 48 | N28: 16.25 | O28: AC1 | P28: AC1 | Q28: 1 | R28: 1 | S28: 1 | W28: Socraticidad 3/5 (Clarificación): Pregunta genérica: pide clarificación sin atacar la raíz del error. Precisión Conceptual 3/5 (Suficiente): Suficiente: identifica que hay un error y usa conceptos correctos, pero el diagnóstico es algo vago. Buen desempeño general; hay margen de mejora en profundidad socrática.
A29: 28 | B29: 10 | C29: 1 | D29: 1 | E29: R1, R2 y R4 dado que por R5 no circula corriente | F29: ¿Qué sucede con la corriente en una rama del circuito cuando hay un interruptor abierto, como el que está entre los nudos N2 y N3? ¿Cómo afecta esto a la contribución de las resistencias en esa rama a la diferencia de potencial entre N2 y 0? | G29: 4 | H29: 3 | I29: 2 | J29: 5 | K29: 14 | L29: 3.872 | M29: 69 | N29: 15.5 | O29: AC6 | P29: AC1, AC9 | Q29: 0 | R29: 0 | S29: 0 | W29: Socraticidad 4/5 (Andamiaje para detección): Andamiaje para detección: identifica el área del error y plantea pregunta que confronta con la teoría. Precisión Conceptual 3/5 (Suficiente): Suficiente: identifica que hay un error y usa conceptos correctos, pero el diagnóstico es algo vago. Buen desempeño general; hay margen de mejora en profundidad socrática.
A30: 29 | B30: 10 | C30: 2 | D30: 1 | E30: R1, R2 y R4 dado que R3 se puede quitar | F30: ¿La eliminación de R3 se debe a que está en serie o en paralelo con otras resistencias en el circuito? ¿Cómo afecta la configuración de las resistencias en el circuito a la circulación de corriente a través de cada una de ellas? | G30: 4 | H30: 3 | I30: 3 | J30: 5 | K30: 15 | L30: 4.241 | M30: 61 | N30: 14.15 | O30: AC1 | P30: AC1, AC9 | Q30: 0.5 | R30: 1 | S30: 0.667 | W30: Socraticidad 4/5 (Andamiaje para detección): Andamiaje para detección: identifica el área del error y plantea pregunta que confronta con la teoría. Precisión Conceptual 3/5 (Suficiente): Suficiente: identifica que hay un error y usa conceptos correctos, pero el diagnóstico es algo vago. Buen desempeño general; hay margen de mejora en profundidad socrática.
A31: 30 | B31: 10 | C31: 3 | D31: 1 | E31: R1, R2 y R4 dado que R5 se puede quitar | F31: ¿La resistencia R5 se puede quitar porque no forma parte de un camino crítico para la corriente en el circuito? ¿Qué condiciones deben cumplirse para que una resistencia en un circuito pueda considerarse no esencial para el flujo de corriente? | G31: 3 | H31: 3 | I31: 3 | J31: 5 | K31: 14 | L31: 4.151 | M31: 61 | N31: 14.45 | O31: AC6 | P31: AC1, AC9 | Q31: 0 | R31: 0 | S31: 0 | W31: Socraticidad 3/5 (Clarificación): Pregunta genérica: pide clarificación sin atacar la raíz del error. Precisión Conceptual 3/5 (Suficiente): Suficiente: identifica que hay un error y usa conceptos correctos, pero el diagnóstico es algo vago. Buen desempeño general; hay margen de mejora en profundidad socrática.
... A36: 35 | B36: 12 | C36: 2 | D36: 1 | E36: R1 y R2 | F36: ¿Estás considerando la posibilidad de que haya una relación entre la suma de resistencias en serie y la ley de Ohm, y cómo esto podría aplicarse a los componentes R1 y R2 en el circuito? | G36: 3 | H36: 3 | I36: 2 | J36: 5 | K36: 13 | L36: 3.589 | M36: 49 | N36: 16.72 | O36: AC9 | P36: AC9 | Q36: 1 | R36: 1 | S36: 1 | W36: Socraticidad 3/5 (Clarificación): Pregunta genérica: pide clarificación sin atacar la raíz del error. Precisión Conceptual 3/5 (Suficiente): Suficiente: identifica que hay un error y usa conceptos correctos, pero el diagnóstico es algo vago. Buen desempeño general; hay margen de mejora en profundidad socrática.
A37: 36 | B37: 12 | C37: 3 | D37: 1 | E37: R1, R2 y R4 | F37: ¿Consideraste la configuración de los componentes R1, R2 y R4 en relación con el nodo común y cómo afecta la distribución de la corriente en el circuito? | G37: 3 | H37: 3 | I37: 3 | J37: 5 | K37: 14 | L37: 3.269 | M37: 43 | N37: 18.35 | P37: AC1 | Q37: 0 | R37: 1 | S37: 0 | W37: Socraticidad 3/5 (Clarificación): Pregunta genérica: pide clarificación sin atacar la raíz del error. Precisión Conceptual 3/5 (Suficiente): Suficiente: identifica que hay un error y usa conceptos correctos, pero el diagnóstico es algo vago. Buen desempeño general; hay margen de mejora en profundidad socrática.
A38: 37 | B38: 13 | C38: 1 | D38: 1 | E38: R1, R2, R4 y R5 | F38: ¿Qué sucede con la corriente que pasa por R5 si se observa que sus dos terminales están conectadas directamente, según el netlist proporcionado? | G38: 4 | H38: 3 | I38: 3 | J38: 5 | K38: 15 | L38: 2.354 | M38: 37 | N38: 25.49 | O38: AC6 | P38: AC1, AC6 | Q38: 0.5 | R38: 1 | S38: 0.667 | W38: Socraticidad 4/5 (Andamiaje para detección): Andamiaje para detección: identifica el área del error y plantea pregunta que confronta con la teoría. Precisión Conceptual 3/5 (Suficiente): Suficiente: identifica que hay un error y usa conceptos correctos, pero el diagnóstico es algo vago. Buen desempeño general; hay margen de mejora en profundidad socrática.
A39: 38 | B39: 13 | C39: 2 | D39: 1 | E39: R1, R2, R3 y R4 | F39: ¿Por qué incluyes R3 en tu lista cuando en la pregunta original solo se mencionan R1, R2, R4 y R5? | G39: 3 | H39: 2 | I39: 4 | J39: 5 | K39: 14 | L39: 2.681 | M39: 34 | N39: 22.38 | O39: AC1 | P39: AC1, AC6 | Q39: 0.5 | R39: 1 | S39: 0.667 | W39: Socraticidad 3/5 (Clarificación): Pregunta genérica: pide clarificación sin atacar la raíz del error. Precisión Conceptual 2/5 (Pobre): Respuesta genérica: sin vocabulario técnico ni diagnóstico del error. Buen desempeño general; hay margen de mejora en profundidad socrática.
A40: 39 | B40: 13 | C40: 3 | D40: 1 | E40: R1 y R2 y R4 hacen un divisor de corriente | F40: ¿Cómo se relaciona el comportamiento de un divisor de corriente con la resistencia R5 en el circuito, considerando que R1, R2 y R4 forman parte de este divisor? | G40: 3 | H40: 3 | I40: 5 | J40: 5 | K40: 16 | L40: 3.238 | M40: 45 | N40: 18.53 | P40: AC1, AC9 | Q40: 0 | R40: 1 | S40: 0 | W40: Socraticidad 3/5 (Clarificación): Pregunta genérica: pide clarificación sin atacar la raíz del error. Precisión Conceptual 3/5 (Suficiente): Suficiente: identifica que hay un error y usa conceptos correctos, pero el diagnóstico es algo vago. Buen desempeño general; hay margen de mejora en profundidad socrática.
A41: 40 | B41: 14 | C41: 1 | D41: 1 | E41: R1 y R2 y R4 hacen un divisor de tensión, r3 no cuenta por estar en corto | F41: ¿Qué sucede con la corriente en una rama cuando hay un interruptor abierto, como el que está entre los nudos N2 y N3, y cómo afecta esto a las resistencias que contribuyen a la diferencia de potencial entre N2 y 0? | G41: 4 | H41: 4 | I41: 3 | J41: 5 | K41: 16 | L41: 3.682 | M41: 61 | N41: 16.3 | O41: AC1 | P41: AC1, AC9 | Q41: 0.5 | R41: 1 | S41: 0.667 | W41: Socraticidad 4/5 (Andamiaje para detección): Andamiaje para detección: identifica el área del error y plantea pregunta que confronta con la teoría. Precisión Conceptual 4/5 (Bueno): Bueno: identifica claramente la concepción alternativa con lenguaje técnico preciso. Buen desempeño general; hay margen de mejora en profundidad socrática.
A42: 41 | B42: 14 | C42: 2 | D42: 1 | E42: No tengo en cuenta R3 porque el interruptor está cerrado | F42: ¿Estás seguro de que el interruptor cerrado no afecta la corriente que fluye a través de R3 y, por lo tanto, su contribución al divisor de tensión? | G42: 3 | H42: 4 | I42: 5 | J42: 5 | K42: 17 | L42: 3.517 | M42: 42 | N42: 17.06 | O42: AC1, AC9 | P42: AC1 | Q42: 1 | R42: 0.5 | S42: 0.667 | W42: Socraticidad 3/5 (Clarificación): Pregunta genérica: pide clarificación sin atacar la raíz del error. Precisión Conceptual 4/5 (Bueno): Bueno: identifica claramente la concepción alternativa con lenguaje técnico preciso. Tutor de alto rendimiento: guía socrática experta con diagnóstico preciso.
A43: 42 | B43: 14 | C43: 3 | D43: 1 | E43: No tengo en cuenta R5 porque está en circuito abierto | F43: ¿Cómo determinarías si R5 realmente está en circuito abierto y no forma parte de un camino de corriente alternativo que pase por otros componentes del circuito? | G43: 3 | H43: 3 | I43: 5 | J43: 5 | K43: 16 | L43: 3.084 | M43: 40 | N43: 19.45 | O43: AC6, AC9 | P43: AC1, AC9 | Q43: 0.5 | R43: 0.5 | S43: 0.5 | W43: Socraticidad 3/5 (Clarificación): Pregunta genérica: pide clarificación sin atacar la raíz del error. Precisión Conceptual 3/5 (Suficiente): Suficiente: identifica que hay un error y usa conceptos correctos, pero el diagnóstico es algo vago. Buen desempeño general; hay margen de mejora en profundidad socrática.

Sheet Resultados_phi4
A1: ID | B1: Conversación | C1: Turno | D1: Ejercicio | E1: Respuesta Estudiante | F1: Respuesta Tutor Socrático | G1: Socraticidad | H1: Precisión Conceptual | I1: Consistencia | J1: Tasa Alucinación | K1: Score Total | L1: Latencia (s) | M1: Tokens | N1: Throughput (resp/min) | O1: ACs Esperadas | P1: ACs Detectadas | Q1: AC Precision | R1: AC Recall | S1: AC F1 | T1: Faithfulness | U1: Relevance | V1: Think Content | W1: Feedback Constructivo
A2: 43 | B2: 15 | C2: 1 | D2: 1 | E2: R1 y R2 dado que las dos resistencia forman un divisor de tensión | F2: ¿Puedes identificar qué ocurre con el flujo del corriente a través de los componentes individuales, y cómo afecta esto las resistencias entre N2 y tierra, teniendo en cuenta el estado del interruptor entre N2 y N3? ¿Debes considerar R1, R2 o otra resistencia también? | G2: 3 | H2: 3 | I2: 5 | J2: 5 | K2: 16 | L2: 32.717 | M2: 60 | N2: 1.83 | O2: AC9 | P2: AC1, AC9 | Q2: 0.5 | R2: 1 | S2: 0.667 | W2: Socraticidad 3/5 (Clarificación): Pregunta genérica: pide clarificación sin atacar la raíz del error. Precisión Conceptual 3/5 (Suficiente): Suficiente: identifica que hay un error y usa conceptos correctos, pero el diagnóstico es algo vago. Buen desempeño general; hay margen de mejora en profundidad socrática.
A3: 44 | B3: 15 | C3: 2 | D3: 1 | E3: R1 y R2 dado que se pide la tensión en R2 | F3: ¿Cómo afectará la presencia de un posible camino corto entre N2 y tierra, influenciado por el estado del interruptor hacia N3, a las diferentes corrientes que pueden fluir através de R1 y R2 durante una situación con o sin cortocircuito? ¿Cuál sería su impacto en los voltajes registrados ante terminales de cada resistencia si se mide con respecto al punto medio común entre R1 y R2? | G3: 3 | H3: 3 | I3: 3 | J3: 5 | K3: 14 | L3: 0.937 | M3: 89 | N3: 64.02 | O3: AC9 | P3: AC1, AC6, AC9 | Q3: 0.333 | R3: 1 | S3: 0.5 | W3: Socraticidad 3/5 (Clarificación): Pregunta genérica: pide clarificación sin atacar la raíz del error. Precisión Conceptual 3/5 (Suficiente): Suficiente: identifica que hay un error y usa conceptos correctos, pero el diagnóstico es algo vago. Buen desempeño general; hay margen de mejora en profundidad socrática.
A4: 45 | B4: 15 | C4: 3 | D4: 1 | E4: R1 y R2 por identificar un divisor de tensión | F4: ¿Puedo asegurarme de haber identificado correctamente el circuito configurado como un divisor de tensión, o he pasado por alto algún otro componente potencialmente relevante? ¿Mi interpretación del papel del interruptor dentro del circuito asegura una configuración dividida apropiada para R1 y R2? | G4: 3 | H4: 3 | I4: 3 | J4: 5 | K4: 14 | L4: 0.719 | M4: 57 | N4: 83.43 | O4: AC9 | P4: AC1 | Q4: 0 | R4: 0 | S4: 0 | W4: Socraticidad 3/5 (Clarificación): Pregunta genérica: pide clarificación sin atacar la raíz del error. Precisión Conceptual 3/5 (Suficiente): Suficiente: identifica que hay un error y usa conceptos correctos, pero el diagnóstico es algo vago. Buen desempeño general; hay margen de mejora en profundidad socrática.
A5: 46 | B5: 16 | C5: 1 | D5: 1 | E5: R1 y R2 hacen un divisor de tensión | F5: ¿Puedes confirmar si el camino del nudo N3 está cerrado, lo que potencialmente involucraría a R3 y una diferencia de potencial entre N3 y tierra? ¿Y cómo afecta un interruptor abierto entre los nudos N2 y N3 al flujo de corriente pasando por R5? | G5: 3 | H5: 3 | I5: 2 | J5: 5 | K5: 13 | L5: 1.009 | M5: 61 | N5: 59.44 | O5: AC9 | P5: AC1, AC9 | Q5: 0.5 | R5: 1 | S5: 0.667 | W5: Socraticidad 3/5 (Clarificación): Pregunta genérica: pide clarificación sin atacar la raíz del error. Precisión Conceptual 3/5 (Suficiente): Suficiente: identifica que hay un error y usa conceptos correctos, pero el diagnóstico es algo vago. Buen desempeño general; hay margen de mejora en profundidad socrática.
A6: 47 | B6: 16 | C6: 2 | D6: 1 | E6: R1, R2, R3 y R4 porque R5 está cortocircuitada | F6: ¿Podrían los valores de las resistencias R1, R2, R3 y R4 determinarse independientemente del cortocircuito creado por R5?, considerando el papel actual jugado por R5 dentro del circuito? | G6: 3 | H6: 3 | I6: 5 | J6: 5 | K6: 16 | L6: 0.693 | M6: 48 | N6: 86.54 | O6: AC1, AC6 | P6: AC6, AC9 | Q6: 0.5 | R6: 0.5 | S6: 0.5 | W6: Socraticidad 3/5 (Clarificación): Pregunta genérica: pide clarificación sin atacar la raíz del error. Precisión Conceptual 3/5 (Suficiente): Suficiente: identifica que hay un error y usa conceptos correctos, pero el diagnóstico es algo vago. Buen desempeño general; hay margen de mejora en profundidad socrática.
A7: 48 | B7: 16 | C7: 3 | D7: 1 | E7: R1, R2, R3 y R4 porque por R5 no circula corriente | F7: Si el nudo N5 está conectado a los terminales de R5, ¿cómo afecta esto a la presencia o ausencia de corriente a través de R1, R2, R3 y R4? Especifica si su estado podría cambiar con una condición diferente (por ejemplo, un cambio del interruptor abierto al cerrado)? | G7: 4 | H7: 3 | I7: 4 | J7: 5 | K7: 16 | L7: 0.825 | M7: 68 | N7: 72.75 | O7: AC1, AC6 | P7: AC1, AC6 | Q7: 1 | R7: 1 | S7: 1 | W7: Socraticidad 4/5 (Andamiaje para detección): Andamiaje para detección: identifica el área del error y plantea pregunta que confronta con la teoría. Precisión Conceptual 3/5 (Suficiente): Suficiente: identifica que hay un error y usa conceptos correctos, pero el diagnóstico es algo vago. Buen desempeño general; hay margen de mejora en profundidad socrática.
A8: 49 | B8: 17 | C8: 1 | D8: 1 | E8: R1, R2, R3 y R4 porque R5 se quita | F8: ¿Puedes confirmar qué sucede con el flujo de corriente a través del interruptor abierto entre N2 y N3, y cómo eso afecta las resistencias R1, R2, R3, R4 y R5? ¿Y cuáles son los efectos del cortocircuito para la contribución al voltaje en el nudo N2 comparado con tierra (0)? | G8: 3 | H8: 5 | I8: 3 | J8: 5 | K8: 16 | L8: 0.825 | M8: 77 | N8: 72.71 | O8: AC1, AC6 | P8: AC1, AC6, AC9 | Q8: 0.667 | R8: 1 | S8: 0.8 | W8: Socraticidad 3/5 (Clarificación): Pregunta genérica: pide clarificación sin atacar la raíz del error. Precisión Conceptual 5/5 (Excelente): Excelente: identifica la concepción alternativa específica y la conecta con la topología del circuito. Buen desempeño general; hay margen de mejora en profundidad socrática.
A9: 50 | B9: 17 | C9: 2 | D9: 1 | E9: R1, R3 y R4 porque R2 está en paralelo con la fuente y R5 corctocircuitada | F9: ¿El posicionamiento del interruptor abierto entre N2 y N3 impacta el flujo de corriente a través de R1, R2, R3, R4 y R5 igual o diferente? Además, ¿cómo podría un cortocircuito afectar al voltaje medido a nivel de N2 en comparación con tierra (0)? | G9: 3 | H9: 5 | I9: 5 | J9: 5 | K9: 18 | L9: 0.988 | M9: 70 | N9: 60.72 | O9: AC1, AC6 | P9: AC1, AC6, AC9 | Q9: 0.667 | R9: 1 | S9: 0.8 | W9: Socraticidad 3/5 (Clarificación): Pregunta genérica: pide clarificación sin atacar la raíz del error. Precisión Conceptual 5/5 (Excelente): Excelente: identifica la concepción alternativa específica y la conecta con la topología del circuito. Tutor de alto rendimiento: guía socrática experta con diagnóstico preciso.
A10: 51 | B10: 17 | C10: 3 | D10: 1 | E10: R1, R4 y R5 porque R2 se elimina y R3 también | F10: ¿El posicionamiento del interruptor abierto entre N2 y N3 cambia efectivamente el papel de R1, R4 o R5 dentro del circuito? Además, ¿cómo podría un cortocircuito influir en la medición del voltaje a nivel de N2 respecto al caso original sin este cambio (0)? | G10: 3 | H10: 5 | I10: 4 | J10: 5 | K10: 17 | L10: 0.694 | M10: 67 | N10: 86.49 | O10: AC1, AC6 | P10: AC1, AC6, AC9 | Q10: 0.667 | R10: 1 | S10: 0.8 | W10: Socraticidad 3/5 (Clarificación): Pregunta genérica: pide clarificación sin atacar la raíz del error. Precisión Conceptual 5/5 (Excelente): Excelente: identifica la concepción alternativa específica y la conecta con la topología del circuito. Tutor de alto rendimiento: guía socrática experta con diagnóstico preciso.
A11: 52 | B11: 18 | C11: 1 | D11: 1 | E11: R1 y R4 dado que R2 está en paralelo con la fuente, R3 en circuito abierto y R5 cortocircuitada | F11: ¿Consideró si el estado del interruptor entre N2 y N3 afecta el camino de corriente para R1, R2 y R4? Y ¿cómo influyen los estados de circuito abierto o cortocircuito de las otras resistencias al cálculo final del valor de la diferencia de potencial entre N2 y 0? | G11: 3 | H11: 5 | I11: 4 | J11: 5 | K11: 17 | L11: 0.729 | M11: 68 | N11: 82.3 | O11: AC1, AC6 | P11: AC1, AC6, AC9 | Q11: 0.667 | R11: 1 | S11: 0.8 | W11: Socraticidad 3/5 (Clarificación): Pregunta genérica: pide clarificación sin atacar la raíz del error. Precisión Conceptual 5/5 (Excelente): Excelente: identifica la concepción alternativa específica y la conecta con la topología del circuito. Tutor de alto rendimiento: guía socrática experta con diagnóstico preciso.
A12: 53 | B12: 18 | C12: 2 | D12: 1 | E12: R1, R2 y R3 dado que R2 y R3 están en paralelo y forman un divisor de tensión con R1 | F12: ¿Podría ayudarme a entender cómo el divisor de dos ramas (R2, R3 paralelos y R1 paralelo con ellos) afecta el valor del voltaje entre N2 y tierra? ¿Cómo calcularía el voltaje efectivo ante el nodo N2 teniendo en cuenta los caminos separados para la corriente por R2 y R3? | G12: 3 | H12: 4 | I12: 5 | J12: 5 | K12: 17 | L12: 0.895 | M12: 70 | N12: 67.04 | O12: AC1, AC9 | P12: AC1, AC9 | Q12: 1 | R12: 1 | S12: 1 | W12: Socraticidad 3/5 (Clarificación): Pregunta genérica: pide clarificación sin atacar la raíz del error. Precisión Conceptual 4/5 (Bueno): Bueno: identifica claramente la concepción alternativa con lenguaje técnico preciso. Tutor de alto rendimiento: guía socrática experta con diagnóstico preciso.
A13: 54 | B13: 18 | C13: 3 | D13: 1 | E13: R1, R2, R4 y R5 dado que R3 está en circuito abierto | F13: ¿Consideró cómo el estado del interruptor entre N1/N2 y N3 afecta los caminos para R4, R5? Y ¿cómo influiría un circuito abierto de R3 en el voltaje total ante N2 comparado con una configuración donde R3 no estuviera cerrado?, considerando la presencia simultánea de R1, R2 (en paralelo) y R4/R5?. | G13: 1 | H13: 4 | I13: 4 | J13: 5 | K13: 14 | L13: 0.839 | M13: 82 | N13: 71.55 | O13: AC1, AC6 | P13: AC1, AC9 | Q13: 0.5 | R13: 0.5 | S13: 0.5 | W13: Socraticidad 1/5 (Instructivo): No termina en pregunta; el tutor es instructivo. Precisión Conceptual 4/5 (Bueno): Bueno: identifica claramente la concepción alternativa con lenguaje técnico preciso. Buen desempeño general; hay margen de mejora en profundidad socrática.
... A15: 56 | B15: 19 | C15: 2 | D15: 1 | E15: R1, R2, R4 y R5 dado que R3 no hace nada | F15: ¿El papel de R3 en el circuito es puramente pasivo, o está diseñado para evitar un cortocircuito potencial entre V1 y N2? ¿Cómo sugiere esto sobre la conexión u omisión del R3 dentro del diseño general del circuito?. | G15: 1 | H15: 2 | I15: 3 | J15: 5 | K15: 11 | L15: 0.689 | M15: 56 | N15: 87.03 | O15: AC1, AC6 | P15: AC1, AC6, AC9 | Q15: 0.667 | R15: 1 | S15: 0.8 | W15: Socraticidad 1/5 (Instructivo): No termina en pregunta; el tutor es instructivo. Precisión Conceptual 2/5 (Pobre): Pobre: responde de forma genérica sin diagnosticar el error conceptual. Desempeño aceptable; necesita mejorar precisión o metodología socrática.
A16: 57 | B16: 19 | C16: 3 | D16: 1 | E16: R1, R2 y R4 dado que son las resistencias que forman parte del circuito. | F16: ¿Podemos confirmar si los voltajes a través de R1, R2 y R4 son iguales o diferentes debido a sus posiciones distintas con respecto entre sí? ¿Y cómo estas variaciones podrían afectar el flujo total de corriente según Kirchhoff's Left-Hand Rule?. | G16: 1 | H16: 3 | I16: 5 | J16: 5 | K16: 14 | L16: 0.658 | M16: 55 | N16: 91.12 | P16: AC1 | Q16: 0 | R16: 1 | S16: 0 | W16: Socraticidad 1/5 (Instructivo): No termina en pregunta; el tutor es instructivo. Precisión Conceptual 3/5 (Suficiente): Suficiente: identifica que hay un error y usa conceptos correctos, pero el diagnóstico es algo vago. Buen desempeño general; hay margen de mejora en profundidad socrática.
A17: 58 | B17: 20 | C17: 1 | D17: 1 | E17: R1, R2 y R4 dado que R2 y R4 están en paralelo y forma un divisor de tensión con R1. | F17: ¿Puedes identificar qué sucede con el flujo de corriente a través de los componentes paralelos cuando hay dos terminales conectados directamente, como es el caso del R5 en este circuito? ¿Y cómo afecta esto a las resistencias restantes (R1, R2 y R4) que están configuradas para determinar la diferencia de potencial entre N2 y 0? | G17: 3 | H17: 5 | I17: 5 | J17: 5 | K17: 18 | L17: 1.333 | M17: 75 | N17: 45.03 | P17: AC1, AC6, AC9 | Q17: 0 | R17: 1 | S17: 0 | W17: Socraticidad 3/5 (Clarificación): Pregunta genérica: pide clarificación sin atacar la raíz del error. Precisión Conceptual 5/5 (Excelente): Excelente: identifica la concepción alternativa específica y la conecta con la topología del circuito. Tutor de alto rendimiento: guía socrática experta con diagnóstico preciso.
A18: 59 | B18: 20 | C18: 2 | D18: 1 | E18: R1, R2 y R4 dado que R3 está en abierto y R5 cortocircuitada | F18: ¿Considerando el estado de un divisor paralelo con dos terminales directamente conectados, cómo se comparan las contribuciones individuales del flujo de corriente a través de R1 y R4 versus R2? Y qué efecto esto tiene sobre los voltajes experimentados por cada una de estas resistencias (R1, R2, R4) en el contexto de su papel como determinantes para la diferencia potencial entre N2 y 0? | G18: 3 | H18: 3 | I18: 3 | J18: 5 | K18: 14 | L18: 1.005 | M18: 90 | N18: 59.71 | O18: AC1, AC6 | P18: AC1, AC6, AC9 | Q18: 0.667 | R18: 1 | S18: 0.8 | W18: Socraticidad 3/5 (Clarificación): Pregunta genérica: pide clarificación sin atacar la raíz del error. Precisión Conceptual 3/5 (Suficiente): Suficiente: identifica que hay un error y usa conceptos correctos, pero el diagnóstico es algo vago. Buen desempeño general; hay margen de mejora en profundidad socrática.
A19: 60 | B19: 20 | C19: 3 | D19: 1 | E19: R1, R2 y R4 dado que solo por estas resistencias circula una corriente diferente de cero | F19: Si se considera el estado del divisor paralelo con los dos terminales directamente conectados, ¿cómo podría afectar esto a la corriente individual y flujo total de las resistencias R1, R2 y R4 dentro del circuito? Y cuál es la implicación probable para sus funciones como determinantes de potencial entre N2 y 0? | G19: 3 | H19: 5 | I19: 5 | J19: 5 | K19: 18 | L19: 0.947 | M19: 68 | N19: 63.39 | P19: AC1, AC6, AC9 | Q19: 0 | R19: 1 | S19: 0 | W19: Socraticidad 3/5 (Clarificación): Pregunta genérica: pide clarificación sin atacar la raíz del error. Precisión Conceptual 5/5 (Excelente): Excelente: identifica la concepción alternativa específica y la conecta con la topología del circuito. Tutor de alto rendimiento: guía socrática experta con diagnóstico preciso.
A20: 61 | B20: 21 | C20: 1 | D20: 1 | E20: R1, R2 y R4 dado que por R3 y por R5 no circula corriente | F20: ¿Puedes confirmar si el flujo de corriente atraviesa las resistencias R3 y R5, o existen condiciones particulares en otras partes del circuito que impidan su participación en la diferencia de potencial entre N2 y 0? | G20: 3 | H20: 3 | I20: 3 | J20: 5 | K20: 14 | L20: 0.898 | M20: 46 | N20: 66.8 | O20: AC1, AC6 | P20: AC1, AC9 | Q20: 0.5 | R20: 0.5 | S20: 0.5 | W20: Socraticidad 3/5 (Clarificación): Pregunta genérica: pide clarificación sin atacar la raíz del error. Precisión Conceptual 3/5 (Suficiente): Suficiente: identifica que hay un error y usa conceptos correctos, pero el diagnóstico es algo vago. Buen desempeño general; hay margen de mejora en profundidad socrática.
A21: 62 | B21: 21 | C21: 2 | D21: 1 | E21: R1, R2 y R4 dado que R3 y R5 se pueden quitar | F21: ¿El circuito está configurado de tal manera que omitir las conexiones de R3 y R5 resulte en un flujo paralelo o serie exclusivo para R1, R2 y R4, impidiendo así el camino del corriente a través de R3 y R5? | G21: 3 | H21: 3 | I21: 5 | J21: 5 | K21: 16 | L21: 0.677 | M21: 55 | N21: 88.56 | O21: AC1, AC6 | P21: AC1, AC9 | Q21: 0.5 | R21: 0.5 | S21: 0.5 | W21: Socraticidad 3/5 (Clarificación): Pregunta genérica: pide clarificación sin atacar la raíz del error. Precisión Conceptual 3/5 (Suficiente): Suficiente: identifica que hay un error y usa conceptos correctos, pero el diagnóstico es algo vago. Buen desempeño general; hay margen de mejora en profundidad socrática.
A22: 63 | B22: 21 | C22: 3 | D22: 1 | E22: R1, R2 y R4 dado que R3 y R5 no influyen para nada en la diferencia de potencial que se pide | F22: ¿El circuito está configurado solo con series o paralelos entre R1, R2 y R4, excluyendo efectivamente las contribuciones de R3 y R5 a la diferencia de potencial requerida? | G22: 3 | H22: 3 | I22: 5 | J22: 5 | K22: 16 | L22: 0.656 | M22: 43 | N22: 91.52 | O22: AC1, AC6 | P22: AC9 | Q22: 0 | R22: 0 | S22: 0 | W22: Socraticidad 3/5 (Clarificación): Pregunta genérica: pide clarificación sin atacar la raíz del error. Precisión Conceptual 3/5 (Suficiente): Suficiente: identifica que hay un error y usa conceptos correctos, pero el diagnóstico es algo vago. Buen desempeño general; hay margen de mejora en profundidad socrática.
A23: 64 | B23: 22 | C23: 1 | D23: 1 | E23: R1, R2 y R4 dado que R3 y R5 sobran | F23: ¿Puedes verificar qué sucede con el flujo de corriente a través de los interruptores abiertos, y cómo afecta eso a las resistencias R3 y R5? ¿Qué pasa con la contribución individual de cada resistencia desde N2 hasta tierra? | G23: 4 | H23: 4 | I23: 3 | J23: 5 | K23: 16 | L23: 0.804 | M23: 50 | N23: 74.64 | O23: AC1, AC6 | P23: AC1, AC9 | Q23: 0.5 | R23: 0.5 | S23: 0.5 | W23: Socraticidad 4/5 (Andamiaje para detección): Andamiaje para detección: identifica el área del error y plantea pregunta que confronta con la teoría. Precisión Conceptual 4/5 (Bueno): Bueno: identifica claramente la concepción alternativa con lenguaje técnico preciso. Buen desempeño general; hay margen de mejora en profundidad socrática.
A24: 65 | B24: 22 | C24: 2 | D24: 1 | E24: R1, R2 y R4 dado que R3 sobra | F24: ¿Puedes deducir qué ocurre con el camino de corriente debido a los interruptores abiertos, y cómo influye esto en las variaciones del voltaje detectado entre N1-N3 y tierra? ¿Cómo se relacionan estas variables con la presencia o ausencia de R4 en el circuito?. | G24: 1 | H24: 4 | I24: 3 | J24: 5 | K24: 13 | L24: 0.958 | M24: 61 | N24: 62.64 | O24: AC1 | P24: AC1, AC9 | Q24: 0.5 | R24: 1 | S24: 0.667 | W24: Socraticidad 1/5 (Instructivo): No termina en pregunta; el tutor es instructivo. Precisión Conceptual 4/5 (Bueno): Bueno: identifica claramente la concepción alternativa con lenguaje técnico preciso. Buen desempeño general; hay margen de mejora en profundidad socrática.
A25: 66 | B25: 22 | C25: 3 | D25: 1 | E25: R1, R2 y R4 dado que R5 sobra | F25: ¿Puedes evaluar el papel de los interruptores abiertos con respecto a las variaciones del voltaje detectado entre N1-N3 y tierra, considerando la presencia o ausencia de R5? ¿Cómo influye esto en la contribución individual para R4 dentro del circuito?. | G25: 1 | H25: 3 | I25: 3 | J25: 5 | K25: 12 | L25: 0.689 | M25: 56 | N25: 87.13 | O25: AC6 | P25: AC1, AC9 | Q25: 0 | R25: 0 | S25: 0 | W25: Socraticidad 1/5 (Instructivo): No termina en pregunta; el tutor es instructivo. Precisión Conceptual 3/5 (Suficiente): Suficiente: identifica que hay un error y usa conceptos correctos, pero el diagnóstico es algo vago. Desempeño aceptable; necesita mejorar precisión o metodología socrática.
A26: 67 | B26: 23 | C26: 1 | D26: 1 | E26: R1, R2 y R4 dado que R3 está en abierto | F26: ¿Puede confirmar si el estado del interruptor entre N2 y N3 impide corriente de pasar, potencialmente afectando qué componentes contribuyen a la diferencia de potencial? | G26: 3 | H26: 4 | I26: 3 | J26: 5 | K26: 15 | L26: 0.617 | M26: 36 | N26: 97.21 | O26: AC1 | P26: AC1 | Q26: 1 | R26: 1 | S26: 1 | W26: Socraticidad 3/5 (Clarificación): Pregunta genérica: pide clarificación sin atacar la raíz del error. Precisión Conceptual 4/5 (Bueno): Bueno: identifica claramente la concepción alternativa con lenguaje técnico preciso. Buen desempeño general; hay margen de mejora en profundidad socrática.
A27: 68 | B27: 23 | C27: 2 | D27: 1 | E27: R1, R2 y R4 dado que R5 cortocircuitada | F27: ¿Podría el estado de R5 como un cortocircuito estar influyendo en su cálculo, haciendo que otros componentes (R1, R2 o R4) contribuyan a una diferencia de potencial diferente del esperado? | G27: 3 | H27: 3 | I27: 4 | J27: 5 | K27: 15 | L27: 0.698 | M27: 47 | N27: 85.92 | O27: AC6 | P27: AC6 | Q27: 1 | R27: 1 | S27: 1 | W27: Socraticidad 3/5 (Clarificación): Pregunta genérica: pide clarificación sin atacar la raíz del error. Precisión Conceptual 3/5 (Suficiente): Suficiente: identifica que hay un error y usa conceptos correctos, pero el diagnóstico es algo vago. Buen desempeño general; hay margen de mejora en profundidad socrática.
A28: 69 | B28: 23 | C28: 3 | D28: 1 | E28: R1, R2 y R4 dado que por R3 no circula corriente | F28: ¿El estado abierto de R3 sugiere una ausencia total de resistencia, o hay otros factores a considerar para determinar el flujo de corriente a través de los componentes R1, R2 y R4? | G28: 3 | H28: 3 | I28: 5 | J28: 5 | K28: 16 | L28: 0.713 | M28: 43 | N28: 84.11 | O28: AC1 | P28: AC1 | Q28: 1 | R28: 1 | S28: 1 | W28: Socraticidad 3/5 (Clarificación): Pregunta genérica: pide clarificación sin atacar la raíz del error. Precisión Conceptual 3/5 (Suficiente): Suficiente: identifica que hay un error y usa conceptos correctos, pero el diagnóstico es algo vago. Buen desempeño general; hay margen de mejora en profundidad socrática.
A29: 70 | B29: 24 | C29: 1 | D29: 1 | E29: R1, R2 y R4 dado que por R5 no circula corriente | F29: ¿Puedes explicar qué sucede con el flujo de corriente a través de R3, considerando la posición del interruptor entre N2 y N3? | G29: 3 | H29: 3 | I29: 3 | J29: 5 | K29: 14 | L29: 0.672 | M29: 30 | N29: 89.34 | O29: AC6 | P29: AC1 | Q29: 0 | R29: 0 | S29: 0 | W29: Socraticidad 3/5 (Clarificación): Clarificación: pide que el alumno explique su razonamiento. Precisión Conceptual 3/5 (Suficiente): Suficiente: identifica que hay un error y usa conceptos correctos, pero el diagnóstico es algo vago. Buen desempeño general; hay margen de mejora en profundidad socrática.
A30: 71 | B30: 24 | C30: 2 | D30: 1 | E30: R1, R2 y R4 dado que R3 se puede quitar | F30: Si el flujo de corriente a través de R5 es cero, ¿cuál sería entonces el estado del circuito si R3 se desconecta? Estaría N1 y R4 aún recibiendo corriente o hay otro escenario posible? | G30: 3 | H30: 2 | I30: 4 | J30: 5 | K30: 14 | L30: 0.8 | M30: 48 | N30: 74.99 | O30: AC1 | P30: AC1 | Q30: 1 | R30: 1 | S30: 1 | W30: Socraticidad 3/5 (Clarificación): Pregunta genérica: pide clarificación sin atacar la raíz del error. Precisión Conceptual 2/5 (Pobre): Pobre: responde de forma genérica sin diagnosticar el error conceptual. Buen desempeño general; hay margen de mejora en profundidad socrática.
A31: 72 | B31: 24 | C31: 3 | D31: 1 | E31: R1, R2 y R4 dado que R5 se puede quitar | F31: Si el flujo de corriente a través de R5 es eliminado eliminando R3, ¿podría aún haber un camino para el flujo de corriente pasando por R1, R2 y R4? Estaría considerando si los interruptores N1, N2 y N3 están configurados correctamente? | G31: 3 | H31: 3 | I31: 4 | J31: 5 | K31: 15 | L31: 0.73 | M31: 61 | N31: 82.22 | O31: AC6 | P31: AC1, AC9 | Q31: 0 | R31: 0 | S31: 0 | W31: Socraticidad 3/5 (Clarificación): Pregunta genérica: pide clarificación sin atacar la raíz del error. Precisión Conceptual 3/5 (Suficiente): Suficiente: identifica que hay un error y usa conceptos correctos, pero el diagnóstico es algo vago. Buen desempeño general; hay margen de mejora en profundidad socrática.
... A36: 77 | B36: 26 | C36: 2 | D36: 1 | E36: R1 y R2 | F36: ¿La presencia simultánea del interruptor N1 con R1, ¿afecta fundamentalmente el flujo de corriente a través de R2 y alteraría su contribución al circuito? Y, ¿hay un componente cuya ausencia impediría efectivamente que R3 participe plenamente en la ruta del voltaje? | G36: 3 | H36: 3 | I36: 2 | J36: 5 | K36: 13 | L36: 1.128 | M36: 62 | N36: 53.21 | O36: AC9 | P36: AC1 | Q36: 0 | R36: 0 | S36: 0 | W36: Socraticidad 3/5 (Clarificación): Pregunta genérica: pide clarificación sin atacar la raíz del error. Precisión Conceptual 3/5 (Suficiente): Suficiente: identifica que hay un error y usa conceptos correctos, pero el diagnóstico es algo vago. Buen desempeño general; hay margen de mejora en profundidad socrática.
A37: 78 | B37: 26 | C37: 3 | D37: 1 | E37: R1, R2 y R4 | F37: ¿Al considerar los caminos abiertos de flujo a través de R1, R2 y el camino paralelo con R3, ¿podría suponerse erróneamente que R4 también está participando activamente en el circuito? Y, ¿hay algún componente cuya inclusión podría sugerir erroneamente la presencia del cortocircuito entre R2 y R3? | G37: 3 | H37: 4 | I37: 2 | J37: 5 | K37: 14 | L37: 1.043 | M37: 75 | N37: 57.53 | P37: AC1, AC6, AC9 | Q37: 0 | R37: 1 | S37: 0 | W37: Socraticidad 3/5 (Clarificación): Pregunta genérica: pide clarificación sin atacar la raíz del error. Precisión Conceptual 4/5 (Bueno): Bueno: identifica claramente la concepción alternativa con lenguaje técnico preciso. Buen desempeño general; hay margen de mejora en profundidad socrática.
A38: 79 | B38: 27 | C38: 1 | D38: 1 | E38: R1, R2, R4 y R5 | F38: ¿Considera el estado del interruptor entre N2 y N3 cuando determina qué resistencias contribuyen a la diferencia de potencial? ¿Y cuál es el impacto de un circuito abierto o cortocircuito sobre las corrientes que fluye por cada resistencia? | G38: 3 | H38: 4 | I38: 2 | J38: 5 | K38: 14 | L38: 0.9 | M38: 54 | N38: 66.68 | O38: AC6 | P38: AC1, AC6, AC9 | Q38: 0.333 | R38: 1 | S38: 0.5 | W38: Socraticidad 3/5 (Clarificación): Pregunta genérica: pide clarificación sin atacar la raíz del error. Precisión Conceptual 4/5 (Bueno): Bueno: identifica claramente la concepción alternativa con lenguaje técnico preciso. Buen desempeño general; hay margen de mejora en profundidad socrática.
A39: 80 | B39: 27 | C39: 2 | D39: 1 | E39: R1, R2, R3 y R4 | F39: ¿El estado de los interruptores afecta el camino del flujo eléctrico para las corrientes i1, i2 e i3? Y cómo influiría un cortocircuito entre N4 y N5 sobre las contribuciones individuales de R1, R2, R3, R4 y R5 al circuito en términos de corriente o voltaje? | G39: 3 | H39: 5 | I39: 2 | J39: 5 | K39: 15 | L39: 0.873 | M39: 73 | N39: 68.69 | O39: AC1 | P39: AC1, AC6, AC9 | Q39: 0.333 | R39: 1 | S39: 0.5 | W39: Socraticidad 3/5 (Clarificación): Pregunta genérica: pide clarificación sin atacar la raíz del error. Precisión Conceptual 5/5 (Excelente): Excelente: identifica la concepción alternativa específica y la conecta con la topología del circuito. Buen desempeño general; hay margen de mejora en profundidad socrática.
A40: 81 | B40: 27 | C40: 3 | D40: 1 | E40: R1 y R2 y R4 hacen un divisor de corriente | F40: ¿Cuáles son las implicaciones para el voltaje terminal de cada resistencia cuando los interruptores entre N1-N3 y N4-N5 se abren, permitiendo solo R1, R2, R3 o R4, R5 a funcionar? (Nota: Considere cómo la presencia potencial de un cortocircuito podría alterar esta configuración.) | G40: 1 | H40: 4 | I40: 4 | J40: 5 | K40: 14 | L40: 1.062 | M40: 75 | N40: 56.48 | P40: AC1, AC6, AC9 | Q40: 0 | R40: 1 | S40: 0 | W40: Socraticidad 1/5 (Instructivo): No termina en pregunta; el tutor es instructivo. Precisión Conceptual 4/5 (Bueno): Bueno: identifica claramente la concepción alternativa con lenguaje técnico preciso. Buen desempeño general; hay margen de mejora en profundidad socrática.
A41: 82 | B41: 28 | C41: 1 | D41: 1 | E41: R1 y R2 y R4 hacen un divisor de tensión, r3 no cuenta por estar en corto | F41: ¿Puedes verificar si cada resistencia contribuye directamente a la diferencia de potencial entre N2 y el punto tierra, considerando las interacciones con otros componentes del circuito? ¿Y cómo afectan los estados del interruptor abierto respecto al flujo de corriente por R3 y R5? | G41: 3 | H41: 4 | I41: 3 | J41: 5 | K41: 15 | L41: 1.047 | M41: 55 | N41: 57.3 | O41: AC1 | P41: AC1, AC9 | Q41: 0.5 | R41: 1 | S41: 0.667 | W41: Socraticidad 3/5 (Clarificación): Pregunta genérica: pide clarificación sin atacar la raíz del error. Precisión Conceptual 4/5 (Bueno): Bueno: identifica claramente la concepción alternativa con lenguaje técnico preciso. Buen desempeño general; hay margen de mejora en profundidad socrática.
A42: 83 | B42: 28 | C42: 2 | D42: 1 | E42: No tengo en cuenta R3 porque el interruptor está cerrado | F42: ¿Consideraste cómo se altera el camino del corriente debido a los cambios de estado entre tus interruptores y cuál sería el impacto sobre las contribuciones potenciales de R3 y R5, incluso cuando uno está cerrado? | G42: 3 | H42: 4 | I42: 5 | J42: 5 | K42: 17 | L42: 0.896 | M42: 45 | N42: 66.98 | O42: AC1, AC9 | P42: AC1, AC9 | Q42: 1 | R42: 1 | S42: 1 | W42: Socraticidad 3/5 (Clarificación): Pregunta genérica: pide clarificación sin atacar la raíz del error. Precisión Conceptual 4/5 (Bueno): Bueno: identifica claramente la concepción alternativa con lenguaje técnico preciso. Tutor de alto rendimiento: guía socrática experta con diagnóstico preciso.
A43: 84 | B43: 28 | C43: 3 | D43: 1 | E43: No tengo en cuenta R5 porque está en circuito abierto | F43: ¿Has verificado cómo el estado del interruptor de R5 afecta su papel en el circuito y si, bajo las condiciones actuales, aún podría influir sobre alguna parte del circuito oponente? ¿Y deberías considerar cualquier posible influencia indirecta que pueda tener debido a la configuración global del circuito? | G43: 3 | H43: 2 | I43: 3 | J43: 5 | K43: 13 | L43: 0.945 | M43: 61 | N43: 63.49 | O43: AC6, AC9 | P43: AC1, AC9 | Q43: 0.5 | R43: 0.5 | S43: 0.5 | W43: Socraticidad 3/5 (Clarificación): Pregunta genérica: pide clarificación sin atacar la raíz del error. Precisión Conceptual 2/5 (Pobre): Pobre: responde de forma genérica sin diagnosticar el error conceptual. Buen desempeño general; hay margen de mejora en profundidad socrática.

Sheet Metadata
A1: Campo | B1: Valor
A2: Fecha generación | B2: 2026-05-20T16:43:06.647154
A3: Método | B3: RAG
A4: Modelos evaluados | B4: llama, phi4
A5: Ejercicios cubiertos | B5: 1
A6: Total evaluaciones | B6: 84
A7: UPV Ollama URL | B7: https://ollama.gti-ia.upv.es:443
A8: PoliGPT URL | B8: https://api.poligpt.upv.es

Sheet Ranking
A1: Ranking | B1: Modelo | C1: muestras | D1: latencia_media | E1: latencia_p95 | F1: throughput | G1: tokens_medio | H1: formato_socratico | I1: correccion_conceptual | J1: adaptabilidad | K1: generacion_reflexion | L1: score_total | M1: pct_socratico | N1: pct_score_15 | O1: faithfulness | P1: relevance | Q1: pct_cot
A2: 1 | B2: llama | C2: =COUNTA('Resultados_llama'!A2:A10000) | D2: =IFERROR(AVERAGE('Resultados_llama'!L2:L10000),"") | E2: =IFERROR(PERCENTILE('Resultados_llama'!L2:L10000,0.95),"") | F2: =IFERROR(IF(AVERAGE('Resultados_llama'!L2:L10000)>0,60/AVERAGE('Resultados_llama'!L2:L10000),0),"") | G2: =IFERROR(AVERAGE('Resultados_llama'!M2:M10000),"") | H2: =IFERROR(AVERAGE('Resultados_llama'!G2:G10000),"") | I2: =IFERROR(AVERAGE('Resultados_llama'!H2:H10000),"") | J2: =IFERROR(AVERAGE('Resultados_llama'!I2:I10000),"") | K2: =IFERROR(AVERAGE('Resultados_llama'!J2:J10000),"") | L2: =IFERROR(AVERAGE('Resultados_llama'!K2:K10000),"") | M2: =IFERROR(COUNTIF('Resultados_llama'!G2:G10000,">=4")/COUNTA('Resultados_llama'!G2:G10000)*100,"") | N2: =IFERROR(COUNTIF('Resultados_llama'!K2:K10000,">=15")/COUNTA('Resultados_llama'!K2:K10000)*100,"") | O2: =IFERROR(AVERAGE('Resultados_llama'!T2:T10000),"") | P2: =IFERROR(AVERAGE('Resultados_llama'!U2:U10000),"") | Q2: =IFERROR(COUNTIF('Resultados_llama'!V2:V10000,"<>")/COUNTA('Resultados_llama'!A2:A10000)*100,"")
