Workbook

Sheet Resultados_Tutor_EDA
A1: ID | B1: Conversación | C1: Turno | D1: Ejercicio | E1: Respuesta Estudiante | F1: Respuesta Tutor Socrático | G1: Socraticidad | H1: Precisión Conceptual | I1: Consistencia | J1: Tasa Alucinación | K1: Score Total | L1: Latencia (s) | M1: Tokens | N1: Throughput (resp/min) | O1: ACs Esperadas | P1: ACs Detectadas | Q1: AC Precision | R1: AC Recall | S1: AC F1 | T1: Faithfulness | U1: Relevance | V1: Think Content | W1: Feedback Constructivo
A2: 41 | B2: 17 | C2: 1 | D2: 1 | E2: R1 y R2 dado que las dos resistencia forman un divisor de tensión | F2: ¿Todas las resistencias entre N2 y 0 contribuyen a la diferencia de potencial? | G2: 3 | H2: 3 | I2: 3 | J2: 5 | K2: 14 | L2: 0.765 | M2: 23 | N2: 78.39 | O2: AC9 | P2: AC9 | Q2: 1 | R2: 1 | S2: 1 | W2: Socraticidad 3/5 (Clarificación): Pregunta genérica: pide clarificación sin atacar la raíz del error. Precisión Conceptual 3/5 (Suficiente): Suficiente: identifica que hay un error y usa conceptos correctos, pero el diagnóstico es algo vago. Buen desempeño general; hay margen de mejora en profundidad socrática.
A3: 42 | B3: 17 | C3: 2 | D3: 1 | E3: R1 y R2 dado que se pide la tensión en R2 | F3: ¿Cómo se calcula la tensión en R2 si R1 y R2 están en serie? | G3: 3 | H3: 3 | I3: 5 | J3: 5 | K3: 16 | L3: 0.624 | M3: 22 | N3: 96.15 | O3: AC9 | Q3: 1 | R3: 0 | S3: 0 | W3: Socraticidad 3/5 (Clarificación): Pregunta genérica: pide clarificación sin atacar la raíz del error. Precisión Conceptual 3/5 (Suficiente): Suficiente: identifica que hay un error y usa conceptos correctos, pero el diagnóstico es algo vago. Buen desempeño general; hay margen de mejora en profundidad socrática.
A4: 43 | B4: 17 | C4: 3 | D4: 1 | E4: R1 y R2 por identificar un divisor de tensión | F4: ¿Cómo se calcula la tensión en R2 si R1 y R2 están en serie? | G4: 3 | H4: 3 | I4: 5 | J4: 5 | K4: 16 | L4: 0.694 | M4: 22 | N4: 86.42 | O4: AC9 | Q4: 1 | R4: 0 | S4: 0 | W4: Socraticidad 3/5 (Clarificación): Pregunta genérica: pide clarificación sin atacar la raíz del error. Precisión Conceptual 3/5 (Suficiente): Suficiente: identifica que hay un error y usa conceptos correctos, pero el diagnóstico es algo vago. Buen desempeño general; hay margen de mejora en profundidad socrática.
A5: 44 | B5: 18 | C5: 1 | D5: 1 | E5: R1 y R2 hacen un divisor de tensión | F5: ¿Y qué ocurre con la corriente en una rama interrumpida? | G5: 3 | H5: 2 | I5: 3 | J5: 5 | K5: 13 | L5: 0.579 | M5: 20 | N5: 103.59 | O5: AC9 | P5: AC1 | Q5: 0 | R5: 0 | S5: 0 | W5: Socraticidad 3/5 (Clarificación): Pregunta genérica: pide clarificación sin atacar la raíz del error. Precisión Conceptual 2/5 (Pobre): Pobre: responde de forma genérica sin diagnosticar el error conceptual. Buen desempeño general; hay margen de mejora en profundidad socrática.
A6: 45 | B6: 18 | C6: 2 | D6: 1 | E6: R1, R2, R3 y R4 porque R5 está cortocircuitada | F6: ¿Qué ocurre cuando un componente se coloca en paralelo con otro? | G6: 4 | H6: 2 | I6: 3 | J6: 5 | K6: 14 | L6: 0.539 | M6: 18 | N6: 111.41 | O6: AC1, AC6 | Q6: 1 | R6: 0 | S6: 0 | W6: Socraticidad 4/5 (Andamiaje para detección): Andamiaje para detección: identifica el área del error y plantea pregunta que confronta con la teoría. Precisión Conceptual 2/5 (Pobre): Pobre: responde de forma genérica sin diagnosticar el error conceptual. Buen desempeño general; hay margen de mejora en profundidad socrática.
A7: 46 | B7: 18 | C7: 3 | D7: 1 | E7: R1, R2, R3 y R4 porque por R5 no circula corriente | F7: ¿Y si R5 no estuviera en el circuito? | G7: 3 | H7: 2 | I7: 3 | J7: 5 | K7: 13 | L7: 0.464 | M7: 15 | N7: 129.41 | O7: AC1, AC6 | Q7: 1 | R7: 0 | S7: 0 | W7: Socraticidad 3/5 (Clarificación): Pregunta genérica: pide clarificación sin atacar la raíz del error. Precisión Conceptual 2/5 (Pobre): Respuesta genérica: sin vocabulario técnico ni diagnóstico del error. Buen desempeño general; hay margen de mejora en profundidad socrática.
A8: 47 | B8: 19 | C8: 1 | D8: 1 | E8: R1, R2, R3 y R4 porque R5 se quita | F8: ¿Qué tienen en común los dos terminales de R5 mirando el netlist? | G8: 3 | H8: 2 | I8: 3 | J8: 5 | K8: 13 | L8: 0.526 | M8: 19 | N8: 114.07 | O8: AC1, AC6 | P8: AC6 | Q8: 1 | R8: 0.5 | S8: 0.667 | W8: Socraticidad 3/5 (Clarificación): Pregunta genérica: pide clarificación sin atacar la raíz del error. Precisión Conceptual 2/5 (Pobre): Pobre: responde de forma genérica sin diagnosticar el error conceptual. Buen desempeño general; hay margen de mejora en profundidad socrática.
A9: 48 | B9: 19 | C9: 2 | D9: 1 | E9: R1, R3 y R4 porque R2 está en paralelo con la fuente y R5 corctocircuitada | F9: ¿Cómo afecta a la resistencia total de una red el cortocircuito de una rama? | G9: 4 | H9: 3 | I9: 3 | J9: 5 | K9: 15 | L9: 0.613 | M9: 23 | N9: 97.95 | O9: AC1, AC6 | P9: AC6 | Q9: 1 | R9: 0.5 | S9: 0.667 | W9: Socraticidad 4/5 (Andamiaje para detección): Andamiaje para detección: identifica el área del error y plantea pregunta que confronta con la teoría. Precisión Conceptual 3/5 (Suficiente): Suficiente: identifica que hay un error y usa conceptos correctos, pero el diagnóstico es algo vago. Buen desempeño general; hay margen de mejora en profundidad socrática.
A10: 49 | B10: 19 | C10: 3 | D10: 1 | E10: R1, R4 y R5 porque R2 se elimina y R3 también | F10: ¿Qué tiene en común los dos terminales de R2 mirando el netlist? | G10: 3 | H10: 2 | I10: 3 | J10: 5 | K10: 13 | L10: 0.527 | M10: 19 | N10: 113.88 | O10: AC1, AC6 | P10: AC6 | Q10: 1 | R10: 0.5 | S10: 0.667 | W10: Socraticidad 3/5 (Clarificación): Pregunta genérica: pide clarificación sin atacar la raíz del error. Precisión Conceptual 2/5 (Pobre): Pobre: responde de forma genérica sin diagnosticar el error conceptual. Buen desempeño general; hay margen de mejora en profundidad socrática.
A11: 50 | B11: 20 | C11: 1 | D11: 1 | E11: R1 y R4 dado que R2 está en paralelo con la fuente, R3 en circuito abierto y R5 cortocircuitada | F11: ¿Qué ocurriría si se retirara el interruptor del circuito? | G11: 3 | H11: 2 | I11: 3 | J11: 5 | K11: 13 | L11: 0.512 | M11: 18 | N11: 117.27 | O11: AC1, AC6 | P11: AC1 | Q11: 1 | R11: 0.5 | S11: 0.667 | W11: Socraticidad 3/5 (Clarificación): Pregunta genérica: pide clarificación sin atacar la raíz del error. Precisión Conceptual 2/5 (Pobre): Pobre: responde de forma genérica sin diagnosticar el error conceptual. Buen desempeño general; hay margen de mejora en profundidad socrática.

Sheet Resultados_deepseek-r1_32b
A1: ID | B1: Conversación | C1: Turno | D1: Ejercicio | E1: Respuesta Estudiante | F1: Respuesta Tutor Socrático | G1: Socraticidad | H1: Precisión Conceptual | I1: Consistencia | J1: Tasa Alucinación | K1: Score Total | L1: Latencia (s) | M1: Tokens | N1: Throughput (resp/min) | O1: ACs Esperadas | P1: ACs Detectadas | Q1: AC Precision | R1: AC Recall | S1: AC F1 | T1: Faithfulness | U1: Relevance | V1: Think Content | W1: Feedback Constructivo
A2: 146 | B2: 58 | C2: 3 | D2: 1 | E2: R1, R2, R3 y R4 porque por R5 no circula corriente | F2: ¿Por qué crees que no circula corriente por R5? | G2: 4 | H2: 2 | I2: 3 | J2: 5 | K2: 14 | L2: 8.704 | M2: 289 | N2: 6.89 | O2: AC1, AC6 | P2: AC1 | Q2: 1 | R2: 0.5 | S2: 0.667 | W2: Socraticidad 4/5 (Andamiaje para detección): Andamiaje para detección: identifica el área del error y plantea pregunta que confronta con la teoría. Precisión Conceptual 2/5 (Pobre): Pobre: responde de forma genérica sin diagnosticar el error conceptual. Buen desempeño general; hay margen de mejora en profundidad socrática.
A3: 147 | B3: 59 | C3: 1 | D3: 1 | E3: R1, R2, R3 y R4 porque R5 se quita | F3: ¿Has considerado cómo afecta el estado del interruptor entre N2 y N3 a la corriente que circula por R3? | G3: 3 | H3: 3 | I3: 3 | J3: 5 | K3: 14 | L3: 8.439 | M3: 333 | N3: 7.11 | O3: AC1, AC6 | P3: AC1 | Q3: 1 | R3: 0.5 | S3: 0.667 | W3: Socraticidad 3/5 (Clarificación): Pregunta genérica: pide clarificación sin atacar la raíz del error. Precisión Conceptual 3/5 (Suficiente): Suficiente: identifica que hay un error y usa conceptos correctos, pero el diagnóstico es algo vago. Buen desempeño general; hay margen de mejora en profundidad socrática.
A4: 148 | B4: 59 | C4: 2 | D4: 1 | E4: R1, R3 y R4 porque R2 está en paralelo con la fuente y R5 corctocircuitada | F4: ¿Cómo afecta la disposición en paralelo de R2 con la fuente a su participación en el flujo total de corriente? | G4: 4 | H4: 3 | I4: 3 | J4: 5 | K4: 15 | L4: 7.3 | M4: 337 | N4: 8.22 | O4: AC1, AC6 | P4: AC1 | Q4: 1 | R4: 0.5 | S4: 0.667 | W4: Socraticidad 4/5 (Andamiaje para detección): Andamiaje para detección: identifica el área del error y plantea pregunta que confronta con la teoría. Precisión Conceptual 3/5 (Suficiente): Suficiente: identifica que hay un error y usa conceptos correctos, pero el diagnóstico es algo vago. Buen desempeño general; hay margen de mejora en profundidad socrática.
A5: 150 | B5: 60 | C5: 1 | D5: 1 | E5: R1 y R4 dado que R2 está en paralelo con la fuente, R3 en circuito abierto y R5 cortocircuitada | F5: ¿Has | G5: 1 | H5: 2 | I5: 2 | J5: 5 | K5: 10 | L5: 9.383 | M5: 400 | N5: 6.39 | O5: AC1, AC6 | Q5: 1 | R5: 0 | S5: 0 | W5: Socraticidad 1/5 (Instructivo): No termina en pregunta; el tutor es instructivo. Precisión Conceptual 2/5 (Pobre): Respuesta genérica: sin vocabulario técnico ni diagnóstico del error. Desempeño aceptable; necesita mejorar precisión o metodología socrática.

Sheet Resultados_deepseek-r1_7b
A1: ID | B1: Conversación | C1: Turno | D1: Ejercicio | E1: Respuesta Estudiante | F1: Respuesta Tutor Socrático | G1: Socraticidad | H1: Precisión Conceptual | I1: Consistencia | J1: Tasa Alucinación | K1: Score Total | L1: Latencia (s) | M1: Tokens | N1: Throughput (resp/min) | O1: ACs Esperadas | P1: ACs Detectadas | Q1: AC Precision | R1: AC Recall | S1: AC F1 | T1: Faithfulness | U1: Relevance | V1: Think Content | W1: Feedback Constructivo
A2: 101 | B2: 41 | C2: 1 | D2: 1 | E2: R1 y R2 dado que las dos resistencia forman un divisor de tensión | F2: ¿Cómo afecta el interruptor entre N2 y N3 al flujo de corriente? | G2: 4 | H2: 3 | I2: 3 | J2: 5 | K2: 15 | L2: 53.287 | M2: 201 | N2: 1.13 | O2: AC9 | P2: AC1 | Q2: 0 | R2: 0 | S2: 0 | W2: Socraticidad 4/5 (Andamiaje para detección): Andamiaje para detección: identifica el área del error y plantea pregunta que confronta con la teoría. Precisión Conceptual 3/5 (Suficiente): Suficiente: identifica que hay un error y usa conceptos correctos, pero el diagnóstico es algo vago. Buen desempeño general; hay margen de mejora en profundidad socrática.
A3: 102 | B3: 41 | C3: 2 | D3: 1 | E3: R1 y R2 dado que se pide la tensión en R2 | F3: ¿Cómo afecta la suma de R1 y R2 al cálculo de la tensión en R2? | G3: 4 | H3: 2 | I3: 5 | J3: 5 | K3: 16 | L3: 1.639 | M3: 189 | N3: 36.62 | O3: AC9 | Q3: 1 | R3: 0 | S3: 0 | W3: Socraticidad 4/5 (Andamiaje para detección): Andamiaje para detección: identifica el área del error y plantea pregunta que confronta con la teoría. Precisión Conceptual 2/5 (Pobre): Pobre: responde de forma genérica sin diagnosticar el error conceptual. Buen desempeño general; hay margen de mejora en profundidad socrática.
A4: 103 | B4: 41 | C4: 3 | D4: 1 | E4: R1 y R2 por identificar un divisor de tensión | F4: ¿Cómo afecta la relación entre R1 y R2 al cálculo de la tensión en R2? | G4: 4 | H4: 2 | I4: 5 | J4: 5 | K4: 16 | L4: 1.946 | M4: 262 | N4: 30.83 | O4: AC9 | Q4: 1 | R4: 0 | S4: 0 | W4: Socraticidad 4/5 (Andamiaje para detección): Andamiaje para detección: identifica el área del error y plantea pregunta que confronta con la teoría. Precisión Conceptual 2/5 (Pobre): Pobre: responde de forma genérica sin diagnosticar el error conceptual. Buen desempeño general; hay margen de mejora en profundidad socrática.
A5: 104 | B5: 42 | C5: 1 | D5: 1 | E5: R1 y R2 hacen un divisor de tensión | F5: ¿Cuáles son las resistorencias que forman el camino completo desde el nodo N2 hasta el nulo del circuito? | G5: 3 | H5: 3 | I5: 3 | J5: 5 | K5: 14 | L5: 1.894 | M5: 253 | N5: 31.68 | O5: AC9 | P5: AC9 | Q5: 1 | R5: 1 | S5: 1 | W5: Socraticidad 3/5 (Clarificación): Pregunta genérica: pide clarificación sin atacar la raíz del error. Precisión Conceptual 3/5 (Suficiente): Suficiente: identifica que hay un error y usa conceptos correctos, pero el diagnóstico es algo vago. Buen desempeño general; hay margen de mejora en profundidad socrática.
A6: 105 | B6: 42 | C6: 2 | D6: 1 | E6: R1, R2, R3 y R4 porque R5 está cortocircuitada | F6: ¿Cómo están conectados R1 y R2 con el resto del circuito? | G6: 3 | H6: 2 | I6: 3 | J6: 5 | K6: 13 | L6: 1.988 | M6: 285 | N6: 30.18 | O6: AC1, AC6 | Q6: 1 | R6: 0 | S6: 0 | W6: Socraticidad 3/5 (Clarificación): Pregunta genérica: pide clarificación sin atacar la raíz del error. Precisión Conceptual 2/5 (Pobre): Respuesta genérica: sin vocabulario técnico ni diagnóstico del error. Buen desempeño general; hay margen de mejora en profundidad socrática.
A7: 106 | B7: 42 | C7: 3 | D7: 1 | E7: R1, R2, R3 y R4 porque por R5 no circula corriente | F7: ¿Cómo contribuyen R1 y R2 al functions como divisor de tensión en el circuito? | G7: 3 | H7: 2 | I7: 3 | J7: 5 | K7: 13 | L7: 2.761 | M7: 290 | N7: 21.73 | O7: AC1, AC6 | Q7: 1 | R7: 0 | S7: 0 | W7: Socraticidad 3/5 (Clarificación): Pregunta genérica: pide clarificación sin atacar la raíz del error. Precisión Conceptual 2/5 (Pobre): Pobre: responde de forma genérica sin diagnosticar el error conceptual. Buen desempeño general; hay margen de mejora en profundidad socrática.
A8: 107 | B8: 43 | C8: 1 | D8: 1 | E8: R1, R2, R3 y R4 porque R5 se quita | F8: ¿Cuáles de las resistoridades (R1, R2, R3, R4, R5) forman una ruta continua desde el nodo N1 hasta el tierra sin interrupción o cortocircuitos? | G8: 3 | H8: 3 | I8: 5 | J8: 5 | K8: 16 | L8: 2.875 | M8: 231 | N8: 20.87 | O8: AC1, AC6 | P8: AC6, AC9 | Q8: 0.5 | R8: 0.5 | S8: 0.5 | W8: Socraticidad 3/5 (Clarificación): Pregunta genérica: pide clarificación sin atacar la raíz del error. Precisión Conceptual 3/5 (Suficiente): Suficiente: identifica que hay un error y usa conceptos correctos, pero el diagnóstico es algo vago. Buen desempeño general; hay margen de mejora en profundidad socrática.
A9: 109 | B9: 43 | C9: 3 | D9: 1 | E9: R1, R4 y R5 porque R2 se elimina y R3 también | F9: ¿Cómo affects la presencia de R5 en la rutacontinua del circuito? ¿Qué roles jueban los resistorios R2 y R3 en la conexión desde N1 al tierra? | G9: 3 | H9: 2 | I9: 4 | J9: 5 | K9: 14 | L9: 2.824 | M9: 237 | N9: 21.25 | O9: AC1, AC6 | P9: AC9 | Q9: 0 | R9: 0 | S9: 0 | W9: Socraticidad 3/5 (Clarificación): Pregunta genérica: pide clarificación sin atacar la raíz del error. Precisión Conceptual 2/5 (Pobre): Respuesta genérica: sin vocabulario técnico ni diagnóstico del error. Buen desempeño general; hay margen de mejora en profundidad socrática.

Sheet Resultados_gemma
A1: ID | B1: Conversación | C1: Turno | D1: Ejercicio | E1: Respuesta Estudiante | F1: Respuesta Tutor Socrático | G1: Socraticidad | H1: Precisión Conceptual | I1: Consistencia | J1: Tasa Alucinación | K1: Score Total | L1: Latencia (s) | M1: Tokens | N1: Throughput (resp/min) | O1: ACs Esperadas | P1: ACs Detectadas | Q1: AC Precision | R1: AC Recall | S1: AC F1 | T1: Faithfulness | U1: Relevance | V1: Think Content | W1: Feedback Constructivo
A2: 21 | B2: 9 | C2: 1 | D2: 1 | E2: R1 y R2 dado que las dos resistencia forman un divisor de tensión | F2: Considerando que el interruptor entre N2 y N3 está abierto, ¿cómo afecta la ausencia de un camino directo entre esos nodos al valor del potencial en N2 con respecto a tierra, y qué papel juegan las resistencias R1 y R2 en ese proceso, específicamente en relación con el potencial en N2? | G2: 4 | H2: 3 | I2: 4 | J2: 5 | K2: 16 | L2: 1.323 | M2: 65 | N2: 45.37 | O2: AC9 | P2: AC1, AC9 | Q2: 0.5 | R2: 1 | S2: 0.667 | W2: Socraticidad 4/5 (Andamiaje para detección): Andamiaje para detección: identifica el área del error y plantea pregunta que confronta con la teoría. Precisión Conceptual 3/5 (Suficiente): Suficiente: identifica que hay un error y usa conceptos correctos, pero el diagnóstico es algo vago. Buen desempeño general; hay margen de mejora en profundidad socrática.
A3: 22 | B3: 9 | C3: 2 | D3: 1 | E3: R1 y R2 dado que se pide la tensión en R2 | F3: Si la corriente fluye a través de R2, ¿cómo se relaciona la intensidad de esa corriente con la diferencia de potencial que estás intentando medir a través de ella, y qué influencia tiene la resistencia de R2 en esa relación, específicamente en relación con la tensión en R2? | G3: 3 | H3: 3 | I3: 4 | J3: 5 | K3: 15 | L3: 1.142 | M3: 59 | N3: 52.54 | O3: AC9 | P3: AC1 | Q3: 0 | R3: 0 | S3: 0 | W3: Socraticidad 3/5 (Clarificación): Pregunta genérica: pide clarificación sin atacar la raíz del error. Precisión Conceptual 3/5 (Suficiente): Suficiente: identifica que hay un error y usa conceptos correctos, pero el diagnóstico es algo vago. Buen desempeño general; hay margen de mejora en profundidad socrática.
A4: 23 | B4: 9 | C4: 3 | D4: 1 | E4: R1 y R2 por identificar un divisor de tensión | F4: Asumiendo que el circuito está en equilibrio, ¿cómo se relacionaría la carga que fluye a través de R2 con la caída de tensión en R2, considerando la configuración del divisor de tensión? | G4: 3 | H4: 2 | I4: 4 | J4: 5 | K4: 14 | L4: 0.994 | M4: 43 | N4: 60.33 | O4: AC9 | Q4: 1 | R4: 0 | S4: 0 | W4: Socraticidad 3/5 (Clarificación): Pregunta genérica: pide clarificación sin atacar la raíz del error. Precisión Conceptual 2/5 (Pobre): Pobre: responde de forma genérica sin diagnosticar el error conceptual. Buen desempeño general; hay margen de mejora en profundidad socrática.
A5: 24 | B5: 10 | C5: 1 | D5: 1 | E5: R1 y R2 hacen un divisor de tensión | F5: Considerando que el interruptor está abierto, ¿qué efecto tiene la ausencia de una conexión continua entre N2 y N3 en la distribución del potencial a través de las resistencias R1 y R2, respectivamente? | G5: 3 | H5: 3 | I5: 4 | J5: 5 | K5: 15 | L5: 0.947 | M5: 44 | N5: 63.36 | O5: AC9 | P5: AC1, AC9 | Q5: 0.5 | R5: 1 | S5: 0.667 | W5: Socraticidad 3/5 (Clarificación): Pregunta genérica: pide clarificación sin atacar la raíz del error. Precisión Conceptual 3/5 (Suficiente): Suficiente: identifica que hay un error y usa conceptos correctos, pero el diagnóstico es algo vago. Buen desempeño general; hay margen de mejora en profundidad socrática.
A6: 25 | B6: 10 | C6: 2 | D6: 1 | E6: R1, R2, R3 y R4 porque R5 está cortocircuitada | F6: Si el circuito está cortocircuitado, ¿qué implicaría la presencia de una caída de voltaje cero a través de R5, considerando el comportamiento de los componentes en un cortocircuito? | G6: 3 | H6: 3 | I6: 3 | J6: 5 | K6: 14 | L6: 0.797 | M6: 40 | N6: 75.29 | O6: AC1, AC6 | P6: AC6 | Q6: 1 | R6: 0.5 | S6: 0.667 | W6: Socraticidad 3/5 (Clarificación): Pregunta genérica: pide clarificación sin atacar la raíz del error. Precisión Conceptual 3/5 (Suficiente): Suficiente: identifica que hay un error y usa conceptos correctos, pero el diagnóstico es algo vago. Buen desempeño general; hay margen de mejora en profundidad socrática.
A7: 26 | B7: 10 | C7: 3 | D7: 1 | E7: R1, R2, R3 y R4 porque por R5 no circula corriente | F7: Si R5 está cortocircuitada, ¿cómo afectaría la distribución de la corriente a través de los otros componentes del circuito, considerando la ley de Ohm y la resistencia de cada rama? | G7: 3 | H7: 3 | I7: 3 | J7: 5 | K7: 14 | L7: 0.783 | M7: 40 | N7: 76.67 | O7: AC1, AC6 | P7: AC1 | Q7: 1 | R7: 0.5 | S7: 0.667 | W7: Socraticidad 3/5 (Clarificación): Pregunta genérica: pide clarificación sin atacar la raíz del error. Precisión Conceptual 3/5 (Suficiente): Suficiente: identifica que hay un error y usa conceptos correctos, pero el diagnóstico es algo vago. Buen desempeño general; hay margen de mejora en profundidad socrática.
A8: 27 | B8: 11 | C8: 1 | D8: 1 | E8: R1, R2, R3 y R4 porque R5 se quita | F8: Considerando que R3 está en un circuito abierto y R5 está cortocircuitado, ¿qué papel juegan las resistencias R1, R2 y R4 en la determinación de la diferencia de potencial entre N2 y 0? | G8: 3 | H8: 4 | I8: 4 | J8: 5 | K8: 16 | L8: 1.11 | M8: 49 | N8: 54.06 | O8: AC1, AC6 | P8: AC1, AC9 | Q8: 0.5 | R8: 0.5 | S8: 0.5 | W8: Socraticidad 3/5 (Clarificación): Pregunta genérica: pide clarificación sin atacar la raíz del error. Precisión Conceptual 4/5 (Bueno): Bueno: identifica claramente la concepción alternativa con lenguaje técnico preciso. Buen desempeño general; hay margen de mejora en profundidad socrática.
A9: 28 | B9: 11 | C9: 2 | D9: 1 | E9: R1, R3 y R4 porque R2 está en paralelo con la fuente y R5 corctocircuitada | F9: Si R2 realmente está en paralelo con la fuente, ¿cómo afectaría esa configuración a la corriente que fluye a través de R1 y R3, considerando que R3 está abierto? | G9: 3 | H9: 3 | I9: 4 | J9: 5 | K9: 15 | L9: 0.925 | M9: 40 | N9: 64.87 | O9: AC1, AC6 | P9: AC1 | Q9: 1 | R9: 0.5 | S9: 0.667 | W9: Socraticidad 3/5 (Clarificación): Pregunta genérica: pide clarificación sin atacar la raíz del error. Precisión Conceptual 3/5 (Suficiente): Suficiente: identifica que hay un error y usa conceptos correctos, pero el diagnóstico es algo vago. Buen desempeño general; hay margen de mejora en profundidad socrática.
A10: 29 | B10: 11 | C10: 3 | D10: 1 | E10: R1, R4 y R5 porque R2 se elimina y R3 también | F10: Dado que R2 está efectivamente eliminada y R3 también está en un estado de circuito abierto, ¿qué efecto tiene esta modificación en la distribución de la corriente a través de las resistencias R1 y R4? | G10: 3 | H10: 4 | I10: 5 | J10: 5 | K10: 17 | L10: 0.928 | M10: 44 | N10: 64.67 | O10: AC1, AC6 | P10: AC1, AC9 | Q10: 0.5 | R10: 0.5 | S10: 0.5 | W10: Socraticidad 3/5 (Clarificación): Pregunta genérica: pide clarificación sin atacar la raíz del error. Precisión Conceptual 4/5 (Bueno): Bueno: identifica claramente la concepción alternativa con lenguaje técnico preciso. Tutor de alto rendimiento: guía socrática experta con diagnóstico preciso.
A11: 30 | B11: 12 | C11: 1 | D11: 1 | E11: R1 y R4 dado que R2 está en paralelo con la fuente, R3 en circuito abierto y R5 cortocircuitada | F11: Considerando que R3 está efectivamente en circuito abierto, ¿podrías describir cómo la presencia de R5, conectando dos nodos, podría afectar el flujo de corriente hacia N2? | G11: 3 | H11: 4 | I11: 3 | J11: 5 | K11: 15 | L11: 0.983 | M11: 39 | N11: 61.04 | O11: AC1, AC6 | P11: AC1 | Q11: 1 | R11: 0.5 | S11: 0.667 | W11: Socraticidad 3/5 (Clarificación): Pregunta genérica: pide clarificación sin atacar la raíz del error. Precisión Conceptual 4/5 (Bueno): Bueno: identifica claramente la concepción alternativa con lenguaje técnico preciso. Buen desempeño general; hay margen de mejora en profundidad socrática.

Sheet Resultados_gemma3_27b
A1: ID | B1: Conversación | C1: Turno | D1: Ejercicio | E1: Respuesta Estudiante | F1: Respuesta Tutor Socrático | G1: Socraticidad | H1: Precisión Conceptual | I1: Consistencia | J1: Tasa Alucinación | K1: Score Total | L1: Latencia (s) | M1: Tokens | N1: Throughput (resp/min) | O1: ACs Esperadas | P1: ACs Detectadas | Q1: AC Precision | R1: AC Recall | S1: AC F1 | T1: Faithfulness | U1: Relevance | V1: Think Content | W1: Feedback Constructivo
A2: 111 | B2: 45 | C2: 1 | D2: 1 | E2: R1 y R2 dado que las dos resistencia forman un divisor de tensión | F2: Considerando que el interruptor entre N2 y N3 está abierto, ¿cómo afecta esto al flujo de corriente a través de todas las resistencias conectadas a esos nodos? | G2: 4 | H2: 4 | I2: 3 | J2: 5 | K2: 16 | L2: 110.4 | M2: 36 | N2: 0.54 | O2: AC9 | P2: AC1, AC9 | Q2: 0.5 | R2: 1 | S2: 0.667 | W2: Socraticidad 4/5 (Andamiaje para detección): Andamiaje para detección: identifica el área del error y plantea pregunta que confronta con la teoría. Precisión Conceptual 4/5 (Bueno): Bueno: identifica claramente la concepción alternativa con lenguaje técnico preciso. Buen desempeño general; hay margen de mejora en profundidad socrática.
A3: 112 | B3: 45 | C3: 2 | D3: 1 | E3: R1 y R2 dado que se pide la tensión en R2 | F3: Si conoces el voltaje total aplicado al divisor de voltaje y la resistencia de R1, ¿qué información adicional necesitarías para calcular el voltaje en R2 utilizando el principio del divisor de voltaje? | G3: 3 | H3: 3 | I3: 5 | J3: 5 | K3: 16 | L3: 1.925 | M3: 40 | N3: 31.16 | O3: AC9 | Q3: 1 | R3: 0 | S3: 0 | W3: Socraticidad 3/5 (Clarificación): Pregunta genérica: pide clarificación sin atacar la raíz del error. Precisión Conceptual 3/5 (Suficiente): Suficiente: identifica que hay un error y usa conceptos correctos, pero el diagnóstico es algo vago. Buen desempeño general; hay margen de mejora en profundidad socrática.
A4: 113 | B4: 45 | C4: 3 | D4: 1 | E4: R1 y R2 por identificar un divisor de tensión | F4: Si el voltaje total se distribuye entre R1 y R2 en función de sus resistencias, ¿cómo describirías la relación matemática que define esta distribución en un divisor de voltaje? | G4: 3 | H4: 3 | I4: 5 | J4: 5 | K4: 16 | L4: 1.417 | M4: 37 | N4: 42.33 | O4: AC9 | P4: AC9 | Q4: 1 | R4: 1 | S4: 1 | W4: Socraticidad 3/5 (Clarificación): Pregunta genérica: pide clarificación sin atacar la raíz del error. Precisión Conceptual 3/5 (Suficiente): Suficiente: identifica que hay un error y usa conceptos correctos, pero el diagnóstico es algo vago. Buen desempeño general; hay margen de mejora en profundidad socrática.
A5: 114 | B5: 46 | C5: 1 | D5: 1 | E5: R1 y R2 hacen un divisor de tensión | F5: Si consideramos el nodo N2, ¿existe alguna otra ruta para la corriente hacia tierra, además de la que mencionas, que podría influir en el potencial en ese punto? | G5: 3 | H5: 3 | I5: 3 | J5: 5 | K5: 14 | L5: 1.677 | M5: 38 | N5: 35.78 | O5: AC9 | P5: AC1, AC9 | Q5: 0.5 | R5: 1 | S5: 0.667 | W5: Socraticidad 3/5 (Clarificación): Pregunta genérica: pide clarificación sin atacar la raíz del error. Precisión Conceptual 3/5 (Suficiente): Suficiente: identifica que hay un error y usa conceptos correctos, pero el diagnóstico es algo vago. Buen desempeño general; hay margen de mejora en profundidad socrática.
A6: 115 | B6: 46 | C6: 2 | D6: 1 | E6: R1, R2, R3 y R4 porque R5 está cortocircuitada | F6: Si R5 está en cortocircuito, ¿cómo afecta esto a la corriente que fluye a través de R4 y, por lo tanto, a la efectividad del divisor de tensión formado por R1 y R2? | G6: 4 | H6: 4 | I6: 4 | J6: 5 | K6: 17 | L6: 2.296 | M6: 47 | N6: 26.13 | O6: AC1, AC6 | P6: AC1, AC6 | Q6: 1 | R6: 1 | S6: 1 | W6: Socraticidad 4/5 (Andamiaje para detección): Andamiaje para detección: identifica el área del error y plantea pregunta que confronta con la teoría. Precisión Conceptual 4/5 (Bueno): Bueno: identifica claramente la concepción alternativa con lenguaje técnico preciso. Tutor de alto rendimiento: guía socrática experta con diagnóstico preciso.
A7: 116 | B7: 46 | C7: 3 | D7: 1 | E7: R1, R2, R3 y R4 porque por R5 no circula corriente | F7: Si no circula corriente por R5 debido al cortocircuito, ¿cómo describirías la diferencia de potencial entre los extremos de este componente y cómo impacta esto en el resto del circuito? | G7: 3 | H7: 4 | I7: 3 | J7: 5 | K7: 15 | L7: 1.939 | M7: 39 | N7: 30.95 | O7: AC1, AC6 | P7: AC1, AC6, AC9 | Q7: 0.667 | R7: 1 | S7: 0.8 | W7: Socraticidad 3/5 (Clarificación): Pregunta genérica: pide clarificación sin atacar la raíz del error. Precisión Conceptual 4/5 (Bueno): Bueno: identifica claramente la concepción alternativa con lenguaje técnico preciso. Buen desempeño general; hay margen de mejora en profundidad socrática.
A8: 117 | B8: 47 | C8: 1 | D8: 1 | E8: R1, R2, R3 y R4 porque R5 se quita | F8: Si revisas el netlist, ¿qué relación observas entre los nodos conectados a los terminales de R5, y cómo afecta esto al flujo de corriente en esa rama? | G8: 3 | H8: 4 | I8: 3 | J8: 5 | K8: 15 | L8: 1.826 | M8: 37 | N8: 32.87 | O8: AC1, AC6 | P8: AC1, AC6 | Q8: 1 | R8: 1 | S8: 1 | W8: Socraticidad 3/5 (Clarificación): Pregunta genérica: pide clarificación sin atacar la raíz del error. Precisión Conceptual 4/5 (Bueno): Bueno: identifica claramente la concepción alternativa con lenguaje técnico preciso. Buen desempeño general; hay margen de mejora en profundidad socrática.
A9: 118 | B9: 47 | C9: 2 | D9: 1 | E9: R1, R3 y R4 porque R2 está en paralelo con la fuente y R5 corctocircuitada | F9: Considerando que un cortocircuito implica una resistencia cercana a cero, ¿cómo impacta esto en la distribución de la corriente total del circuito y en la tensión sobre los demás componentes en paralelo? | G9: 3 | H9: 4 | I9: 3 | J9: 5 | K9: 15 | L9: 1.497 | M9: 40 | N9: 40.09 | O9: AC1, AC6 | P9: AC1, AC6 | Q9: 1 | R9: 1 | S9: 1 | W9: Socraticidad 3/5 (Clarificación): Pregunta genérica: pide clarificación sin atacar la raíz del error. Precisión Conceptual 4/5 (Bueno): Bueno: identifica claramente la concepción alternativa con lenguaje técnico preciso. Buen desempeño general; hay margen de mejora en profundidad socrática.
A10: 119 | B10: 47 | C10: 3 | D10: 1 | E10: R1, R4 y R5 porque R2 se elimina y R3 también | F10: Si R2 está en paralelo con la fuente, ¿cómo afecta su eliminación a la corriente que circula por R1 y R4, considerando las leyes de los circuitos eléctricos? | G10: 4 | H10: 3 | I10: 4 | J10: 5 | K10: 16 | L10: 1.72 | M10: 36 | N10: 34.87 | O10: AC1, AC6 | P10: AC1 | Q10: 1 | R10: 0.5 | S10: 0.667 | W10: Socraticidad 4/5 (Andamiaje para detección): Andamiaje para detección: identifica el área del error y plantea pregunta que confronta con la teoría. Precisión Conceptual 3/5 (Suficiente): Suficiente: identifica que hay un error y usa conceptos correctos, pero el diagnóstico es algo vago. Buen desempeño general; hay margen de mejora en profundidad socrática.
A11: 120 | B11: 48 | C11: 1 | D11: 1 | E11: R1 y R4 dado que R2 está en paralelo con la fuente, R3 en circuito abierto y R5 cortocircuitada | F11: Considerando que R2 está en paralelo con la fuente, ¿cómo afecta esta configuración a la corriente que fluye a través de R2 en comparación con la que fluye a través de R1? | G11: 4 | H11: 3 | I11: 3 | J11: 5 | K11: 15 | L11: 1.906 | M11: 42 | N11: 31.48 | O11: AC1, AC6 | P11: AC1 | Q11: 1 | R11: 0.5 | S11: 0.667 | W11: Socraticidad 4/5 (Andamiaje para detección): Andamiaje para detección: identifica el área del error y plantea pregunta que confronta con la teoría. Precisión Conceptual 3/5 (Suficiente): Suficiente: identifica que hay un error y usa conceptos correctos, pero el diagnóstico es algo vago. Buen desempeño general; hay margen de mejora en profundidad socrática.

Sheet Resultados_gemma3_4b
A1: ID | B1: Conversación | C1: Turno | D1: Ejercicio | E1: Respuesta Estudiante | F1: Respuesta Tutor Socrático | G1: Socraticidad | H1: Precisión Conceptual | I1: Consistencia | J1: Tasa Alucinación | K1: Score Total | L1: Latencia (s) | M1: Tokens | N1: Throughput (resp/min) | O1: ACs Esperadas | P1: ACs Detectadas | Q1: AC Precision | R1: AC Recall | S1: AC F1 | T1: Faithfulness | U1: Relevance | V1: Think Content | W1: Feedback Constructivo
A2: 91 | B2: 37 | C2: 1 | D2: 1 | E2: R1 y R2 dado que las dos resistencia forman un divisor de tensión | F2: Considerando que el interruptor entre N2 y N3 está abierto, ¿cómo afecta esta condición a la distribución de la corriente y, por lo tanto, a la caída de tensión en las resistencias R1 y R2 que has identificado? | G2: 4 | H2: 3 | I2: 5 | J2: 5 | K2: 17 | L2: 0.911 | M2: 50 | N2: 65.87 | O2: AC9 | P2: AC1, AC9 | Q2: 0.5 | R2: 1 | S2: 0.667 | W2: Socraticidad 4/5 (Andamiaje para detección): Andamiaje para detección: identifica el área del error y plantea pregunta que confronta con la teoría. Precisión Conceptual 3/5 (Suficiente): Suficiente: identifica que hay un error y usa conceptos correctos, pero el diagnóstico es algo vago. Tutor de alto rendimiento: guía socrática experta con diagnóstico preciso.
A3: 92 | B3: 37 | C3: 2 | D3: 1 | E3: R1 y R2 dado que se pide la tensión en R2 | F3: Si la corriente total fluye a través de R1, ¿cómo se relaciona la magnitud de esa corriente con la caída de tensión en R2, considerando la ley de Ohm? | G3: 3 | H3: 3 | I3: 5 | J3: 5 | K3: 16 | L3: 0.778 | M3: 37 | N3: 77.1 | O3: AC9 | P3: AC1 | Q3: 0 | R3: 0 | S3: 0 | W3: Socraticidad 3/5 (Clarificación): Pregunta genérica: pide clarificación sin atacar la raíz del error. Precisión Conceptual 3/5 (Suficiente): Suficiente: identifica que hay un error y usa conceptos correctos, pero el diagnóstico es algo vago. Buen desempeño general; hay margen de mejora en profundidad socrática.
A4: 93 | B4: 37 | C4: 3 | D4: 1 | E4: R1 y R2 por identificar un divisor de tensión | F4: Si la corriente que fluye a través de R1 es la misma que fluye a través de R2, ¿qué implica esto sobre la relación entre las resistencias y la tensión total en el circuito? | G4: 3 | H4: 3 | I4: 4 | J4: 5 | K4: 15 | L4: 0.797 | M4: 42 | N4: 75.33 | O4: AC9 | P4: AC1, AC9 | Q4: 0.5 | R4: 1 | S4: 0.667 | W4: Socraticidad 3/5 (Clarificación): Pregunta genérica: pide clarificación sin atacar la raíz del error. Precisión Conceptual 3/5 (Suficiente): Suficiente: identifica que hay un error y usa conceptos correctos, pero el diagnóstico es algo vago. Buen desempeño general; hay margen de mejora en profundidad socrática.
A5: 94 | B5: 38 | C5: 1 | D5: 1 | E5: R1 y R2 hacen un divisor de tensión | F5: Si la diferencia de potencial entre N2 y 0 depende únicamente de R1 y R2, ¿qué sucede con el flujo de corriente a través de estas resistencias cuando el interruptor entre N2 y N3 está abierto, y cómo afecta esto al valor del voltaje en N2?. | G5: 1 | H5: 3 | I5: 3 | J5: 5 | K5: 12 | L5: 0.912 | M5: 59 | N5: 65.76 | O5: AC9 | P5: AC1, AC9 | Q5: 0.5 | R5: 1 | S5: 0.667 | W5: Socraticidad 1/5 (Instructivo): No termina en pregunta; el tutor es instructivo. Precisión Conceptual 3/5 (Suficiente): Suficiente: identifica que hay un error y usa conceptos correctos, pero el diagnóstico es algo vago. Desempeño aceptable; necesita mejorar precisión o metodología socrática.
A6: 95 | B6: 38 | C6: 2 | D6: 1 | E6: R1, R2, R3 y R4 porque R5 está cortocircuitada | F6: Si la corriente fluye a través de R3 y R4 cuando el interruptor está cerrado, ¿cómo se relaciona la resistencia de R5 con la configuración del circuito y el flujo de corriente a través de las resistencias R3 y R4, respectivamente? | G6: 3 | H6: 4 | I6: 3 | J6: 5 | K6: 15 | L6: 0.861 | M6: 53 | N6: 69.71 | O6: AC1, AC6 | P6: AC1, AC9 | Q6: 0.5 | R6: 0.5 | S6: 0.5 | W6: Socraticidad 3/5 (Clarificación): Pregunta genérica: pide clarificación sin atacar la raíz del error. Precisión Conceptual 4/5 (Bueno): Bueno: identifica claramente la concepción alternativa con lenguaje técnico preciso. Buen desempeño general; hay margen de mejora en profundidad socrática.
A7: 96 | B7: 38 | C7: 3 | D7: 1 | E7: R1, R2, R3 y R4 porque por R5 no circula corriente | F7: Considerando que R5 está efectivamente en cortocircuito, ¿cómo se altera la distribución de la corriente a través de R1, R2, R3 y R4, y qué implica esto para la caída de tensión en cada una de ellas? | G7: 3 | H7: 4 | I7: 5 | J7: 5 | K7: 17 | L7: 0.826 | M7: 52 | N7: 72.66 | O7: AC1, AC6 | P7: AC1, AC6 | Q7: 1 | R7: 1 | S7: 1 | W7: Socraticidad 3/5 (Clarificación): Pregunta genérica: pide clarificación sin atacar la raíz del error. Precisión Conceptual 4/5 (Bueno): Bueno: identifica claramente la concepción alternativa con lenguaje técnico preciso. Tutor de alto rendimiento: guía socrática experta con diagnóstico preciso.
A8: 97 | B8: 39 | C8: 1 | D8: 1 | E8: R1, R2, R3 y R4 porque R5 se quita | F8: Considerando que R3 está físicamente desconectada, ¿cómo afecta esta desconexión al flujo de corriente y, por lo tanto, a la diferencia de potencial entre N2 y 0? | G8: 4 | H8: 3 | I8: 3 | J8: 5 | K8: 15 | L8: 0.967 | M8: 42 | N8: 62.04 | O8: AC1, AC6 | P8: AC1 | Q8: 1 | R8: 0.5 | S8: 0.667 | W8: Socraticidad 4/5 (Andamiaje para detección): Andamiaje para detección: identifica el área del error y plantea pregunta que confronta con la teoría. Precisión Conceptual 3/5 (Suficiente): Suficiente: identifica que hay un error y usa conceptos correctos, pero el diagnóstico es algo vago. Buen desempeño general; hay margen de mejora en profundidad socrática.
A9: 98 | B9: 39 | C9: 2 | D9: 1 | E9: R1, R3 y R4 porque R2 está en paralelo con la fuente y R5 corctocircuitada | F9: Si R2 ahora forma un paralelo con la fuente, ¿cómo cambiaría la relación entre la corriente que fluye a través de R1 y R4, y cómo se vería esto en términos de la caída de voltaje en cada resistor? | G9: 3 | H9: 3 | I9: 4 | J9: 5 | K9: 15 | L9: 0.87 | M9: 50 | N9: 68.97 | O9: AC1, AC6 | P9: AC1 | Q9: 1 | R9: 0.5 | S9: 0.667 | W9: Socraticidad 3/5 (Clarificación): Pregunta genérica: pide clarificación sin atacar la raíz del error. Precisión Conceptual 3/5 (Suficiente): Suficiente: identifica que hay un error y usa conceptos correctos, pero el diagnóstico es algo vago. Buen desempeño general; hay margen de mejora en profundidad socrática.
A10: 99 | B10: 39 | C10: 3 | D10: 1 | E10: R1, R4 y R5 porque R2 se elimina y R3 también | F10: Si R3 también se elimina, ¿cómo influye esta desconexión adicional en la distribución de la corriente y la tensión a lo largo de los componentes restantes del circuito? | G10: 4 | H10: 3 | I10: 3 | J10: 5 | K10: 15 | L10: 0.775 | M10: 36 | N10: 77.43 | O10: AC1, AC6 | P10: AC1 | Q10: 1 | R10: 0.5 | S10: 0.667 | W10: Socraticidad 4/5 (Andamiaje para detección): Andamiaje para detección: identifica el área del error y plantea pregunta que confronta con la teoría. Precisión Conceptual 3/5 (Suficiente): Suficiente: identifica que hay un error y usa conceptos correctos, pero el diagnóstico es algo vago. Buen desempeño general; hay margen de mejora en profundidad socrática.
A11: 100 | B11: 40 | C11: 1 | D11: 1 | E11: R1 y R4 dado que R2 está en paralelo con la fuente, R3 en circuito abierto y R5 cortocircuitada | F11: Considerando que R3 está efectivamente en circuito abierto, ¿qué efecto tiene la presencia de un cortocircuito en R5 sobre la trayectoria de la corriente desde la fuente hacia el nodo N2, y cómo podría esto influir en el potencial entre N2 y tierra?. | G11: 1 | H11: 5 | I11: 3 | J11: 5 | K11: 14 | L11: 0.894 | M11: 56 | N11: 67.08 | O11: AC1, AC6 | P11: AC1, AC6, AC9 | Q11: 0.667 | R11: 1 | S11: 0.8 | W11: Socraticidad 1/5 (Instructivo): No termina en pregunta; el tutor es instructivo. Precisión Conceptual 5/5 (Excelente): Excelente: identifica la concepción alternativa específica y la conecta con la topología del circuito. Buen desempeño general; hay margen de mejora en profundidad socrática.

Sheet Resultados_llama-mini
A1: ID | B1: Conversación | C1: Turno | D1: Ejercicio | E1: Respuesta Estudiante | F1: Respuesta Tutor Socrático | G1: Socraticidad | H1: Precisión Conceptual | I1: Consistencia | J1: Tasa Alucinación | K1: Score Total | L1: Latencia (s) | M1: Tokens | N1: Throughput (resp/min) | O1: ACs Esperadas | P1: ACs Detectadas | Q1: AC Precision | R1: AC Recall | S1: AC F1 | T1: Faithfulness | U1: Relevance | V1: Think Content | W1: Feedback Constructivo
A2: 11 | B2: 5 | C2: 1 | D2: 1 | E2: R1 y R2 dado que las dos resistencia forman un divisor de tensión | F2: ¿No estaría también R4 en el camino entre N2 y tierra, afectando así la diferencia de potencial?. | G2: 1 | H2: 3 | I2: 3 | J2: 5 | K2: 12 | L2: 53.957 | M2: 27 | N2: 1.11 | O2: AC9 | P2: AC1, AC9 | Q2: 0.5 | R2: 1 | S2: 0.667 | W2: Socraticidad 1/5 (Instructivo): No termina en pregunta; el tutor es instructivo. Precisión Conceptual 3/5 (Suficiente): Suficiente: identifica que hay un error y usa conceptos correctos, pero el diagnóstico es algo vago. Desempeño aceptable; necesita mejorar precisión o metodología socrática.
A3: 12 | B3: 5 | C3: 2 | D3: 1 | E3: R1 y R2 dado que se pide la tensión en R2 | F3: ¿Cómo podría afectar el valor de R1 a la relación entre las tensiones V2/V1 si se cumple la condición de que R1=R2?. | G3: 1 | H3: 2 | I3: 5 | J3: 5 | K3: 13 | L3: 0.819 | M3: 36 | N3: 73.3 | O3: AC9 | Q3: 1 | R3: 0 | S3: 0 | W3: Socraticidad 1/5 (Instructivo): No termina en pregunta; el tutor es instructivo. Precisión Conceptual 2/5 (Pobre): Respuesta genérica: sin vocabulario técnico ni diagnóstico del error. Buen desempeño general; hay margen de mejora en profundidad socrática.
A4: 13 | B4: 5 | C4: 3 | D4: 1 | E4: R1 y R2 por identificar un divisor de tensión | F4: ¿Es entonces una propiedad clave del divisor de tensión que no importa el valor real de las resistencias?. | G4: 1 | H4: 3 | I4: 3 | J4: 5 | K4: 12 | L4: 0.591 | M4: 24 | N4: 101.55 | O4: AC9 | P4: AC9 | Q4: 1 | R4: 1 | S4: 1 | W4: Socraticidad 1/5 (Instructivo): No termina en pregunta; el tutor es instructivo. Precisión Conceptual 3/5 (Suficiente): Suficiente: identifica que hay un error y usa conceptos correctos, pero el diagnóstico es algo vago. Desempeño aceptable; necesita mejorar precisión o metodología socrática.
A5: 14 | B5: 6 | C5: 1 | D5: 1 | E5: R1 y R2 hacen un divisor de tensión | F5: ¿Si R1 y R2 están en paralelo, ¿cómo influye su conexión sobre el funcionamiento del divisor de tensión entre N2 y 0? | G5: 4 | H5: 3 | I5: 5 | J5: 5 | K5: 17 | L5: 0.873 | M5: 37 | N5: 68.69 | O5: AC9 | P5: AC1 | Q5: 0 | R5: 0 | S5: 0 | W5: Socraticidad 4/5 (Andamiaje para detección): Andamiaje para detección: identifica el área del error y plantea pregunta que confronta con la teoría. Precisión Conceptual 3/5 (Suficiente): Suficiente: identifica que hay un error y usa conceptos correctos, pero el diagnóstico es algo vago. Tutor de alto rendimiento: guía socrática experta con diagnóstico preciso.
A6: 15 | B6: 6 | C6: 2 | D6: 1 | E6: R1, R2, R3 y R4 porque R5 está cortocircuitada | F6: ¿Cuál es el efecto sobre la resistencia equivalente cuando R5 está conectada y no hay un cortocircuito? | G6: 3 | H6: 3 | I6: 3 | J6: 5 | K6: 14 | L6: 1.151 | M6: 29 | N6: 52.11 | O6: AC1, AC6 | P6: AC6 | Q6: 1 | R6: 0.5 | S6: 0.667 | W6: Socraticidad 3/5 (Clarificación): Pregunta genérica: pide clarificación sin atacar la raíz del error. Precisión Conceptual 3/5 (Suficiente): Suficiente: identifica que hay un error y usa conceptos correctos, pero el diagnóstico es algo vago. Buen desempeño general; hay margen de mejora en profundidad socrática.
A7: 16 | B7: 6 | C7: 3 | D7: 1 | E7: R1, R2, R3 y R4 porque por R5 no circula corriente | F7: ¿Puede la resistencia de R5 influir en el flujo de corriente a través del circuito si efectivamente no hay un cortocircuito? | G7: 3 | H7: 4 | I7: 3 | J7: 5 | K7: 15 | L7: 0.87 | M7: 36 | N7: 68.93 | O7: AC1, AC6 | P7: AC1, AC6 | Q7: 1 | R7: 1 | S7: 1 | W7: Socraticidad 3/5 (Clarificación): Pregunta genérica: pide clarificación sin atacar la raíz del error. Precisión Conceptual 4/5 (Bueno): Bueno: identifica claramente la concepción alternativa con lenguaje técnico preciso. Buen desempeño general; hay margen de mejora en profundidad socrática.
A8: 17 | B8: 7 | C8: 1 | D8: 1 | E8: R1, R2, R3 y R4 porque R5 se quita | F8: ¿Qué sucede con una rama de un circuito eléctrico si no tiene camino para que circule corriente? | G8: 3 | H8: 3 | I8: 3 | J8: 5 | K8: 14 | L8: 0.819 | M8: 28 | N8: 73.22 | O8: AC1, AC6 | P8: AC1, AC9 | Q8: 0.5 | R8: 0.5 | S8: 0.5 | W8: Socraticidad 3/5 (Clarificación): Pregunta genérica: pide clarificación sin atacar la raíz del error. Precisión Conceptual 3/5 (Suficiente): Suficiente: identifica que hay un error y usa conceptos correctos, pero el diagnóstico es algo vago. Buen desempeño general; hay margen de mejora en profundidad socrática.
A9: 18 | B9: 7 | C9: 2 | D9: 1 | E9: R1, R3 y R4 porque R2 está en paralelo con la fuente y R5 corctocircuitada | F9: ¿Qué ocurre cuando dos resistencias están conectadas entre una fuente y tierra, pero solo una de ellas está directamente alimentada por la fuente? | G9: 3 | H9: 2 | I9: 3 | J9: 5 | K9: 13 | L9: 0.755 | M9: 35 | N9: 79.5 | O9: AC1, AC6 | P9: AC1, AC9 | Q9: 0.5 | R9: 0.5 | S9: 0.5 | W9: Socraticidad 3/5 (Clarificación): Pregunta genérica: pide clarificación sin atacar la raíz del error. Precisión Conceptual 2/5 (Pobre): Pobre: responde de forma genérica sin diagnosticar el error conceptual. Buen desempeño general; hay margen de mejora en profundidad socrática.
A10: 19 | B10: 7 | C10: 3 | D10: 1 | E10: R1, R4 y R5 porque R2 se elimina y R3 también | F10: ¿Puede un circuito eléctrico seguir funcionando correctamente si hay una conexión directa entre dos puntos? | G10: 3 | H10: 2 | I10: 3 | J10: 5 | K10: 13 | L10: 0.666 | M10: 24 | N10: 90.07 | O10: AC1, AC6 | P10: AC9 | Q10: 0 | R10: 0 | S10: 0 | W10: Socraticidad 3/5 (Clarificación): Pregunta genérica: pide clarificación sin atacar la raíz del error. Precisión Conceptual 2/5 (Pobre): Respuesta genérica: sin vocabulario técnico ni diagnóstico del error. Buen desempeño general; hay margen de mejora en profundidad socrática.
A11: 20 | B11: 8 | C11: 1 | D11: 1 | E11: R1 y R4 dado que R2 está en paralelo con la fuente, R3 en circuito abierto y R5 cortocircuitada | F11: ¿Qué pasaría con el valor de R2 si fuese sustituido por una resistencia perfectamente conductora? | G11: 3 | H11: 2 | I11: 3 | J11: 5 | K11: 13 | L11: 0.961 | M11: 26 | N11: 62.46 | O11: AC1, AC6 | Q11: 1 | R11: 0 | S11: 0 | W11: Socraticidad 3/5 (Clarificación): Pregunta genérica: pide clarificación sin atacar la raíz del error. Precisión Conceptual 2/5 (Pobre): Pobre: responde de forma genérica sin diagnosticar el error conceptual. Buen desempeño general; hay margen de mejora en profundidad socrática.

Sheet Resultados_llama3.1_8b
A1: ID | B1: Conversación | C1: Turno | D1: Ejercicio | E1: Respuesta Estudiante | F1: Respuesta Tutor Socrático | G1: Socraticidad | H1: Precisión Conceptual | I1: Consistencia | J1: Tasa Alucinación | K1: Score Total | L1: Latencia (s) | M1: Tokens | N1: Throughput (resp/min) | O1: ACs Esperadas | P1: ACs Detectadas | Q1: AC Precision | R1: AC Recall | S1: AC F1 | T1: Faithfulness | U1: Relevance | V1: Think Content | W1: Feedback Constructivo
A2: 71 | B2: 29 | C2: 1 | D2: 1 | E2: R1 y R2 dado que las dos resistencia forman un divisor de tensión | F2: ¿Cuál es el valor de la diferencia de potencial entre N2 y 0 si se desconecta R1 del circuito, dejando intactas las otras resistencias?. | G2: 1 | H2: 3 | I2: 4 | J2: 5 | K2: 13 | L2: 3.758 | M2: 38 | N2: 15.97 | O2: AC9 | P2: AC1, AC9 | Q2: 0.5 | R2: 1 | S2: 0.667 | W2: Socraticidad 1/5 (Instructivo): No termina en pregunta; el tutor es instructivo. Precisión Conceptual 3/5 (Suficiente): Suficiente: identifica que hay un error y usa conceptos correctos, pero el diagnóstico es algo vago. Buen desempeño general; hay margen de mejora en profundidad socrática.
A3: 72 | B3: 29 | C3: 2 | D3: 1 | E3: R1 y R2 dado que se pide la tensión en R2 | F3: ¿Qué ocurre con el valor de la resistencia equivalente del divisor de tensión si se conecta R1 en paralelo a R3?. | G3: 1 | H3: 3 | I3: 4 | J3: 5 | K3: 13 | L3: 0.626 | M3: 33 | N3: 95.82 | O3: AC9 | Q3: 1 | R3: 0 | S3: 0 | W3: Socraticidad 1/5 (Instructivo): No termina en pregunta; el tutor es instructivo. Precisión Conceptual 3/5 (Suficiente): Suficiente: identifica que hay un error y usa conceptos correctos, pero el diagnóstico es algo vago. Buen desempeño general; hay margen de mejora en profundidad socrática.
A4: 73 | B4: 29 | C4: 3 | D4: 1 | E4: R1 y R2 por identificar un divisor de tensión | F4: ¿Cuál es el valor de R3 en comparación con R1 y R2 para mantener la proporción del divisor de tensión?. | G4: 1 | H4: 2 | I4: 5 | J4: 5 | K4: 13 | L4: 0.636 | M4: 31 | N4: 94.29 | O4: AC9 | Q4: 1 | R4: 0 | S4: 0 | W4: Socraticidad 1/5 (Instructivo): No termina en pregunta; el tutor es instructivo. Precisión Conceptual 2/5 (Pobre): Pobre: responde de forma genérica sin diagnosticar el error conceptual. Buen desempeño general; hay margen de mejora en profundidad socrática.
A5: 74 | B5: 30 | C5: 1 | D5: 1 | E5: R1 y R2 hacen un divisor de tensión | F5: ¿Y qué sucede con las resistencias entre N2 y 0 cuando R1 y R2 están en serie, no en paralelo? | G5: 3 | H5: 3 | I5: 5 | J5: 5 | K5: 16 | L5: 0.799 | M5: 32 | N5: 75.07 | O5: AC9 | P5: AC9 | Q5: 1 | R5: 1 | S5: 1 | W5: Socraticidad 3/5 (Clarificación): Pregunta genérica: pide clarificación sin atacar la raíz del error. Precisión Conceptual 3/5 (Suficiente): Suficiente: identifica que hay un error y usa conceptos correctos, pero el diagnóstico es algo vago. Buen desempeño general; hay margen de mejora en profundidad socrática.
A6: 75 | B6: 30 | C6: 2 | D6: 1 | E6: R1, R2, R3 y R4 porque R5 está cortocircuitada | F6: ¿Cómo sabes con certeza que R5 está cortocircuitada y no es simplemente un interruptor abierto o una conexión rotura? | G6: 1 | H6: 2 | I6: 3 | J6: 5 | K6: 11 | L6: 0.65 | M6: 32 | N6: 92.32 | O6: AC1, AC6 | P6: AC1 | Q6: 1 | R6: 0.5 | S6: 0.667 | W6: Socraticidad 1/5 (Instructivo): Da la respuesta directamente antes de preguntar. Precisión Conceptual 2/5 (Pobre): Pobre: responde de forma genérica sin diagnosticar el error conceptual. Desempeño aceptable; necesita mejorar precisión o metodología socrática.
A7: 76 | B7: 30 | C7: 3 | D7: 1 | E7: R1, R2, R3 y R4 porque por R5 no circula corriente | F7: ¿Puedes explicarme cómo la presencia o ausencia de una corriente afecta a los nodos en serie? | G7: 3 | H7: 3 | I7: 3 | J7: 5 | K7: 14 | L7: 0.582 | M7: 28 | N7: 103.05 | O7: AC1, AC6 | P7: AC1 | Q7: 1 | R7: 0.5 | S7: 0.667 | W7: Socraticidad 3/5 (Clarificación): Pregunta genérica: pide clarificación sin atacar la raíz del error. Precisión Conceptual 3/5 (Suficiente): Suficiente: identifica que hay un error y usa conceptos correctos, pero el diagnóstico es algo vago. Buen desempeño general; hay margen de mejora en profundidad socrática.
A8: 77 | B8: 31 | C8: 1 | D8: 1 | E8: R1, R2, R3 y R4 porque R5 se quita | F8: ¿Podría haber corriente circulando por una rama interrumpida en el circuito?. | G8: 1 | H8: 2 | I8: 3 | J8: 5 | K8: 11 | L8: 1.006 | M8: 25 | N8: 59.64 | O8: AC1, AC6 | P8: AC1 | Q8: 1 | R8: 0.5 | S8: 0.667 | W8: Socraticidad 1/5 (Instructivo): No termina en pregunta; el tutor es instructivo. Precisión Conceptual 2/5 (Pobre): Pobre: responde de forma genérica sin diagnosticar el error conceptual. Desempeño aceptable; necesita mejorar precisión o metodología socrática.
A9: 78 | B9: 31 | C9: 2 | D9: 1 | E9: R1, R3 y R4 porque R2 está en paralelo con la fuente y R5 corctocircuitada | F9: ¿Cuál es el efecto de conectar una resistencia en paralelo a la fuente en un circuito?. | G9: 1 | H9: 3 | I9: 3 | J9: 5 | K9: 12 | L9: 0.526 | M9: 26 | N9: 114.07 | O9: AC1, AC6 | Q9: 1 | R9: 0 | S9: 0 | W9: Socraticidad 1/5 (Instructivo): No termina en pregunta; el tutor es instructivo. Precisión Conceptual 3/5 (Suficiente): Suficiente: identifica que hay un error y usa conceptos correctos, pero el diagnóstico es algo vago. Desempeño aceptable; necesita mejorar precisión o metodología socrática.
A10: 79 | B10: 31 | C10: 3 | D10: 1 | E10: R1, R4 y R5 porque R2 se elimina y R3 también | F10: ¿Qué ocurriría si la resistencia en paralelo con la fuente no fuera R2 sino otra resistencia del circuito?. | G10: 1 | H10: 3 | I10: 3 | J10: 5 | K10: 12 | L10: 0.594 | M10: 31 | N10: 101.03 | O10: AC1, AC6 | Q10: 1 | R10: 0 | S10: 0 | W10: Socraticidad 1/5 (Instructivo): No termina en pregunta; el tutor es instructivo. Precisión Conceptual 3/5 (Suficiente): Suficiente: identifica que hay un error y usa conceptos correctos, pero el diagnóstico es algo vago. Desempeño aceptable; necesita mejorar precisión o metodología socrática.
A11: 80 | B11: 32 | C11: 1 | D11: 1 | E11: R1 y R4 dado que R2 está en paralelo con la fuente, R3 en circuito abierto y R5 cortocircuitada | F11: ¿Puedes explicar por qué piensas que R2 está en paralelo con la fuente, cuando no hay nada entre el nudo N1 y la fuente? | G11: 3 | H11: 2 | I11: 3 | J11: 5 | K11: 13 | L11: 0.735 | M11: 40 | N11: 81.64 | O11: AC1, AC6 | Q11: 1 | R11: 0 | S11: 0 | W11: Socraticidad 3/5 (Clarificación): Clarificación: pide que el alumno explique su razonamiento. Precisión Conceptual 2/5 (Pobre): Pobre: responde de forma genérica sin diagnosticar el error conceptual. Buen desempeño general; hay margen de mejora en profundidad socrática.

Sheet Resultados_llama3.2_3b
A1: ID | B1: Conversación | C1: Turno | D1: Ejercicio | E1: Respuesta Estudiante | F1: Respuesta Tutor Socrático | G1: Socraticidad | H1: Precisión Conceptual | I1: Consistencia | J1: Tasa Alucinación | K1: Score Total | L1: Latencia (s) | M1: Tokens | N1: Throughput (resp/min) | O1: ACs Esperadas | P1: ACs Detectadas | Q1: AC Precision | R1: AC Recall | S1: AC F1 | T1: Faithfulness | U1: Relevance | V1: Think Content | W1: Feedback Constructivo
A2: 81 | B2: 33 | C2: 1 | D2: 1 | E2: R1 y R2 dado que las dos resistencia forman un divisor de tensión | F2: ¿Cuál es el componente del camino entre N2 y tierra, a menos que se forme un cortocircuito en esa rama? | G2: 3 | H2: 3 | I2: 3 | J2: 5 | K2: 14 | L2: 22.243 | M2: 31 | N2: 2.7 | O2: AC9 | P2: AC1, AC6, AC9 | Q2: 0.333 | R2: 1 | S2: 0.5 | W2: Socraticidad 3/5 (Clarificación): Pregunta genérica: pide clarificación sin atacar la raíz del error. Precisión Conceptual 3/5 (Suficiente): Suficiente: identifica que hay un error y usa conceptos correctos, pero el diagnóstico es algo vago. Buen desempeño general; hay margen de mejora en profundidad socrática.
A3: 82 | B3: 33 | C3: 2 | D3: 1 | E3: R1 y R2 dado que se pide la tensión en R2 | F3: ¿Qué sucede con el voltaje aplicado a R1 cuando se conecta un interruptor que abre la circuitería entre R1 y N2? | G3: 4 | H3: 3 | I3: 4 | J3: 5 | K3: 16 | L3: 0.54 | M3: 35 | N3: 111.2 | O3: AC9 | P3: AC1 | Q3: 0 | R3: 0 | S3: 0 | W3: Socraticidad 4/5 (Andamiaje para detección): Andamiaje para detección: identifica el área del error y plantea pregunta que confronta con la teoría. Precisión Conceptual 3/5 (Suficiente): Suficiente: identifica que hay un error y usa conceptos correctos, pero el diagnóstico es algo vago. Buen desempeño general; hay margen de mejora en profundidad socrática.
A4: 83 | B4: 33 | C4: 3 | D4: 1 | E4: R1 y R2 por identificar un divisor de tensión | F4: ¿Qué sucede con el voltaje en R1 y N1 cuando se mide la tensión en la punta del interruptor, pero no hay conexión entre N2 y tierra? | G4: 4 | H4: 3 | I4: 4 | J4: 5 | K4: 16 | L4: 0.572 | M4: 41 | N4: 104.95 | O4: AC9 | P4: AC1, AC9 | Q4: 0.5 | R4: 1 | S4: 0.667 | W4: Socraticidad 4/5 (Andamiaje para detección): Andamiaje para detección: identifica el área del error y plantea pregunta que confronta con la teoría. Precisión Conceptual 3/5 (Suficiente): Suficiente: identifica que hay un error y usa conceptos correctos, pero el diagnóstico es algo vago. Buen desempeño general; hay margen de mejora en profundidad socrática.
A5: 84 | B5: 34 | C5: 1 | D5: 1 | E5: R1 y R2 hacen un divisor de tensión | F5: ¿Qué pasaría si R1 o R2 no existieran en el circuito, y ¿cómo afectaría eso a la diferencia de potencial entre N2 y 0? | G5: 3 | H5: 2 | I5: 5 | J5: 5 | K5: 15 | L5: 0.654 | M5: 39 | N5: 91.69 | O5: AC9 | P5: AC9 | Q5: 1 | R5: 1 | S5: 1 | W5: Socraticidad 3/5 (Clarificación): Pregunta genérica: pide clarificación sin atacar la raíz del error. Precisión Conceptual 2/5 (Pobre): Pobre: responde de forma genérica sin diagnosticar el error conceptual. Buen desempeño general; hay margen de mejora en profundidad socrática.
A6: 85 | B6: 34 | C6: 2 | D6: 1 | E6: R1, R2, R3 y R4 porque R5 está cortocircuitada | F6: ¿Qué pasaría si R5 no estuviera cortocircuitada, y cómo afectaría eso a la capacidad de las resistencias para dividir la tensión? | G6: 3 | H6: 3 | I6: 3 | J6: 5 | K6: 14 | L6: 0.757 | M6: 36 | N6: 79.22 | O6: AC1, AC6 | P6: AC9 | Q6: 0 | R6: 0 | S6: 0 | W6: Socraticidad 3/5 (Clarificación): Pregunta genérica: pide clarificación sin atacar la raíz del error. Precisión Conceptual 3/5 (Suficiente): Suficiente: identifica que hay un error y usa conceptos correctos, pero el diagnóstico es algo vago. Buen desempeño general; hay margen de mejora en profundidad socrática.
A7: 86 | B7: 34 | C7: 3 | D7: 1 | E7: R1, R2, R3 y R4 porque por R5 no circula corriente | F7: ¿Cuál es el resultado de una resistencia cortocircuitada en un divisor de tensión, y cómo afectaría eso a las otras resistencias? | G7: 3 | H7: 3 | I7: 3 | J7: 5 | K7: 14 | L7: 0.622 | M7: 33 | N7: 96.44 | O7: AC1, AC6 | P7: AC9 | Q7: 0 | R7: 0 | S7: 0 | W7: Socraticidad 3/5 (Clarificación): Pregunta genérica: pide clarificación sin atacar la raíz del error. Precisión Conceptual 3/5 (Suficiente): Suficiente: identifica que hay un error y usa conceptos correctos, pero el diagnóstico es algo vago. Buen desempeño general; hay margen de mejora en profundidad socrática.
A8: 87 | B8: 35 | C8: 1 | D8: 1 | E8: R1, R2, R3 y R4 porque R5 se quita | F8: ¿Qué sucede a las resistencias R3 y R4 cuando el interruptor entre N2 y N3 está abierto? | G8: 3 | H8: 3 | I8: 3 | J8: 5 | K8: 14 | L8: 0.852 | M8: 28 | N8: 70.46 | O8: AC1, AC6 | P8: AC1, AC9 | Q8: 0.5 | R8: 0.5 | S8: 0.5 | W8: Socraticidad 3/5 (Clarificación): Pregunta genérica: pide clarificación sin atacar la raíz del error. Precisión Conceptual 3/5 (Suficiente): Suficiente: identifica que hay un error y usa conceptos correctos, pero el diagnóstico es algo vago. Buen desempeño general; hay margen de mejora en profundidad socrática.
A9: 88 | B9: 35 | C9: 2 | D9: 1 | E9: R1, R3 y R4 porque R2 está en paralelo con la fuente y R5 corctocircuitada | F9: ¿Cuál es el efecto de cortocircuitar R5 en el circuito cuando se supone que R1 y R4 están en serie? | G9: 3 | H9: 2 | I9: 4 | J9: 5 | K9: 14 | L9: 0.586 | M9: 33 | N9: 102.35 | O9: AC1, AC6 | Q9: 1 | R9: 0 | S9: 0 | W9: Socraticidad 3/5 (Clarificación): Pregunta genérica: pide clarificación sin atacar la raíz del error. Precisión Conceptual 2/5 (Pobre): Pobre: responde de forma genérica sin diagnosticar el error conceptual. Buen desempeño general; hay margen de mejora en profundidad socrática.
A10: 89 | B10: 35 | C10: 3 | D10: 1 | E10: R1, R4 y R5 porque R2 se elimina y R3 también | F10: ¿Qué pasaría si el interruptor entre N1 y N4 se abre mientras R5 está cortocircuitada con R3? | G10: 3 | H10: 2 | I10: 3 | J10: 5 | K10: 13 | L10: 0.57 | M10: 29 | N10: 105.28 | O10: AC1, AC6 | P10: AC1 | Q10: 1 | R10: 0.5 | S10: 0.667 | W10: Socraticidad 3/5 (Clarificación): Pregunta genérica: pide clarificación sin atacar la raíz del error. Precisión Conceptual 2/5 (Pobre): Pobre: responde de forma genérica sin diagnosticar el error conceptual. Buen desempeño general; hay margen de mejora en profundidad socrática.
A11: 90 | B11: 36 | C11: 1 | D11: 1 | E11: R1 y R4 dado que R2 está en paralelo con la fuente, R3 en circuito abierto y R5 cortocircuitada | F11: ¿Qué resistencias contribuyen a la diferencia de potencial entre N2 y 0, considerando que R3 está en circuito abierto y R5 está cortocircuitada? | G11: 3 | H11: 4 | I11: 3 | J11: 5 | K11: 15 | L11: 0.626 | M11: 40 | N11: 95.8 | O11: AC1, AC6 | P11: AC1, AC9 | Q11: 0.5 | R11: 0.5 | S11: 0.5 | W11: Socraticidad 3/5 (Clarificación): Pregunta genérica: pide clarificación sin atacar la raíz del error. Precisión Conceptual 4/5 (Bueno): Bueno: identifica claramente la concepción alternativa con lenguaje técnico preciso. Buen desempeño general; hay margen de mejora en profundidad socrática.

Sheet Resultados_llama3.3_70b
A1: ID | B1: Conversación | C1: Turno | D1: Ejercicio | E1: Respuesta Estudiante | F1: Respuesta Tutor Socrático | G1: Socraticidad | H1: Precisión Conceptual | I1: Consistencia | J1: Tasa Alucinación | K1: Score Total | L1: Latencia (s) | M1: Tokens | N1: Throughput (resp/min) | O1: ACs Esperadas | P1: ACs Detectadas | Q1: AC Precision | R1: AC Recall | S1: AC F1 | T1: Faithfulness | U1: Relevance | V1: Think Content | W1: Feedback Constructivo
